File: 118.9GPa.txt
#Acq. time (s)=	10
#Accumulations=	1
#Range (cm-¹)=	1300...1700
#Windows=	2
#Autofocus=	Off
#AutoExposure=	Off
#Spike filter=	Single accum. (Size=3)
#Delay time (s)=	0.1
#Binning=	1
#Readout mode=	Signal
#DeNoise=	Standard
#ICS correction=	On
#Dark correction=	Off
#Inst. Process=	Off
#Instrument=	LabRAM HR Evol
#Detector=	Synapse
#Objective=	x20SLWD
#Grating=	1800 gr/mm
#ND Filter=	100%
#Laser (nm)=	633
#Hole=	150.001
#Range=	Visible
#Collection=	Microscope
#StageXY=	Marzhauser
#StageZ=	Marzhauser
#X (µm)=	0
#Y (µm)=	0
#Z (µm)=	0
#Project=	20190124
#Sample=	1-2
#Site=
#Title=	D_75
#Remark=
#Date=	19.05.2019 00:48
#Acquired=	19.05.2019 00:48:23
1300.13	39.7333
1300.68	42.7185
1301.23	43.3598
1301.78	43.8179
1302.32	44.1938
1302.87	44.4986
1303.42	44.5415
1303.97	44.2427
1304.52	44.4133
1305.07	44.6405
1305.61	44.929
1306.16	45.4088
1306.71	46.0299
1307.26	46.4396
1307.8	46.7521
1308.35	47.0406
1308.9	47.2323
1309.45	47.4654
1310	47.732
1310.54	48.039
1311.09	48.2561
1311.64	48.485
1312.19	48.7399
1312.73	49.0354
1313.28	49.3895
1313.83	49.8164
1314.37	50.4433
1314.92	51.1137
1315.47	51.8407
1316.01	52.6348
1316.56	53.4893
1317.11	54.4844
1317.65	55.6548
1318.2	56.9757
1318.75	58.6755
1319.29	60.4417
1319.84	62.2315
1320.39	64.0403
1320.93	65.3082
1321.48	66.6994
1322.02	68.5251
1322.57	72.0112
1323.11	76.0595
1323.66	80.9348
1324.21	86.8475
1324.75	93.845
1325.3	100.145
1325.84	105.994
1326.39	113.326
1326.93	122.509
1327.48	135.278
1328.02	153.562
1328.57	180.901
1329.11	221.546
1329.66	277.954
1330.2	355.001
1330.75	494.943
1331.29	719.692
1331.84	1019.96
1332.38	1412.22
1332.93	1739.62
1333.47	1865.85
1334.01	1835.94
1334.56	1672.78
1335.1	1511.31
1335.65	1351.06
1336.19	1223.58
1336.73	1115.82
1337.28	1019.85
1337.82	936.915
1338.36	866.523
1338.91	809.317
1339.45	766.578
1340	728.457
1340.54	685.874
1341.08	644.119
1341.63	609.101
1342.17	583.462
1342.71	556.5
1343.26	531.109
1343.8	508.515
1344.34	487.575
1344.88	468.339
1345.43	448.819
1345.97	431.08
1346.51	415.476
1347.05	401.448
1347.6	387.795
1348.14	374.445
1348.68	362.458
1349.22	352.437
1349.77	343.941
1350.31	335.976
1350.85	328.057
1351.39	320.776
1351.93	312.933
1352.48	305.162
1353.02	297.591
1353.56	289.047
1354.1	280.568
1354.64	272.954
1355.18	266.192
1355.72	260.204
1356.26	255.167
1356.81	249.205
1357.35	247.027
1357.89	246.361
1358.43	244.068
1358.97	239.009
1359.51	233.711
1360.05	228.795
1360.59	224.512
1361.13	220.722
1361.67	217.384
1362.21	214.463
1362.75	212.101
1363.29	209.962
1363.83	207.909
1364.37	205.693
1364.91	203.447
1365.45	200.936
1365.99	197.867
1366.53	194.541
1367.07	191.458
1367.61	188.506
1368.15	186.197
1368.69	183.971
1369.23	181.881
1369.77	179.959
1370.31	178.2
1370.85	176.492
1371.39	175.097
1371.93	173.874
1372.47	172.72
1373.01	171.684
1373.55	170.321
1374.08	168.418
1374.62	166.553
1375.16	164.735
1375.7	163.01
1376.24	161.388
1376.78	160.069
1377.31	158.829
1377.85	157.762
1378.39	156.877
1378.93	156.223
1379.47	155.863
1380.01	155.653
1380.54	155.511
1381.08	154.997
1381.62	152.359
1382.16	149.652
1382.69	146.57
1383.23	144.009
1383.77	142.198
1384.31	141.094
1384.84	140.566
1385.38	140.473
1385.92	141.138
1386.46	141.802
1386.99	142.236
1387.53	142.09
1388.07	141.043
1388.6	139.202
1389.14	136.855
1389.68	134.441
1390.21	132.096
1390.75	130.611
1391.29	129.703
1391.82	129.708
1392.36	130.282
1392.9	130.406
1393.43	130.219
1393.97	129.711
1394.5	129.001
1395.04	128.204
1395.58	127.359
1396.11	126.494
1396.65	125.672
1397.18	124.817
1397.72	123.834
1398.25	122.55
1398.79	121.244
1399.32	119.938
1399.86	118.792
1400.39	118.138
1400.93	118.523
1401.46	118.916
1402	119.293
1402.53	119.57
1403.07	119.373
1403.6	118.704
1404.14	117.864
1404.67	116.974
1405.21	116.306
1405.74	116.5
1406.28	116.806
1406.81	116.858
1407.34	115.684
1407.88	115.234
1408.41	115.081
1408.95	114.478
1409.48	113.841
1410.01	113.167
1410.55	112.556
1411.08	111.987
1411.62	111.453
1412.15	110.95
1412.68	110.462
1413.22	109.993
1413.75	109.522
1414.28	109.058
1414.82	108.614
1415.35	108.195
1415.88	107.811
1416.42	107.507
1416.95	107.037
1417.48	106.534
1418.01	106.005
1418.55	105.463
1419.08	104.893
1419.61	104.409
1420.14	104.088
1420.68	104.73
1421.21	104.971
1421.74	104.079
1422.27	102.617
1422.81	101.27
1423.34	100.15
1423.87	99.2878
1424.4	98.6286
1424.93	99.2947
1425.46	100.593
1426	100.453
1426.53	99.1522
1427.06	99.9623
1427.59	101.704
1428.12	101.831
1428.65	100.582
1429.18	98.8867
1429.72	97.9119
1430.25	97.6676
1430.78	96.4951
1431.31	95.977
1431.84	96.2165
1432.37	96.7926
1432.9	96.7334
1433.43	95.5843
1433.96	93.8814
1434.49	93.6167
1435.02	93.3264
1435.55	93.0989
1436.08	93.3121
1436.61	93.3055
1437.14	92.8888
1437.67	92.2868
1438.2	91.5928
1438.73	91.319
1439.26	91.9516
1439.79	91.9518
1440.32	92.2477
1440.85	92.3037
1441.38	91.7668
1441.91	90.7716
1442.44	89.5121
1442.97	88.4317
1443.5	88.595
1444.03	88.8843
1444.56	89.1719
1445.09	89.6574
1445.61	89.7677
1446.14	89.2631
1446.67	88.6325
1447.2	88.229
1447.73	88.0284
1448.26	88.0463
1448.79	88.1961
1449.32	87.8783
1449.84	87.5988
1450.37	87.5708
1450.9	86.8757
1451.43	86.2813
1451.96	85.763
1452.48	84.816
1453.01	84.3212
1453.54	84.1041
1454.07	84.5295
1454.6	85.1802
1455.12	85.6962
1455.65	85.8536
1456.18	85.6906
1456.71	85.7531
1457.23	85.1641
1457.76	84.5153
1458.29	84.4795
1458.81	84.2733
1459.34	84.2858
1459.87	84.176
1460.4	83.2846
1460.92	82.106
1461.45	81.1864
1461.98	80.4866
1462.5	80.3615
1463.03	80.3886
1463.55	80.4672
1464.08	80.5148
1464.61	80.5361
1465.13	80.4296
1465.66	79.8982
1466.19	79.1668
1466.71	78.3311
1467.24	77.3783
1467.76	76.7618
1468.29	78.4991
1468.82	79.41
1469.34	80.0465
1469.87	79.9342
1470.39	79.2704
1470.92	78.6154
1471.44	78.8541
1471.97	78.697
1472.49	78.3744
1473.02	77.892
1473.54	77.3105
1474.07	76.9165
1474.59	76.3532
1475.12	75.2659
1475.64	74.4718
1476.17	74.5843
1476.69	75.1452
1477.22	76.3373
1477.74	76.5106
1478.27	76.7929
1478.79	76.62
1479.32	75.8747
1479.84	74.7853
1480.36	74.048
1480.89	73.6726
1481.41	74.3717
1481.93	74.7301
1482.46	74.2452
1482.98	74.6563
1483.51	74.8988
1484.03	74.2723
1484.55	72.7931
1485.08	71.2925
1485.6	70.283
1486.12	70.1251
1486.65	70.2968
1487.17	70.4449
1487.69	70.9022
1488.22	71.0854
1488.74	70.9656
1489.26	70.1469
1489.78	70.1906
1490.31	70.4956
1490.83	71.5145
1491.35	72.4737
1491.88	72.749
1492.4	72.4802
1492.92	71.3547
1493.44	70.2528
1493.96	69.371
1494.49	68.576
1495.01	67.6938
1495.53	67.5222
1496.05	67.6871
1496.57	67.765
1497.1	67.7397
1497.62	67.5323
1498.14	67.1019
1498.66	66.7892
1499.18	66.5153
1499.7	66.1751
1500.23	66.019
1500.75	66.1116
1501.27	66.0937
1501.79	66.0645
1502.31	65.8128
1502.83	65.2536
1503.35	64.3968
1503.87	63.5612
1504.39	63.2774
1504.91	63.4006
1505.44	64.0733
1505.96	64.6972
1506.48	65.3212
1507	65.577
1507.52	65.4383
1508.04	65.4227
1508.56	65.283
1509.08	65.031
1509.6	64.6746
1510.12	64.2643
1510.64	63.9066
1511.16	63.3375
1511.68	62.7687
1512.2	62.213
1512.72	61.6816
1513.24	61.1845
1513.76	60.7124
1514.27	60.3119
1514.79	59.9837
1515.31	59.6532
1515.83	59.5806
1516.35	59.6059
1516.87	59.8056
1517.39	60.1345
1517.91	60.189
1518.43	60.2085
1518.95	60.1848
1519.46	60.1261
1519.98	59.8627
1520.5	59.6132
1521.02	59.4259
1521.54	59.2603
1522.06	59.1242
1522.58	59.1692
1523.09	59.1076
1523.61	59.0484
1524.13	58.9974
1524.65	58.9488
1525.17	58.9279
1525.68	58.838
1526.2	58.9103
1526.72	59.0093
1527.24	59.1105
1527.75	59.2048
1528.27	59.2805
1528.79	59.2771
1529.31	59.1924
1529.82	58.9376
1530.34	58.0591
1530.86	57.1757
1531.37	56.6039
1531.89	56.5693
1532.41	57.2219
1532.92	57.6582
1533.44	58.0457
1533.96	58.3798
1534.47	58.5257
1534.99	58.6486
1535.51	58.7726
1536.02	58.6634
1536.54	58.2422
1537.06	57.7594
1537.57	57.2324
1538.09	56.7406
1538.6	56.3601
1539.12	56.0646
1539.64	56.0822
1540.15	56.6106
1540.67	57.1886
1541.18	57.8465
1541.7	58.4942
1542.21	59.1064
1542.73	59.6465
1543.25	59.9478
1543.76	60.0796
1544.28	59.6894
1544.79	59.163
1545.31	58.5126
1545.82	58.0046
1546.34	57.5981
1546.85	57.2773
1547.37	57.6274
1547.88	57.8018
1548.39	58.0378
1548.91	58.34
1549.42	58.5297
1549.94	59.0112
1550.45	59.7005
1550.97	60.3699
1551.48	60.68
1552	59.2623
1552.51	59.0907
1553.02	59.1351
1553.54	58.7414
1554.05	58.5687
1554.56	58.3292
1555.08	58.0425
1555.59	57.8795
1556.11	57.735
1556.62	57.613
1557.13	57.5694
1557.65	57.5332
1558.16	57.2226
1558.67	56.9021
1559.19	56.9395
1559.7	56.7551
1560.21	56.5768
1560.72	56.2998
1561.24	56.0948
1561.75	56.0873
1562.26	56.1823
1562.78	56.8433
1563.29	57.7441
1563.8	58.4441
1564.31	58.9684
1564.82	59.3941
1565.34	59.2791
1565.85	58.6593
1566.36	57.524
1566.87	55.9983
1567.39	54.4001
1567.9	52.4908
1568.41	50.3231
1568.92	48.0008
1569.43	45.709
1569.94	43.6982
1570.46	41.6808
1570.93	40.3323
1571.45	39.4354
1571.97	38.98
1572.49	39.0304
1573.01	38.9157
1573.53	38.7713
1574.05	38.4396
1574.57	38.2485
1575.09	38.3927
1575.61	38.5946
1576.13	38.4508
1576.64	38.2387
1577.16	37.6893
1577.68	37.473
1578.2	37.2776
1578.72	37.1228
1579.24	37.3496
1579.76	37.969
1580.28	38.4394
1580.8	38.6577
1581.31	38.6188
1581.83	38.4894
1582.35	38.7209
1582.87	38.6986
1583.39	38.3069
1583.91	37.8092
1584.42	37.7924
1584.94	37.5029
1585.46	37.1922
1585.98	36.6654
1586.5	36.7312
1587.01	36.8574
1587.53	37.1945
1588.05	37.5333
1588.57	37.6263
1589.08	37.8822
1589.6	38.1665
1590.12	38.0429
1590.64	37.9013
1591.15	37.495
1591.67	37.1744
1592.19	36.8089
1592.7	36.8645
1593.22	36.8131
1593.74	36.996
1594.26	37.5903
1594.77	37.9391
1595.29	38.07
1595.81	38.2514
1596.32	38.3169
1596.84	38.3468
1597.36	38.597
1597.87	38.4734
1598.39	38.2982
1598.9	37.725
1599.42	37.3739
1599.94	37.0396
1600.45	36.9082
1600.97	37.2333
1601.48	37.4674
1602	37.804
1602.52	38.121
1603.03	37.9601
1603.55	37.5732
1604.06	37.1507
1604.58	36.8317
1605.09	36.4976
1605.61	36.706
1606.12	37.0497
1606.64	37.6053
1607.15	38.0693
1607.67	38.1483
1608.18	37.9514
1608.7	37.9491
1609.21	37.936
1609.73	37.4216
1610.24	37.1333
1610.76	37.139
1611.27	37.2493
1611.79	37.2856
1612.3	37.1834
1612.81	37.4699
1613.33	37.5283
1613.84	37.4796
1614.36	37.2991
1614.87	37.0663
1615.38	36.9286
1615.9	36.7232
1616.41	36.4772
1616.93	36.3483
1617.44	36.2259
1617.95	36.4445
1618.47	36.563
1618.98	36.8146
1619.49	37.0017
1620.01	36.7915
1620.52	36.7675
1621.03	36.8861
1621.55	36.9435
1622.06	36.6388
1622.57	36.4642
1623.09	36.3455
1623.6	36.6952
1624.11	36.9266
1624.62	37.3459
1625.14	37.8561
1625.65	38.2519
1626.16	38.5755
1626.67	38.496
1627.19	37.8792
1627.7	37.1026
1628.21	36.3049
1628.72	35.6391
1629.23	35.0156
1629.75	34.8209
1630.26	35.3629
1630.77	35.6685
1631.28	36.0452
1631.79	36.1015
1632.3	36.2587
1632.82	35.9498
1633.33	35.5899
1633.84	35.3062
1634.35	35.9537
1634.86	36.7742
1635.37	37.6232
1635.89	37.9244
1636.4	38.1782
1636.91	38.3323
1637.42	37.6622
1637.93	36.9608
1638.44	36.3508
1638.95	35.7665
1639.46	35.6709
1639.97	35.5186
1640.48	35.3728
1640.99	35.5929
1641.5	35.7696
1642.01	35.8629
1642.52	35.7358
1643.03	35.742
1643.54	36.0943
1644.05	36.4075
1644.56	36.5556
1645.07	36.5661
1645.58	36.5735
1646.09	36.4191
1646.6	36.2681
1647.11	36.1804
1647.62	36.2504
1648.13	36.3691
1648.64	36.5901
1649.15	36.6868
1649.66	36.8828
1650.17	37.1643
1650.68	37.4034
1651.19	37.5508
1651.69	37.4336
1652.2	37.1774
1652.71	36.8327
1653.22	36.6495
1653.73	36.2667
1654.24	36.3008
1654.75	36.8511
1655.26	37.409
1655.76	37.3419
1656.27	37.2188
1656.78	37.0358
1657.29	36.6675
1657.8	36.5733
1658.31	36.3081
1658.81	36.4581
1659.32	36.8966
1659.83	37.3625
1660.34	37.4807
1660.84	37.3882
1661.35	37.4868
1661.86	37.4937
1662.37	37.3067
1662.87	36.9614
1663.38	36.6371
1663.89	36.3951
1664.4	35.9807
1664.9	36.1163
1665.41	36.2051
1665.92	36.2819
1666.42	36.2161
1666.93	35.8781
1667.44	35.4383
1667.94	35.0424
1668.45	34.898
1668.96	34.9604
1669.46	35.2874
1669.97	35.8591
1670.48	36.4274
1670.98	36.94
1671.49	36.6714
1672	36.3091
1672.5	35.9812
1673.01	35.8998
1673.51	35.7448
1674.02	35.5069
1674.53	35.6789
1675.03	35.7936
1675.54	36.1464
1676.04	36.3158
1676.55	36.3593
1677.05	36.4705
1677.56	36.0553
1678.06	35.4547
1678.57	35.0734
1679.08	35.0832
1679.58	35.1625
1680.09	35.6898
1680.59	36.1757
1681.09	36.8479
1681.6	37.8151
1682.11	38.6225
1682.61	39.1123
1683.11	39.4491
1683.62	39.169
1684.12	38.5596
1684.63	37.8202
1685.13	37.3272
1685.64	36.8986
1686.14	36.9469
1686.65	37.1987
1687.15	37.5937
1687.65	38.2048
1688.16	38.652
1688.66	38.7782
1689.16	38.715
1689.67	38.4684
1690.17	38.3035
1690.68	37.8688
1691.18	37.1668
1691.68	36.7189
1692.19	36.5483
1692.69	36.5262
1693.19	36.5757
1693.7	36.6319
1694.2	37.255
1694.7	37.9886
1695.2	38.6838
1695.71	38.6375
1696.21	37.6841
1696.71	36.2972
1697.22	37.3987
1697.72	37.6228
1698.22	36.3968
1698.72	35.135
1699.23	36.4114
1699.73	37.8558
1699.98	37.8541