File: 126GPa.txt
#Acq. time (s)=	10
#Accumulations=	1
#Range (cm-¹)=	1300...1700
#Windows=	2
#Autofocus=	Off
#AutoExposure=	Off
#Spike filter=	Single accum. (Size=3)
#Delay time (s)=	0.1
#Binning=	1
#Readout mode=	Signal
#DeNoise=	Standard
#ICS correction=	On
#Dark correction=	Off
#Inst. Process=	Off
#Instrument=	LabRAM HR Evol
#Detector=	Synapse
#Objective=	x20SLWD
#Grating=	1800 gr/mm
#ND Filter=	100%
#Laser (nm)=	633
#Hole=	150.001
#Range=	Visible
#Collection=	Microscope
#StageXY=	Marzhauser
#StageZ=	Marzhauser
#X (µm)=	0
#Y (µm)=	0
#Z (µm)=	0
#Project=	20190124
#Sample=	1-2
#Site=
#Title=	D_64
#Remark=
#Date=	19.05.2019 00:18
#Acquired=	19.05.2019 00:18:35
#Edit:Spike=	19.05.2019 00:18:47
#Edit:Spike=	19.05.2019 00:18:48
#Edit:Spike=	19.05.2019 00:18:49
#Edit:Spike=	19.05.2019 00:18:50
#Edit:Spike=	19.05.2019 00:18:51
#Edit:Spike=	19.05.2019 00:18:51
1300.13	41.7128
1300.68	42.5786
1301.23	43.3131
1301.78	44.0791
1302.32	44.7807
1302.87	45.4256
1303.42	46.0216
1303.97	46.5587
1304.52	47.0239
1305.07	47.4235
1305.61	47.6096
1306.16	47.8137
1306.71	47.5086
1307.26	47.1455
1307.8	46.5925
1308.35	46.1428
1308.9	46.1978
1309.45	46.7012
1310	47.4976
1310.54	48.3574
1311.09	49.369
1311.64	49.9939
1312.19	50.3477
1312.73	50.6114
1313.28	50.8703
1313.83	51.1515
1314.37	51.4999
1314.92	52.0232
1315.47	52.7702
1316.01	53.3008
1316.56	53.8505
1317.11	54.4545
1317.65	55.1655
1318.2	56.0419
1318.75	57.1385
1319.29	59.0912
1319.84	61.2583
1320.39	63.2651
1320.93	64.1479
1321.48	64.924
1322.02	67.2138
1322.57	70.8067
1323.11	76.4219
1323.66	77.9942
1324.21	79.838
1324.75	83.7957
1325.3	92.7776
1325.84	100.429
1326.39	110.579
1326.93	122.137
1327.48	136.941
1328.02	156.111
1328.57	180.373
1329.11	215.09
1329.66	266.004
1330.2	340.694
1330.75	470.49
1331.29	668.62
1331.84	957.849
1332.38	1332.1
1332.93	1634.32
1333.47	1796.18
1334.01	1756.83
1334.56	1608.38
1335.1	1479.56
1335.65	1303.56
1336.19	1189.83
1336.73	1092.42
1337.28	1009.47
1337.82	934.026
1338.36	875.821
1338.91	819.245
1339.45	769.289
1340	725.368
1340.54	685.994
1341.08	651.575
1341.63	617.979
1342.17	586.49
1342.71	559.091
1343.26	537.997
1343.8	527.735
1344.34	520.39
1344.88	481.482
1345.43	456.218
1345.97	436.165
1346.51	422.158
1347.05	405.54
1347.6	408.232
1348.14	386.596
1348.68	398.611
1349.22	391.773
1349.77	354.78
1350.31	349.263
1350.85	340.85
1351.39	331.216
1351.93	325.776
1352.48	316.051
1353.02	307.977
1353.56	299.948
1354.1	292.798
1354.64	286.525
1355.18	280.674
1355.72	274.783
1356.26	269.195
1356.81	264.959
1357.35	260.403
1357.89	255.134
1358.43	250.468
1358.97	247.257
1359.51	245.297
1360.05	241.235
1360.59	236.941
1361.13	232.597
1361.67	228.006
1362.21	223.323
1362.75	218.873
1363.29	214.969
1363.83	211.972
1364.37	210.251
1364.91	209.339
1365.45	208.36
1365.99	206.964
1366.53	205.112
1367.07	202.844
1367.61	200.027
1368.15	196.966
1368.69	194.085
1369.23	191.302
1369.77	188.793
1370.31	186.488
1370.85	184.401
1371.39	182.43
1371.93	180.597
1372.47	178.702
1373.01	176.875
1373.55	175.081
1374.08	173.413
1374.62	171.879
1375.16	170.506
1375.7	169.309
1376.24	168.395
1376.78	167.974
1377.31	168.011
1377.85	168.126
1378.39	167.053
1378.93	165.235
1379.47	163.116
1380.01	159.875
1380.54	157.036
1381.08	155.084
1381.62	153.899
1382.16	152.969
1382.69	152.247
1383.23	152.045
1383.77	151.988
1384.31	151.958
1384.84	151.816
1385.38	151.544
1385.92	150.968
1386.46	149.941
1386.99	148.756
1387.53	147.272
1388.07	145.28
1388.6	143.166
1389.14	141.029
1389.68	139.082
1390.21	137.946
1390.75	137.659
1391.29	137.712
1391.82	137.887
1392.36	137.967
1392.9	137.115
1393.43	135.878
1393.97	134.58
1394.5	133.298
1395.04	132.228
1395.58	131.936
1396.11	131.779
1396.65	131.727
1397.18	131.72
1397.72	130.951
1398.25	129.701
1398.79	128.393
1399.32	127.363
1399.86	126.844
1400.39	126.475
1400.93	126.127
1401.46	125.787
1402	125.464
1402.53	125.132
1403.07	124.803
1403.6	124.287
1404.14	123.742
1404.67	123.074
1405.21	122.306
1405.74	121.717
1406.28	121.426
1406.81	123.291
1407.34	120.744
1407.88	119.152
1408.41	118.122
1408.95	117.31
1409.48	116.691
1410.01	116.238
1410.55	115.594
1411.08	114.928
1411.62	114.185
1412.15	113.409
1412.68	112.959
1413.22	112.608
1413.75	112.363
1414.28	112.207
1414.82	112.108
1415.35	111.923
1415.88	111.711
1416.42	111.082
1416.95	111.176
1417.48	111.393
1418.01	111.973
1418.55	111.948
1419.08	111.794
1419.61	111.371
1420.14	110.929
1420.68	110.439
1421.21	109.934
1421.74	109.423
1422.27	108.904
1422.81	108.39
1423.34	107.957
1423.87	107.489
1424.4	107.017
1424.93	106.516
1425.46	106.019
1426	105.53
1426.53	105.055
1427.06	104.622
1427.59	104.151
1428.12	103.697
1428.65	103.255
1429.18	102.834
1429.72	102.423
1430.25	102.012
1430.78	101.638
1431.31	101.31
1431.84	101.027
1432.37	100.819
1432.9	100.642
1433.43	100.445
1433.96	100.588
1434.49	100.951
1435.02	101.198
1435.55	101.386
1436.08	101.395
1436.61	100.117
1437.14	98.5646
1437.67	96.9672
1438.2	95.4094
1438.73	95.1337
1439.26	95.2917
1439.79	95.597
1440.32	95.8969
1440.85	95.6308
1441.38	95.1874
1441.91	94.7496
1442.44	94.3347
1442.97	94.0201
1443.5	93.975
1444.03	94.2841
1444.56	94.6204
1445.09	94.8915
1445.61	95.0815
1446.14	95.1975
1446.67	94.9756
1447.2	94.2098
1447.73	93.3229
1448.26	92.4233
1448.79	91.479
1449.32	90.6104
1449.84	89.8568
1450.37	89.8798
1450.9	89.9132
1451.43	90.052
1451.96	90.1741
1452.48	90.2779
1453.01	90.3579
1453.54	90.41
1454.07	90.4342
1454.6	90.1673
1455.12	89.7231
1455.65	89.2025
1456.18	88.5094
1456.71	87.7948
1457.23	87.0781
1457.76	86.3989
1458.29	85.7663
1458.81	85.1793
1459.34	84.9416
1459.87	84.7495
1460.4	84.6432
1460.92	84.9185
1461.45	85.2478
1461.98	85.6206
1462.5	85.9733
1463.03	86.2554
1463.55	86.4174
1464.08	86.1812
1464.61	85.8439
1465.13	85.3709
1465.66	84.8002
1466.19	83.8861
1466.71	82.9265
1467.24	81.9548
1467.76	80.9784
1468.29	80.0019
1468.82	80.0219
1469.34	80.304
1469.87	80.6965
1470.39	81.0998
1470.92	81.4904
1471.44	81.837
1471.97	82.0283
1472.49	81.808
1473.02	81.5128
1473.54	81.1464
1474.07	80.7259
1474.59	80.2765
1475.12	79.6897
1475.64	79.3896
1476.17	79.1948
1476.69	79.4081
1477.22	79.5514
1477.74	79.6516
1478.27	79.7164
1478.79	79.7368
1479.32	79.6912
1479.84	79.5681
1480.36	79.0729
1480.89	78.671
1481.41	78.2525
1481.93	77.8354
1482.46	77.0082
1482.98	76.0699
1483.51	75.1292
1484.03	74.1938
1484.55	73.3465
1485.08	72.7024
1485.6	73.1654
1486.12	73.7141
1486.65	74.2611
1487.17	74.7592
1487.69	75.0505
1488.22	75.2095
1488.74	75.3085
1489.26	75.1964
1489.78	75.0128
1490.31	74.7663
1490.83	74.4331
1491.35	74.0904
1491.88	73.7275
1492.4	73.371
1492.92	73.0266
1493.44	72.7215
1493.96	72.4507
1494.49	72.1994
1495.01	72.0177
1495.53	71.8994
1496.05	71.544
1496.57	71.1652
1497.1	70.7925
1497.62	70.4393
1498.14	70.0998
1498.66	69.7083
1499.18	69.7373
1499.7	70.2022
1500.23	70.589
1500.75	70.9347
1501.27	71.1248
1501.79	71.2007
1502.31	70.6028
1502.83	69.8825
1503.35	69.0233
1503.87	68.5677
1504.39	68.2632
1504.91	68.3824
1505.44	68.5427
1505.96	68.7388
1506.48	68.5392
1507	68.0982
1507.52	67.4286
1508.04	66.8979
1508.56	66.4036
1509.08	65.9548
1509.6	65.5957
1510.12	65.4467
1510.64	65.3355
1511.16	65.2201
1511.68	65.176
1512.2	65.1857
1512.72	65.256
1513.24	65.3319
1513.76	65.4764
1514.27	65.6111
1514.79	65.731
1515.31	65.8324
1515.83	65.9086
1516.35	65.9498
1516.87	65.7721
1517.39	65.1195
1517.91	64.3607
1518.43	63.9747
1518.95	63.6092
1519.46	63.4149
1519.98	63.2658
1520.5	62.941
1521.02	62.5866
1521.54	62.0869
1522.06	61.6929
1522.58	61.3418
1523.09	61.0291
1523.61	60.7552
1524.13	60.514
1524.65	60.2962
1525.17	60.1798
1525.68	59.9728
1526.2	59.8096
1526.72	59.628
1527.24	59.4685
1527.75	59.3356
1528.27	59.0698
1528.79	59.2526
1529.31	59.4896
1529.82	60.1295
1530.34	60.7276
1530.86	60.9495
1531.37	61.0482
1531.89	60.7755
1532.41	60.5987
1532.92	60.4121
1533.44	60.2639
1533.96	60.0616
1534.47	59.8563
1534.99	59.6533
1535.51	59.5035
1536.02	59.3653
1536.54	59.2618
1537.06	59.1932
1537.57	59.1617
1538.09	59.1611
1538.6	59.1954
1539.12	59.1564
1539.64	59.444
1540.15	59.8158
1540.67	60.2237
1541.18	60.7752
1541.7	61.3438
1542.21	61.2975
1542.73	60.6079
1543.25	60.0719
1543.76	59.5436
1544.28	59.1449
1544.79	59.046
1545.31	59.1209
1545.82	59.3444
1546.34	59.7076
1546.85	60.1078
1547.37	60.5076
1547.88	60.8993
1548.39	61.2308
1548.91	61.518
1549.42	61.2744
1549.94	60.78
1550.45	60.3485
1550.97	60.1005
1551.48	59.9949
1552	60.1296
1552.51	60.36
1553.02	60.5832
1553.54	60.8143
1554.05	61.0127
1554.56	61.1011
1555.08	61.2273
1555.59	61.3468
1556.11	61.4263
1556.62	61.4218
1557.13	61.4221
1557.65	61.4441
1558.16	61.5634
1558.67	62.1339
1559.19	62.9509
1559.7	63.8421
1560.21	64.1862
1560.72	63.6885
1561.24	63.7106
1561.75	63.7275
1562.26	63.7414
1562.78	63.7602
1563.29	63.8014
1563.8	63.8559
1564.31	63.8975
1564.82	63.9262
1565.34	63.9564
1565.85	64.0181
1566.36	64.0327
1566.87	63.957
1567.39	63.796
1567.9	63.5551
1568.41	63.2577
1568.92	62.9705
1569.43	62.6976
1569.94	62.4748
1570.46	62.2532
1570.93	62.0541
1571.45	61.9328
1571.97	61.9458
1572.49	62.4925
1573.01	63.1298
1573.53	63.6462
1574.05	64.0615
1574.57	64.3248
1575.09	63.77
1575.61	63.0289
1576.13	61.924
1576.64	60.4638
1577.16	58.7168
1577.68	56.2233
1578.2	53.6034
1578.72	50.9763
1579.24	48.382
1579.76	46.3751
1580.28	44.6275
1580.8	43.1933
1581.31	42.2568
1581.83	41.4912
1582.35	40.876
1582.87	40.3814
1583.39	39.9838
1583.91	39.6631
1584.42	39.403
1584.94	39.1149
1585.46	38.8208
1585.98	38.5768
1586.5	38.3671
1587.01	38.2092
1587.53	38.0815
1588.05	37.9894
1588.57	37.9226
1589.08	37.875
1589.6	37.8406
1590.12	37.8116
1590.64	37.7816
1591.15	37.7421
1591.67	37.6961
1592.19	37.649
1592.7	37.6004
1593.22	37.5512
1593.74	37.4414
1594.26	37.4063
1594.77	37.3979
1595.29	37.4196
1595.81	37.4789
1596.32	37.5608
1596.84	37.6661
1597.36	37.7945
1597.87	37.9447
1598.39	38.1233
1598.9	38.2992
1599.42	38.4655
1599.94	38.6002
1600.45	38.6822
1600.97	38.7009
1601.48	38.4616
1602	38.3212
1602.52	38.1559
1603.03	37.9693
1603.55	37.7257
1604.06	37.3156
1604.58	37.1962
1605.09	37.1267
1605.61	37.1091
1606.12	37.3209
1606.64	37.5732
1607.15	37.7746
1607.67	37.9005
1608.18	38.0884
1608.7	38.104
1609.21	38.0859
1609.73	38.0344
1610.24	37.9523
1610.76	37.8506
1611.27	37.7043
1611.79	37.5984
1612.3	37.4559
1612.81	37.4174
1613.33	37.4008
1613.84	37.4095
1614.36	37.4433
1614.87	37.523
1615.38	37.7912
1615.9	38.0099
1616.41	38.0612
1616.93	38.0888
1617.44	38.073
1617.95	38.0248
1618.47	37.9391
1618.98	37.6546
1619.49	37.4278
1620.01	37.4412
1620.52	37.4985
1621.03	37.6014
1621.55	37.9599
1622.06	38.338
1622.57	38.3076
1623.09	38.2225
1623.6	38.0995
1624.11	37.791
1624.62	37.5814
1625.14	37.4152
1625.65	37.2774
1626.16	37.1725
1626.67	37.1003
1627.19	37.0584
1627.7	37.1227
1628.21	37.1802
1628.72	37.2167
1629.23	37.2534
1629.75	37.2857
1630.26	37.3092
1630.77	37.3357
1631.28	37.3388
1631.79	37.2641
1632.3	37.1498
1632.82	36.9825
1633.33	36.8282
1633.84	36.7895
1634.35	37.7605
1634.86	39.2828
1635.37	36.8071
1635.89	36.9214
1636.4	37.1788
1636.91	37.5851
1637.42	37.8591
1637.93	37.8124
1638.44	37.4095
1638.95	37.0117
1639.46	36.7959
1639.97	36.5769
1640.48	36.4594
1640.99	36.3803
1641.5	36.3295
1642.01	36.3058
1642.52	36.2573
1643.03	36.3976
1643.54	36.5637
1644.05	36.7536
1644.56	37.0107
1645.07	37.1682
1645.58	37.279
1646.09	37.3461
1646.6	37.3778
1647.11	37.3795
1647.62	37.3623
1648.13	37.3361
1648.64	37.3059
1649.15	37.2743
1649.66	37.2416
1650.17	37.2049
1650.68	37.161
1651.19	37.1069
1651.69	37.0404
1652.2	36.9609
1652.71	36.8691
1653.22	36.7663
1653.73	36.6541
1654.24	36.5337
1654.75	36.4073
1655.26	36.2733
1655.76	36.136
1656.27	36.0038
1656.78	35.8878
1657.29	35.8044
1657.8	35.7629
1658.31	35.7668
1658.81	35.8167
1659.32	35.9095
1659.83	36.0376
1660.34	36.187
1660.84	36.3475
1661.35	36.4982
1661.86	36.6462
1662.37	36.7882
1662.87	36.9198
1663.38	37.0358
1663.89	37.1476
1664.4	37.1932
1664.9	37.2156
1665.41	37.2271
1665.92	37.223
1666.42	37.2069
1666.93	37.1824
1667.44	37.1527
1667.94	37.1195
1668.45	37.0855
1668.96	37.0564
1669.46	37.0373
1669.97	37.0271
1670.48	37.0217
1670.98	37.0136
1671.49	37.1081
1672	36.946
1672.5	36.7511
1673.01	36.5312
1673.51	36.2968
1674.02	36.0734
1674.53	35.862
1675.03	35.8084
1675.54	36.4953
1676.04	37.1236
1676.55	37.7675
1677.05	38.3484
1677.56	38.2562
1678.06	37.5742
1678.57	37.0426
1679.08	36.6966
1679.58	36.5731
1680.09	36.6164
1680.59	36.733
1681.09	36.8636
1681.6	36.9295
1682.11	37.1635
1682.61	37.404
1683.11	37.6471
1683.62	37.8816
1684.12	38.1118
1684.63	38.2629
1685.13	38.3312
1685.64	38.2493
1686.14	37.8198
1686.65	37.0606
1687.15	36.3889
1687.65	35.803
1688.16	35.3855
1688.66	35.0607
1689.16	35.0487
1689.67	35.0645
1690.17	35.0832
1690.68	35.1386
1691.18	35.2296
1691.68	35.351
1692.19	35.4922
1692.69	35.6578
1693.19	35.8029
1693.7	35.9274
1694.2	36.0109
1694.7	36.0796
1695.2	35.9936
1695.71	35.9809
1696.21	35.9448
1696.71	35.8667
1697.22	35.7907
1697.72	35.7088
1698.22	35.6213
1698.72	35.5499
1699.23	35.5061
1699.73	36.0544
1699.98	36.4847