File: 126GPa.txt
#Acq. time (s)=	10
#Accumulations=	1
#Range=	Off
#Autofocus=	Off
#AutoExposure=	Off
#Spike filter=	Single accum. (Size=3)
#Delay time (s)=	0.1
#Binning=	1
#Readout mode=	Signal
#DeNoise=	Standard
#ICS correction=	On
#Dark correction=	Off
#Inst. Process=	Off
#Instrument=	LabRAM HR Evol
#Detector=	Synapse
#Objective=	x20SLWD
#Grating=	1800 gr/mm
#ND Filter=	100%
#Laser (nm)=	633
#Spectro (cm-¹)=	1500.02
#Hole=	150.001
#Range=	Visible
#Collection=	Microscope
#StageXY=	Marzhauser
#StageZ=	Marzhauser
#X (µm)=	0
#Y (µm)=	0
#Z (µm)=	0
#Project=	20190124
#Sample=	1-2
#Site=
#Title=	D_107
#Remark=
#Date=	19.05.2019 05:57
#Acquired=	19.05.2019 05:57:00
1364.14	345.439
1364.41	339.396
1364.68	335.954
1364.95	333.409
1365.22	330.338
1365.49	325.831
1365.76	323.205
1366.04	320.517
1366.31	319.092
1366.58	317.54
1366.85	316.473
1367.12	315.206
1367.39	314.032
1367.66	312.497
1367.93	311.572
1368.2	310.271
1368.47	308.909
1368.74	307.553
1369.01	306.211
1369.29	304.486
1369.56	302.937
1369.83	300.87
1370.1	299.045
1370.37	297.415
1370.64	295.607
1370.91	293.218
1371.18	291.978
1371.45	290.978
1371.72	290.487
1371.99	289.087
1372.26	287.155
1372.53	283.981
1372.8	280.747
1373.07	278.51
1373.34	279.195
1373.62	277.869
1373.89	276.403
1374.16	274.85
1374.43	273.403
1374.7	271.573
1374.97	270.222
1375.24	268.68
1375.51	268.513
1375.78	269.063
1376.05	268.206
1376.32	267.321
1376.59	265.841
1376.86	264.169
1377.13	261.415
1377.4	259.255
1377.67	257.185
1377.94	255.534
1378.21	254.196
1378.48	252.967
1378.75	251.891
1379.02	251.054
1379.29	251.847
1379.56	251.617
1379.83	251.206
1380.1	251.095
1380.37	250.973
1380.64	250.602
1380.91	249.995
1381.18	249.431
1381.45	248.365
1381.72	246.711
1381.99	244.774
1382.26	242.586
1382.53	240.739
1382.8	239.274
1383.07	238.124
1383.34	237.16
1383.61	235.97
1383.88	235.025
1384.15	234.764
1384.42	234.458
1384.69	234.493
1384.96	234.381
1385.23	234.491
1385.5	234.515
1385.77	234.556
1386.04	234.121
1386.31	233.573
1386.57	232.968
1386.85	231.531
1387.11	229.843
1387.38	228.447
1387.65	227.455
1387.92	226.401
1388.19	225.277
1388.46	224.108
1388.73	222.749
1389	221.22
1389.27	220.025
1389.54	219.39
1389.81	218.801
1390.08	218.107
1390.35	217.526
1390.62	217.273
1390.89	216.731
1391.16	216.493
1391.43	216.319
1391.69	215.878
1391.96	215.114
1392.23	214.177
1392.5	213.41
1392.77	212.624
1393.04	211.775
1393.31	210.314
1393.58	208.65
1393.85	207.234
1394.12	205.934
1394.39	204.891
1394.65	204.033
1394.92	203.401
1395.19	203.222
1395.46	203.105
1395.73	202.688
1396	202.19
1396.27	201.714
1396.54	200.964
1396.81	200.262
1397.07	199.128
1397.34	198.358
1397.61	197.679
1397.88	197.618
1398.15	197.477
1398.42	197.281
1398.69	197.2
1398.96	197.371
1399.23	197.748
1399.49	197.801
1399.76	198.01
1400.03	198.243
1400.3	198.203
1400.57	197.911
1400.84	196.86
1401.11	195.325
1401.37	193.75
1401.64	192.037
1401.91	190.624
1402.18	189.07
1402.45	187.411
1402.72	186.395
1402.98	185.984
1403.25	185.499
1403.52	185.304
1403.79	185.349
1404.06	185.073
1404.33	184.697
1404.6	184.624
1404.86	184.481
1405.13	184.519
1405.4	184.599
1405.67	184.58
1405.94	184.47
1406.21	183.943
1406.47	183.532
1406.74	183.455
1407.01	183.071
1407.28	182.799
1407.55	182.053
1407.81	181.051
1408.08	180.222
1408.35	178.992
1408.62	178.054
1408.89	177.673
1409.15	177.177
1409.42	176.483
1409.69	176.171
1409.96	176.826
1410.23	176.745
1410.49	176.684
1410.76	176.662
1411.03	176.307
1411.3	175.877
1411.57	175.438
1411.83	174.333
1412.1	173.663
1412.37	173.134
1412.64	172.635
1412.91	171.995
1413.17	171.329
1413.44	170.964
1413.71	170.3
1413.98	169.735
1414.24	169.336
1414.51	168.772
1414.78	168.233
1415.05	167.763
1415.31	167.6
1415.58	167.461
1415.85	167.267
1416.12	167.433
1416.38	167.314
1416.65	167.173
1416.92	167.17
1417.19	166.709
1417.45	166.597
1417.72	166.301
1417.99	165.544
1418.26	164.681
1418.52	164.15
1418.79	163.302
1419.06	162.445
1419.33	161.752
1419.59	161.294
1419.86	160.896
1420.13	160.939
1420.4	160.886
1420.66	160.893
1420.93	160.776
1421.2	160.814
1421.46	160.698
1421.73	160.422
1422	160.027
1422.27	159.627
1422.53	158.794
1422.8	157.891
1423.07	156.849
1423.33	155.932
1423.6	155.248
1423.87	154.361
1424.14	153.668
1424.4	153.454
1424.67	153.202
1424.94	153.121
1425.2	153.226
1425.47	153.48
1425.74	153.532
1426	153.747
1426.27	153.861
1426.54	153.887
1426.8	153.873
1427.07	153.803
1427.34	153.44
1427.61	153.092
1427.87	152.687
1428.14	152.297
1428.41	151.917
1428.67	151.559
1428.94	150.891
1429.21	150.245
1429.47	149.869
1429.74	149.473
1430.01	149.052
1430.27	148.862
1430.54	148.979
1430.8	148.95
1431.07	149.321
1431.34	149.309
1431.61	148.992
1431.87	148.388
1432.14	148.039
1432.4	147.463
1432.67	146.991
1432.94	146.691
1433.2	146.218
1433.47	145.847
1433.74	145.146
1434	144.502
1434.27	144.143
1434.54	144.204
1434.8	144.096
1435.07	144.172
1435.33	144.244
1435.6	143.989
1435.87	143.886
1436.13	143.468
1436.4	143.102
1436.66	142.256
1436.93	141.818
1437.2	141.724
1437.46	141.608
1437.73	141.446
1438	140.97
1438.26	140.359
1438.53	139.683
1438.79	139.221
1439.06	138.75
1439.33	138.598
1439.59	138.549
1439.86	138.475
1440.12	138.508
1440.39	138.731
1440.66	138.422
1440.92	138.307
1441.19	138.282
1441.45	138.342
1441.72	138.168
1441.98	138.21
1442.25	138.64
1442.52	138.919
1442.78	139.031
1443.05	138.947
1443.31	138.737
1443.58	138.386
1443.84	137.885
1444.11	137.32
1444.38	136.796
1444.64	136.269
1444.91	135.695
1445.17	134.977
1445.44	134.328
1445.7	133.679
1445.97	133.133
1446.23	132.901
1446.5	132.753
1446.77	133.419
1447.03	132.474
1447.3	131.258
1447.56	131.031
1447.83	131.081
1448.09	131.148
1448.36	131.5
1448.62	131.738
1448.89	132.448
1449.15	133.267
1449.42	133.548
1449.68	133.768
1449.95	133.936
1450.22	133.942
1450.48	133.399
1450.74	133.104
1451.01	132.704
1451.28	131.487
1451.54	131.079
1451.81	130.726
1452.07	130.321
1452.34	129.932
1452.6	129.775
1452.87	129.874
1453.13	129.702
1453.4	129.521
1453.66	129.765
1453.93	129.645
1454.19	130.007
1454.46	130.181
1454.72	130.139
1454.99	130.338
1455.25	130.324
1455.52	130.19
1455.78	129.746
1456.05	129.518
1456.31	129.137
1456.58	128.786
1456.84	128.512
1457.1	128.295
1457.37	128.133
1457.63	127.705
1457.9	127.382
1458.16	126.794
1458.43	126.729
1458.69	126.843
1458.96	127.295
1459.22	127.497
1459.49	127.852
1459.75	127.899
1460.02	127.847
1460.28	128.021
1460.55	128.115
1460.81	127.775
1461.07	127.36
1461.34	126.827
1461.6	126.571
1461.87	126.13
1462.13	125.918
1462.4	125.682
1462.66	125.915
1462.92	125.909
1463.19	125.622
1463.45	125.163
1463.72	124.694
1463.98	124.24
1464.25	123.867
1464.51	123.374
1464.77	122.91
1465.04	122.428
1465.3	121.84
1465.57	121.234
1465.83	120.803
1466.1	120.454
1466.36	120.519
1466.62	120.846
1466.89	121.825
1467.15	122.088
1467.42	122.852
1467.68	123.469
1467.94	123.726
1468.21	123.832
1468.47	123.93
1468.74	123.743
1469	123.73
1469.26	123.667
1469.53	123.344
1469.79	122.876
1470.06	122.216
1470.32	121.386
1470.58	120.667
1470.85	119.764
1471.11	119.397
1471.37	118.934
1471.64	118.494
1471.9	118.115
1472.17	117.89
1472.43	117.66
1472.69	117.759
1472.96	117.884
1473.22	118.147
1473.48	118.429
1473.75	118.739
1474.01	119.03
1474.28	119.689
1474.54	120.084
1474.8	120.409
1475.07	120.288
1475.33	119.817
1475.59	119.486
1475.86	119.19
1476.12	118.948
1476.38	118.858
1476.65	118.887
1476.91	118.754
1477.17	118.78
1477.44	118.504
1477.7	118.218
1477.96	117.768
1478.23	117.527
1478.49	117.353
1478.75	117.299
1479.02	117.276
1479.28	117.091
1479.54	116.669
1479.81	116.304
1480.07	115.809
1480.33	115.527
1480.6	115.575
1480.86	115.665
1481.12	116.082
1481.38	116.29
1481.65	116.505
1481.91	116.614
1482.17	116.554
1482.44	116.751
1482.7	117.046
1482.96	117.183
1483.23	117.365
1483.49	117.674
1483.75	117.774
1484.01	117.857
1484.28	117.602
1484.54	117.823
1484.8	117.616
1485.07	117.3
1485.33	117.174
1485.59	117.366
1485.85	117.454
1486.12	117.362
1486.38	117.328
1486.64	117.389
1486.9	117.147
1487.17	116.663
1487.43	116.186
1487.69	115.196
1487.96	114.847
1488.22	114.695
1488.48	114.849
1488.74	114.947
1489.01	115.006
1489.27	115.044
1489.53	114.988
1489.79	114.816
1490.06	114.49
1490.32	114.368
1490.58	114.184
1490.84	114.043
1491.11	113.936
1491.37	113.795
1491.63	113.483
1491.89	113.157
1492.16	113.267
1492.42	112.916
1492.68	112.318
1492.94	111.782
1493.21	111.043
1493.47	110.516
1493.73	110.497
1493.99	109.64
1494.25	107.157
1494.52	102.9
1494.78	105.744
1495.04	109.173
1495.3	109.516
1495.56	109.731
1495.83	109.595
1496.09	109.321
1496.35	109.168
1496.61	109.4
1496.87	110.434
1497.14	111.102
1497.4	111.687
1497.66	111.36
1497.92	110.961
1498.18	110.831
1498.45	110.665
1498.71	110.331
1498.97	110.154
1499.23	110.115
1499.49	110.254
1499.76	110.616
1500.02	110.863
1500.28	110.73
1500.54	110.84
1500.8	110.982
1501.06	111.046
1501.33	111.413
1501.59	111.806
1501.85	112.208
1502.11	112.574
1502.37	112.85
1502.63	112.931
1502.9	112.504
1503.16	112.007
1503.42	111.711
1503.68	111.207
1503.94	110.872
1504.2	110.687
1504.47	110.506
1504.73	110.064
1504.99	109.714
1505.25	109.14
1505.51	108.628
1505.77	108.405
1506.03	108.158
1506.3	107.996
1506.56	108.332
1506.82	108.623
1507.08	109.046
1507.34	109.422
1507.6	109.566
1507.86	109.721
1508.13	110.215
1508.39	110.695
1508.65	111.078
1508.91	111.294
1509.17	111.117
1509.43	110.735
1509.69	110.472
1509.95	110.323
1510.21	110.361
1510.48	110.431
1510.74	110.448
1511	110.528
1511.26	110.456
1511.52	110.375
1511.78	110.124
1512.04	110.034
1512.3	109.869
1512.56	109.485
1512.82	109.323
1513.08	109.086
1513.35	108.97
1513.61	108.765
1513.87	108.553
1514.13	108.315
1514.39	108.207
1514.65	107.968
1514.91	108.02
1515.17	108.484
1515.43	109.029
1515.69	109.648
1515.95	110.081
1516.21	110.437
1516.47	110.677
1516.74	111.077
1517	111.472
1517.26	112.095
1517.52	112.444
1517.78	112.701
1518.04	112.991
1518.3	113.323
1518.56	113.245
1518.82	112.747
1519.08	112.145
1519.34	111.362
1519.6	110.719
1519.86	110.032
1520.12	109.48
1520.38	108.936
1520.64	108.493
1520.9	108.07
1521.16	107.592
1521.42	107.585
1521.68	107.776
1521.94	107.766
1522.21	107.878
1522.47	108.265
1522.73	108.363
1522.99	108.37
1523.25	108.081
1523.51	107.906
1523.77	107.399
1524.03	107.165
1524.29	106.831
1524.55	106.706
1524.81	106.369
1525.07	106.239
1525.33	106.167
1525.59	106.025
1525.85	106.04
1526.11	105.937
1526.37	106.132
1526.63	106.446
1526.89	106.821
1527.15	107.353
1527.41	107.863
1527.67	108.533
1527.93	108.977
1528.19	109.136
1528.45	109.371
1528.71	109.5
1528.97	109.391
1529.23	109.637
1529.49	109.364
1529.74	109.044
1530	108.895
1530.26	108.775
1530.52	108.805
1530.78	108.817
1531.04	108.628
1531.3	108.473
1531.56	108.362
1531.82	108.397
1532.08	108.646
1532.34	109.097
1532.6	109.358
1532.86	109.77
1533.12	110.137
1533.38	110.195
1533.64	110.506
1533.9	110.647
1534.16	110.654
1534.42	110.347
1534.68	110.01
1534.94	109.794
1535.2	109.43
1535.45	108.89
1535.71	108.483
1535.97	107.901
1536.23	107.562
1536.49	107.534
1536.75	107.398
1537.01	107.496
1537.27	107.642
1537.53	107.881
1537.79	108.024
1538.05	108.45
1538.31	108.891
1538.57	108.991
1538.82	109.23
1539.08	109.406
1539.34	109.386
1539.6	109.322
1539.86	109.451
1540.12	109.434
1540.38	109.142
1540.64	108.723
1540.9	108.021
1541.16	107.237
1541.41	106.692
1541.67	106.464
1541.93	106.322
1542.19	106.085
1542.45	105.993
1542.71	105.933
1542.97	106.059
1543.23	106.221
1543.49	106.301
1543.74	106.507
1544	106.87
1544.26	107.09
1544.52	107.341
1544.78	107.624
1545.04	107.893
1545.3	107.833
1545.56	107.822
1545.81	107.879
1546.07	107.937
1546.33	107.947
1546.59	108.085
1546.85	108.504
1547.11	108.757
1547.37	109.028
1547.62	109.304
1547.88	109.746
1548.14	109.914
1548.4	110.107
1548.66	110.075
1548.92	110.249
1549.17	110.112
1549.43	109.697
1549.69	109.087
1549.95	108.628
1550.21	108.3
1550.47	107.964
1550.72	107.963
1550.98	107.024
1551.24	106.083
1551.5	105.023
1551.76	103.988
1552.02	103.587
1552.27	102.622
1552.53	103.642
1552.79	105.14
1553.05	107.449
1553.31	111.446
1553.57	112.977
1553.82	114.011
1554.08	112.721
1554.34	112.572
1554.6	112.256
1554.86	111.936
1555.11	112.088
1555.37	111.802
1555.63	111.894
1555.89	111.896
1556.14	111.717
1556.4	111.238
1556.66	110.722
1556.92	109.934
1557.18	109.083
1557.43	108.711
1557.69	108.571
1557.95	108.563
1558.21	108.538
1558.46	108.806
1558.72	109.218
1558.98	109.543
1559.24	110.162
1559.5	110.719
1559.75	111.558
1560.01	112.222
1560.27	112.619
1560.53	113.109
1560.78	113.766
1561.04	114.436
1561.3	115.012
1561.56	115.634
1561.81	115.994
1562.07	116.214
1562.33	116.543
1562.59	117.069
1562.84	117.461
1563.1	117.522
1563.36	117.5
1563.62	117.362
1563.87	117.284
1564.13	117.272
1564.39	117.081
1564.65	116.712
1564.9	116.058
1565.16	115.338
1565.42	114.473
1565.67	114.07
1565.93	114.854
1566.19	114.695
1566.45	114.883
1566.7	115.211
1566.96	115.466
1567.22	115.813
1567.48	115.858
1567.73	115.923
1567.99	115.977
1568.25	115.945
1568.5	115.956
1568.76	115.66
1569.02	114.896
1569.27	114.556
1569.53	114.777
1569.79	114.876
1570.05	114.969
1570.3	115.948
1570.56	116.496
1570.82	116.693
1571.07	116.809
1571.33	116.867
1571.59	116.303
1571.84	116.144
1572.1	116.144
1572.36	116.441
1572.61	116.981
1572.87	117.466
1573.13	117.876
1573.38	118.711
1573.64	119.229
1573.9	119.663
1574.15	120.403
1574.41	120.97
1574.67	121.684
1574.92	121.964
1575.18	121.733
1575.44	121.639
1575.69	121.397
1575.95	121.286
1576.21	121.156
1576.46	121.102
1576.72	121.239
1576.98	121.329
1577.23	121.286
1577.49	120.581
1577.75	119.643
1578	118.89
1578.26	117.169
1578.51	114.877
1578.77	112.542
1579.03	109.672
1579.28	106.562
1579.54	102.854
1579.8	99.3715
1580.05	95.5427
1580.31	91.4812
1580.56	87.8787
1580.82	84.4253
1581.08	81.2596
1581.33	78.5011
1581.59	76.1249
1581.85	74.0681
1582.1	72.2362
1582.36	70.6505
1582.61	69.6622
1582.87	68.2122
1583.13	66.8136
1583.38	65.4169
1583.64	64.2873
1583.89	63.0796
1584.15	61.8588
1584.41	60.5674
1584.66	59.3983
1584.92	58.3811
1585.17	57.6584
1585.43	57.0596
1585.69	56.6694
1585.94	56.2618
1586.2	56.0615
1586.45	55.9691
1586.71	55.9524
1586.96	56.0266
1587.22	56.2934
1587.48	56.455
1587.73	56.4433
1587.99	56.4752
1588.24	56.498
1588.5	56.5528
1588.75	56.5531
1589.01	56.3259
1589.27	56.2671
1589.52	56.2546
1589.78	56.3412
1590.03	56.3526
1590.29	56.3442
1590.54	56.468
1590.8	56.2201
1591.05	56.0171
1591.31	55.9187
1591.56	55.6232
1591.82	55.4048
1592.08	55.0138
1592.33	54.6125
1592.59	53.8887
1592.84	53.2705
1593.1	52.7778
1593.35	52.3393
1593.61	52.0055
1593.86	51.8539
1594.12	51.735
1594.37	51.7534
1594.63	51.8437
1594.88	52.1043
1595.14	52.4091
1595.39	52.6788
1595.65	53.0355
1595.9	53.1845
1596.16	53.3893
1596.41	53.484
1596.67	53.377
1596.93	53.4562
1597.18	53.266
1597.44	53.1301
1597.69	52.9295
1597.95	52.907
1598.2	52.991
1598.46	53.1401
1598.71	53.258
1598.97	53.2978
1599.22	53.2703
1599.47	53.0931
1599.73	53.1108
1599.98	53.0274
1600.24	52.8823
1600.49	52.7412
1600.75	52.7111
1601	52.6353
1601.26	52.5157
1601.51	52.4676
1601.77	52.3382
1602.02	52.255
1602.28	52.1925
1602.53	52.2846
1602.79	52.3789
1603.04	52.5914
1603.3	52.8184
1603.55	53.0778
1603.81	53.1908
1604.06	53.1575
1604.31	53.1074
1604.57	52.9342
1604.82	52.6395
1605.08	52.3079
1605.33	52.1106
1605.59	51.7102
1605.84	51.3137
1606.1	51.0552
1606.35	50.7554
1606.61	50.6749
1606.86	50.6744
1607.11	50.7567
1607.37	50.8945
1607.62	51.1528
1607.88	51.3569
1608.13	51.6358
1608.38	52.0479
1608.64	52.4459
1608.89	52.8109
1609.15	53.001
1609.4	53.0965
1609.66	52.9894
1609.91	52.8412
1610.16	52.8499
1610.42	52.6869
1610.67	52.6153
1610.93	52.5125
1611.18	52.3789
1611.43	52.3743
1611.69	52.3737
1611.94	52.3393
1612.2	52.1829
1612.45	51.903
1612.7	51.732
1612.96	51.6108
1613.21	51.6036
1613.47	51.6942
1613.72	51.729
1613.97	51.7299
1614.23	51.6064
1614.48	51.5307
1614.74	51.6613
1614.99	51.6411
1615.24	51.685
1615.5	51.5598
1615.75	51.4344
1616	51.4965
1616.26	51.6089
1616.51	51.832
1616.77	52.0284
1617.02	51.9777
1617.27	51.953
1617.53	52.0003
1617.78	52.0074
1618.03	52.1159
1618.29	52.1272
1618.54	52.1682
1618.8	52.2178
1619.05	52.2303
1619.3	52.2907
1619.56	52.3451
1619.81	52.4578
1620.06	52.477
1620.32	52.3645
1620.57	52.2062
1620.82	52.392
1621.08	52.4802
1621.33	52.642
1621.58	52.7152
1621.84	52.6128
1622.09	52.7047
1622.34	52.7955
1622.6	53.0172
1622.85	52.9985
1623.1	52.8087
1623.36	52.6727
1623.61	52.4993
1623.86	52.2138
1624.11	51.8167
1624.37	51.4893
1624.62	51.0746
1624.87	50.7761
1625.13	50.4268
1625.38	50.2086
1625.63	50.0009
1625.89	49.8511
1626.14	49.9497
1626.39	50.126
1626.65	50.4251
1626.9	50.7485
1627.15	51.0855
1627.4	51.3075
1627.66	51.6761
1627.91	51.8492
1628.16	52.0686
1628.42	52.2581
1628.67	52.456
1628.92	52.5772
1629.17	52.5134
1629.43	52.4145
1629.68	52.3358
1629.93	51.9829
1630.19	51.6344
1630.44	51.3226
1630.69	50.9798
1630.94	50.7563
1631.2	51.066
1631.45	51.2052
1631.7	51.459
1631.95	52.2217