File: 130GPa.txt
#Acq. time (s)=	10
#Accumulations=	1
#Range (cm-¹)=	1300...1700
#Windows=	2
#Autofocus=	Off
#AutoExposure=	Off
#Spike filter=	Single accum. (Size=3)
#Delay time (s)=	0.1
#Binning=	1
#Readout mode=	Signal
#DeNoise=	Standard
#ICS correction=	On
#Dark correction=	Off
#Inst. Process=	Off
#Instrument=	LabRAM HR Evol
#Detector=	Synapse
#Objective=	x20SLWD
#Grating=	1800 gr/mm
#ND Filter=	100%
#Laser (nm)=	633
#Hole=	150.001
#Range=	Visible
#Collection=	Microscope
#StageXY=	Marzhauser
#StageZ=	Marzhauser
#X (µm)=	0
#Y (µm)=	0
#Z (µm)=	0
#Project=	20190124
#Sample=	1-2
#Site=
#Title=	D_82
#Remark=
#Date=	19.05.2019 01:50
#Acquired=	19.05.2019 01:50:18
1300.13	76.488
1300.68	76.5898
1301.23	76.7633
1301.78	76.9677
1302.32	77.3084
1302.87	77.6415
1303.42	77.9664
1303.97	78.2962
1304.52	78.5798
1305.07	78.8493
1305.61	79.0711
1306.16	79.2805
1306.71	79.4362
1307.26	79.6007
1307.8	79.7212
1308.35	79.699
1308.9	79.6915
1309.45	79.6933
1310	79.7043
1310.54	79.7523
1311.09	79.8635
1311.64	80.0442
1312.19	80.3349
1312.73	80.7624
1313.28	81.512
1313.83	82.4362
1314.37	83.4903
1314.92	84.5895
1315.47	85.76
1316.01	86.6902
1316.56	87.5453
1317.11	87.9353
1317.65	88.4674
1318.2	89.0201
1318.75	89.6696
1319.29	90.4344
1319.84	91.522
1320.39	92.5163
1320.93	93.7386
1321.48	95.208
1322.02	96.9815
1322.57	99.1079
1323.11	101.683
1323.66	104.856
1324.21	108.615
1324.75	112.925
1325.3	117.792
1325.84	123.209
1326.39	129.321
1326.93	139.145
1327.48	151.506
1328.02	166.816
1328.57	185.69
1329.11	210.312
1329.66	239.442
1330.2	306.092
1330.75	391.902
1331.29	513.094
1331.84	680.111
1332.38	887.954
1332.93	1123.25
1333.47	1280.28
1334.01	1332.76
1334.56	1312.91
1335.1	1270.97
1335.65	1205.65
1336.19	1130.17
1336.73	1070.27
1337.28	1018.28
1337.82	968.401
1338.36	921.818
1338.91	879.909
1339.45	843.253
1340	813.729
1340.54	787.031
1341.08	760.833
1341.63	736.147
1342.17	713.724
1342.71	692.018
1343.26	669.519
1343.8	648.309
1344.34	628.155
1344.88	609.55
1345.43	592.971
1345.97	578.318
1346.51	564.425
1347.05	552.333
1347.6	541.005
1348.14	529.594
1348.68	518.213
1349.22	506.893
1349.77	495.77
1350.31	484.868
1350.85	474.19
1351.39	463.788
1351.93	453.559
1352.48	443.389
1353.02	433.464
1353.56	423.933
1354.1	414.939
1354.64	407.191
1355.18	400.397
1355.72	394.89
1356.26	390.508
1356.81	385.779
1357.35	380.002
1357.89	373.151
1358.43	365.96
1358.97	358.608
1359.51	351.658
1360.05	345.008
1360.59	338.665
1361.13	332.674
1361.67	327.071
1362.21	322.422
1362.75	318.136
1363.29	314.066
1363.83	310.124
1364.37	306.161
1364.91	301.888
1365.45	297.067
1365.99	292.104
1366.53	287.243
1367.07	282.612
1367.61	279.059
1368.15	276.134
1368.69	274.526
1369.23	273.369
1369.77	272.055
1370.31	269.9
1370.85	267.418
1371.39	264.823
1371.93	262.241
1372.47	259.699
1373.01	257.494
1373.55	254.776
1374.08	251.694
1374.62	249.81
1375.16	245.901
1375.7	241.434
1376.24	237.303
1376.78	233.679
1377.31	231.224
1377.85	229.441
1378.39	228.342
1378.93	228.475
1379.47	226.767
1380.01	225.021
1380.54	223.335
1381.08	221.695
1381.62	219.986
1382.16	218.159
1382.69	216.236
1383.23	214.227
1383.77	212.25
1384.31	210.047
1384.84	207.866
1385.38	205.821
1385.92	204.074
1386.46	202.588
1386.99	202.45
1387.53	202.332
1388.07	201.931
1388.6	200.313
1389.14	197.853
1389.68	194.898
1390.21	191.743
1390.75	188.688
1391.29	185.983
1391.82	184.996
1392.36	184.975
1392.9	184.854
1393.43	184.454
1393.97	183.717
1394.5	182.699
1395.04	181.555
1395.58	180.331
1396.11	178.979
1396.65	177.33
1397.18	175.442
1397.72	175.308
1398.25	175.223
1398.79	174.781
1399.32	174.091
1399.86	173.125
1400.39	171.711
1400.93	170.244
1401.46	168.797
1402	167.559
1402.53	167.421
1403.07	167.956
1403.6	168.119
1404.14	167.102
1404.67	166.24
1405.21	165.126
1405.74	163.47
1406.28	161.336
1406.81	161.019
1407.34	160.149
1407.88	158.875
1408.41	157.399
1408.95	155.744
1409.48	153.955
1410.01	152.692
1410.55	152.375
1411.08	153.02
1411.62	153.071
1412.15	153.734
1412.68	155.669
1413.22	156.283
1413.75	155.257
1414.28	152.929
1414.82	151.231
1415.35	150.326
1415.88	150.271
1416.42	150.384
1416.95	150.434
1417.48	150.091
1418.01	149.236
1418.55	147.941
1419.08	146.639
1419.61	145.393
1420.14	144.307
1420.68	143.591
1421.21	143.39
1421.74	143.709
1422.27	144.429
1422.81	145.099
1423.34	145.608
1423.87	145.123
1424.4	143.771
1424.93	141.611
1425.46	138.771
1426	136.044
1426.53	134.987
1427.06	134.948
1427.59	135.685
1428.12	136.43
1428.65	137.049
1429.18	137.518
1429.72	137.808
1430.25	137.9
1430.78	137.634
1431.31	137.085
1431.84	136.244
1432.37	135.272
1432.9	134.026
1433.43	132.757
1433.96	131.497
1434.49	130.289
1435.02	129.693
1435.55	129.445
1436.08	129.633
1436.61	130.045
1437.14	130.618
1437.67	131.128
1438.2	131.434
1438.73	131.083
1439.26	130.63
1439.79	130.06
1440.32	129.526
1440.85	129.064
1441.38	128.799
1441.91	128.825
1442.44	128.932
1442.97	129.013
1443.5	128.992
1444.03	128.808
1444.56	128.019
1445.09	126.742
1445.61	125.132
1446.14	124.679
1446.67	124.947
1447.2	124.978
1447.73	124.899
1448.26	124.724
1448.79	124.415
1449.32	123.929
1449.84	123.258
1450.37	122.394
1450.9	121.418
1451.43	120.42
1451.96	119.286
1452.48	118.007
1453.01	116.881
1453.54	116.901
1454.07	117.875
1454.6	118.96
1455.12	120.028
1455.65	120.901
1456.18	121.347
1456.71	121.527
1457.23	121.238
1457.76	120.355
1458.29	119.338
1458.81	118.277
1459.34	117.475
1459.87	116.817
1460.4	116.352
1460.92	116.409
1461.45	116.661
1461.98	117.05
1462.5	117.291
1463.03	117.504
1463.55	117.453
1464.08	116.915
1464.61	116.372
1465.13	116.054
1465.66	115.776
1466.19	115.568
1466.71	115.651
1467.24	115.674
1467.76	115.409
1468.29	115.13
1468.82	114.85
1469.34	114.582
1469.87	114.34
1470.39	114.143
1470.92	114.014
1471.44	113.896
1471.97	113.863
1472.49	114.217
1473.02	114.621
1473.54	115.043
1474.07	115.443
1474.59	115.833
1475.12	115.973
1475.64	115.219
1476.17	114.562
1476.69	113.803
1477.22	113.111
1477.74	112.423
1478.27	111.924
1478.79	112.179
1479.32	112.385
1479.84	112.649
1480.36	112.911
1480.89	113.123
1481.41	113.325
1481.93	113.265
1482.46	113.163
1482.98	112.749
1483.51	112.277
1484.03	111.781
1484.55	111.263
1485.08	110.727
1485.6	110.219
1486.12	109.716
1486.65	109.293
1487.17	108.909
1487.69	108.81
1488.22	108.69
1488.74	108.752
1489.26	108.882
1489.78	109.037
1490.31	109.201
1490.83	109.368
1491.35	109.525
1491.88	109.654
1492.4	109.742
1492.92	109.791
1493.44	109.559
1493.96	109.224
1494.49	108.507
1495.01	107.697
1495.53	106.927
1496.05	106.196
1496.57	105.53
1497.1	105.043
1497.62	105.399
1498.14	105.85
1498.66	106.63
1499.18	107.442
1499.7	108.257
1500.23	109.043
1500.75	109.705
1501.27	109.768
1501.79	109.68
1502.31	109.282
1502.83	108.523
1503.35	107.678
1503.87	106.835
1504.39	106.007
1504.91	105.223
1505.44	104.78
1505.96	104.402
1506.48	104.164
1507	104.048
1507.52	104.013
1508.04	104.065
1508.56	104.195
1509.08	104.408
1509.6	104.706
1510.12	105.095
1510.64	105.589
1511.16	106.205
1511.68	106.957
1512.2	106.471
1512.72	103.8
1513.24	103.052
1513.76	102.902
1514.27	103.484
1514.79	104.435
1515.31	105.034
1515.83	105.196
1516.35	104.604
1516.87	103.897
1517.39	103.264
1517.91	102.855
1518.43	102.875
1518.95	103.631
1519.46	104.435
1519.98	105.166
1520.5	105.328
1521.02	104.589
1521.54	103.588
1522.06	102.631
1522.58	101.789
1523.09	101.733
1523.61	102.058
1524.13	102.521
1524.65	102.918
1525.17	103.145
1525.68	102.36
1526.2	101.56
1526.72	100.821
1527.24	100.284
1527.75	100.285
1528.27	100.664
1528.79	101.165
1529.31	101.767
1529.82	102.323
1530.34	103.056
1530.86	103.633
1531.37	104.035
1531.89	104.156
1532.41	103.972
1532.92	102.853
1533.44	101.347
1533.96	99.9215
1534.47	98.4813
1534.99	98.2036
1535.51	98.3579
1536.02	98.603
1536.54	98.9238
1537.06	99.1611
1537.57	99.1283
1538.09	99.0096
1538.6	98.9468
1539.12	98.9266
1539.64	99.2483
1540.15	99.6396
1540.67	100.226
1541.18	100.854
1541.7	101.013
1542.21	100.875
1542.73	100.618
1543.25	100.502
1543.76	100.483
1544.28	100.534
1544.79	100.904
1545.31	101.451
1545.82	102.05
1546.34	102.532
1546.85	102.828
1547.37	102.978
1547.88	102.747
1548.39	102.2
1548.91	101.401
1549.42	100.599
1549.94	99.8858
1550.45	99.3096
1550.97	99.0496
1551.48	99.0917
1552	99.3706
1552.51	99.8881
1553.02	100.651
1553.54	101.286
1554.05	101.947
1554.56	102.58
1555.08	102.699
1555.59	101.628
1556.11	101.633
1556.62	102.286
1557.13	103.153
1557.65	104.525
1558.16	105.332
1558.67	105.453
1559.19	105.58
1559.7	105.26
1560.21	104.737
1560.72	104.52
1561.24	104.551
1561.75	104.871
1562.26	105.222
1562.78	105.879
1563.29	106.062
1563.8	106.289
1564.31	106.493
1564.82	106.252
1565.34	106.137
1565.85	106.477
1566.36	106.555
1566.87	106.59
1567.39	106.757
1567.9	107.232
1568.41	107.864
1568.92	108.393
1569.43	108.741
1569.94	109.078
1570.46	109.687
1570.93	110.394
1571.45	110.224
1571.97	110.135
1572.49	110.63
1573.01	110.781
1573.53	110.869
1574.05	110.978
1574.57	110.88
1575.09	110.896
1575.61	110.431
1576.13	109.706
1576.64	109.171
1577.16	109.873
1577.68	110.064
1578.2	110.529
1578.72	111.623
1579.24	113.385
1579.76	113.939
1580.28	115.071
1580.8	116.23
1581.31	117.066
1581.83	117.358
1582.35	116.693
1582.87	115.124
1583.39	113.338
1583.91	111.193
1584.42	107.637
1584.94	102.885
1585.46	98.3559
1585.98	93.6982
1586.5	88.8432
1587.01	84.4654
1587.53	80.5323
1588.05	77.6355
1588.57	75.5371
1589.08	74.3549
1589.6	72.7583
1590.12	71.2469
1590.64	69.5801
1591.15	68.4725
1591.67	67.4582
1592.19	67.0834
1592.7	66.6466
1593.22	65.9943
1593.74	65.6751
1594.26	65.2718
1594.77	65.0605
1595.29	64.945
1595.81	65.2142
1596.32	65.3804
1596.84	65.2452
1597.36	65.358
1597.87	65.1259
1598.39	64.5077
1598.9	63.8917
1599.42	63.584
1599.94	63.6095
1600.45	63.9403
1600.97	64.7861
1601.48	65.2533
1602	65.4507
1602.52	65.7331
1603.03	65.6421
1603.55	65.3484
1604.06	64.9082
1604.58	64.1
1605.09	63.5065
1605.61	63.2514
1606.12	63.1253
1606.64	63.0524
1607.15	62.7781
1607.67	62.8914
1608.18	63.1273
1608.7	63.576
1609.21	63.8224
1609.73	63.5419
1610.24	63.1458
1610.76	62.8295
1611.27	62.5896
1611.79	62.5742
1612.3	62.4224
1612.81	62.7446
1613.33	63.0818
1613.84	63.5718
1614.36	63.6849
1614.87	64.0953
1615.38	64.483
1615.9	64.4414
1616.41	64.4771
1616.93	64.1003
1617.44	63.3081
1617.95	62.5013
1618.47	61.8131
1618.98	61.5107
1619.49	61.3477
1620.01	61.134
1620.52	60.8629
1621.03	60.6455
1621.55	60.526
1622.06	60.5104
1622.57	60.8583
1623.09	61.5481
1623.6	62.0386
1624.11	62.0299
1624.62	62.04
1625.14	62.0301
1625.65	61.7463
1626.16	61.7913
1626.67	62.0981
1627.19	62.3876
1627.7	63.2715
1628.21	63.7945
1628.72	63.6893
1629.23	63.5167
1629.75	63.2387
1630.26	62.7937
1630.77	61.7872
1631.28	61.2442
1631.79	61.1676
1632.3	61.3383
1632.82	61.4016
1633.33	61.8045
1633.84	61.8137
1634.35	61.6382
1634.86	61.1666
1635.37	60.9372
1635.89	60.802
1636.4	60.9294
1636.91	61.0667
1637.42	61.1338
1637.93	61.2405
1638.44	61.2966
1638.95	60.9313
1639.46	60.5634
1639.97	60.2558
1640.48	60.1134
1640.99	60.0489
1641.5	60.0578
1642.01	59.9385
1642.52	59.7681
1643.03	60.1997
1643.54	60.2923
1644.05	60.3614
1644.56	60.4475
1645.07	60.4986
1645.58	59.8514
1646.09	59.9109
1646.6	60.2843
1647.11	60.1812
1647.62	60.3519
1648.13	60.6539
1648.64	60.6196
1649.15	60.6623
1649.66	60.7846
1650.17	60.9873
1650.68	61.1918
1651.19	61.1874
1651.69	61.1333
1652.2	60.5431
1652.71	60.0427
1653.22	59.6403
1653.73	59.3874
1654.24	59.3381
1654.75	59.7003
1655.26	60.095
1655.76	60.8559
1656.27	60.7503
1656.78	60.462
1657.29	60.173
1657.8	59.67
1658.31	59.3539
1658.81	59.248
1659.32	59.6389
1659.83	59.5978
1660.34	59.8051
1660.84	60.0381
1661.35	59.8543
1661.86	59.9064
1662.37	59.711
1662.87	59.4909
1663.38	59.4528
1663.89	59.6754
1664.4	60.8179
1664.9	61.9941
1665.41	62.9108
1665.92	62.9369
1666.42	62.591
1666.93	62.5135
1667.44	61.9106
1667.94	61.3259
1668.45	60.3639
1668.96	59.5656
1669.46	59.3417
1669.97	59.4442
1670.48	59.5415
1670.98	60.3614
1671.49	61.1834
1672	61.6617
1672.5	61.3671
1673.01	60.4135
1673.51	59.8622
1674.02	59.1009
1674.53	59.293
1675.03	58.9104
1675.54	58.8237
1676.04	59.0541
1676.55	59.477
1677.05	59.9567
1677.56	59.9634
1678.06	59.778
1678.57	59.3252
1679.08	58.7806
1679.58	58.8517
1680.09	58.949
1680.59	59.3443
1681.09	59.6998
1681.6	59.9446
1682.11	60.0842
1682.61	60.3276
1683.11	60.3055
1683.62	59.8151
1684.12	59.2154
1684.63	58.4997
1685.13	58.0201
1685.64	57.459
1686.14	57.0892
1686.65	56.8718
1687.15	57.5756
1687.65	58.5845
1688.16	59.3772
1688.66	59.9187
1689.16	60.4022
1689.67	60.7428
1690.17	61.2015
1690.68	61.2775
1691.18	61.2509
1691.68	60.847
1692.19	59.9473
1692.69	59.0036
1693.19	58.0439
1693.7	57.4941
1694.2	57.1732
1694.7	57.0951
1695.2	57.0963
1695.71	57.3627
1696.21	57.8104
1696.71	58.2015
1697.22	58.6712
1697.72	59.1263
1698.22	59.7586
1698.72	60.1697
1699.23	60.2748
1699.73	60.1601
1699.98	59.8105