File: 134.8GPa.txt
#Acq. time (s)=	10
#Accumulations=	1
#Range (cm-¹)=	1300...1700
#Windows=	2
#Autofocus=	Off
#AutoExposure=	Off
#Spike filter=	Single accum. (Size=3)
#Delay time (s)=	0.1
#Binning=	1
#Readout mode=	Signal
#DeNoise=	Standard
#ICS correction=	On
#Dark correction=	Off
#Inst. Process=	Off
#Instrument=	LabRAM HR Evol
#Detector=	Synapse
#Objective=	x20SLWD
#Grating=	1800 gr/mm
#ND Filter=	100%
#Laser (nm)=	633
#Hole=	150.001
#Range=	Visible
#Collection=	Microscope
#StageXY=	Marzhauser
#StageZ=	Marzhauser
#X (µm)=	0
#Y (µm)=	0
#Z (µm)=	0
#Project=	20190124
#Sample=	1-2
#Site=
#Title=	D_56
#Remark=
#Date=	18.05.2019 23:55
#Acquired=	18.05.2019 23:55:00
1300.13	46.0467
1300.68	46.2262
1301.23	46.4633
1301.78	46.7163
1302.32	46.9094
1302.87	47.02
1303.42	47.0161
1303.97	47.039
1304.52	47.2812
1305.07	47.5514
1305.61	47.8518
1306.16	48.1538
1306.71	48.4604
1307.26	48.6261
1307.8	48.5165
1308.35	47.9016
1308.9	47.5761
1309.45	47.5743
1310	48.4901
1310.54	49.4021
1311.09	50.2322
1311.64	50.9626
1312.19	51.1068
1312.73	51.1041
1313.28	51.1012
1313.83	51.1922
1314.37	51.4163
1314.92	51.9163
1315.47	52.8356
1316.01	53.8676
1316.56	54.9854
1317.11	56.1916
1317.65	57.4163
1318.2	58.6745
1318.75	60.7178
1319.29	61.2761
1319.84	61.472
1320.39	61.8751
1320.93	62.7917
1321.48	64.4071
1322.02	66.7417
1322.57	70.1323
1323.11	74.9925
1323.66	79.8475
1324.21	84.1183
1324.75	88.4081
1325.3	92.9035
1325.84	98.291
1326.39	104.725
1326.93	113.074
1327.48	126.589
1328.02	146.488
1328.57	172.386
1329.11	205.87
1329.66	251.937
1330.2	320.428
1330.75	438.12
1331.29	612.362
1331.84	857.642
1332.38	1182.37
1332.93	1457.28
1333.47	1619.03
1334.01	1603.29
1334.56	1517.46
1335.1	1400.95
1335.65	1236
1336.19	1158.31
1336.73	1067.04
1337.28	978.979
1337.82	906.644
1338.36	848.356
1338.91	792.207
1339.45	745.338
1340	705.409
1340.54	671.393
1341.08	640.517
1341.63	612.345
1342.17	585.303
1342.71	558.853
1343.26	534.454
1343.8	509.298
1344.34	487.755
1344.88	469.616
1345.43	452.138
1345.97	436.729
1346.51	423.912
1347.05	411.422
1347.6	399.683
1348.14	388.413
1348.68	377.987
1349.22	368.794
1349.77	362.098
1350.31	355.803
1350.85	348.279
1351.39	341.662
1351.93	335.606
1352.48	329.757
1353.02	322.711
1353.56	316.314
1354.1	310.158
1354.64	304.586
1355.18	299.613
1355.72	293.585
1356.26	287.59
1356.81	281.9
1357.35	277.039
1357.89	271.768
1358.43	266.048
1358.97	261.2
1359.51	257.585
1360.05	254.86
1360.59	252.125
1361.13	250
1361.67	248.56
1362.21	246.963
1362.75	244.394
1363.29	240.577
1363.83	236.866
1364.37	234.379
1364.91	231.956
1365.45	229.099
1365.99	225.751
1366.53	222.694
1367.07	219.077
1367.61	215.51
1368.15	211.987
1368.69	209.192
1369.23	206.873
1369.77	205.509
1370.31	204.441
1370.85	203.53
1371.39	202.709
1371.93	201.114
1372.47	199.295
1373.01	197.29
1373.55	195.326
1374.08	193.412
1374.62	191.602
1375.16	190.193
1375.7	188.829
1376.24	187.434
1376.78	186.041
1377.31	184.57
1377.85	182.984
1378.39	181.025
1378.93	179.331
1379.47	178.042
1380.01	176.117
1380.54	173.903
1381.08	172.732
1381.62	172.496
1382.16	172.234
1382.69	171.542
1383.23	170.377
1383.77	168.73
1384.31	166.338
1384.84	163.888
1385.38	161.799
1385.92	160.929
1386.46	161.987
1386.99	162.115
1387.53	160.701
1388.07	159.091
1388.6	157.376
1389.14	155.563
1389.68	154.09
1390.21	153.334
1390.75	153.21
1391.29	153.312
1391.82	153.285
1392.36	153.019
1392.9	152.682
1393.43	152.523
1393.97	152.675
1394.5	152.251
1395.04	150.38
1395.58	147.994
1396.11	146.334
1396.65	144.979
1397.18	144.726
1397.72	144.291
1398.25	143.095
1398.79	141.788
1399.32	140.715
1399.86	139.916
1400.39	139.549
1400.93	138.99
1401.46	138.442
1402	138.356
1402.53	137.183
1403.07	135.622
1403.6	134.205
1404.14	133.681
1404.67	133.673
1405.21	133.947
1405.74	134.381
1406.28	134.93
1406.81	135.417
1407.34	134.871
1407.88	133.314
1408.41	131.596
1408.95	129.795
1409.48	129.062
1410.01	128.519
1410.55	128.165
1411.08	127.882
1411.62	127.615
1412.15	127.316
1412.68	126.789
1413.22	126.228
1413.75	125.637
1414.28	124.948
1414.82	124.207
1415.35	123.392
1415.88	122.557
1416.42	121.76
1416.95	121.051
1417.48	120.481
1418.01	120.521
1418.55	120.997
1419.08	121.055
1419.61	120.351
1420.14	119.076
1420.68	117.288
1421.21	116.318
1421.74	116.417
1422.27	117.189
1422.81	116.351
1423.34	115.501
1423.87	114.701
1424.4	113.966
1424.93	113.329
1425.46	112.786
1426	112.293
1426.53	111.821
1427.06	111.344
1427.59	110.857
1428.12	110.433
1428.65	110.098
1429.18	109.958
1429.72	110.103
1430.25	111.33
1430.78	112.583
1431.31	113.191
1431.84	112.248
1432.37	110.893
1432.9	109.482
1433.43	108.286
1433.96	107.209
1434.49	106.234
1435.02	105.364
1435.55	104.641
1436.08	103.862
1436.61	103.823
1437.14	103.902
1437.67	104.052
1438.2	104.19
1438.73	104.307
1439.26	104.06
1439.79	103.851
1440.32	103.623
1440.85	103.337
1441.38	103.005
1441.91	102.573
1442.44	102.107
1442.97	101.565
1443.5	101.023
1444.03	100.504
1444.56	100.017
1445.09	99.5608
1445.61	99.231
1446.14	99.1064
1446.67	99.4988
1447.2	99.9299
1447.73	100.19
1448.26	100.2
1448.79	99.0049
1449.32	95.7219
1449.84	94.361
1450.37	93.892
1450.9	93.8266
1451.43	94.2947
1451.96	96.2617
1452.48	97.1866
1453.01	97.6586
1453.54	96.47
1454.07	95.4218
1454.6	94.22
1455.12	93.5525
1455.65	93.1028
1456.18	93.1804
1456.71	93.341
1457.23	93.4492
1457.76	93.6758
1458.29	93.2931
1458.81	92.6781
1459.34	92.0192
1459.87	91.4074
1460.4	90.8426
1460.92	90.3286
1461.45	89.872
1461.98	89.6394
1462.5	89.3805
1463.03	89.1609
1463.55	88.9631
1464.08	88.67
1464.61	88.8356
1465.13	89.0701
1465.66	89.3203
1466.19	89.5496
1466.71	89.5967
1467.24	89.4204
1467.76	88.0393
1468.29	86.8992
1468.82	85.7924
1469.34	85.1096
1469.87	85.0607
1470.39	85.232
1470.92	85.1288
1471.44	84.9541
1471.97	84.7402
1472.49	84.3535
1473.02	83.8646
1473.54	83.7772
1474.07	83.7653
1474.59	83.9558
1475.12	84.0133
1475.64	84.0071
1476.17	83.8784
1476.69	83.7669
1477.22	83.7201
1477.74	83.672
1478.27	83.6164
1478.79	83.5565
1479.32	83.4255
1479.84	82.9285
1480.36	82.296
1480.89	81.1876
1481.41	80.812
1481.93	81.0316
1482.46	81.4327
1482.98	81.3406
1483.51	81.0744
1484.03	80.7824
1484.55	80.5608
1485.08	80.3601
1485.6	80.1868
1486.12	80.0579
1486.65	80.0555
1487.17	80.0455
1487.69	80.0379
1488.22	80.0338
1488.74	80.0152
1489.26	79.976
1489.78	79.9155
1490.31	79.8274
1490.83	79.7276
1491.35	79.6345
1491.88	79.5415
1492.4	79.2723
1492.92	78.9932
1493.44	78.4591
1493.96	77.8876
1494.49	77.1243
1495.01	76.4862
1495.53	75.9313
1496.05	75.4413
1496.57	75.2476
1497.1	75.1454
1497.62	75.1769
1498.14	75.6331
1498.66	76.2452
1499.18	76.8447
1499.7	77.3521
1500.23	77.7795
1500.75	77.8457
1501.27	77.2505
1501.79	76.5821
1502.31	75.891
1502.83	75.1563
1503.35	74.4314
1503.87	73.7569
1504.39	73.403
1504.91	73.1546
1505.44	73.001
1505.96	72.9895
1506.48	73.201
1507	73.7457
1507.52	74.9035
1508.04	76.1757
1508.56	74.525
1509.08	72.4007
1509.6	70.1991
1510.12	69.6771
1510.64	70.2361
1511.16	70.6475
1511.68	70.9949
1512.2	71.4149
1512.72	71.2729
1513.24	71.5916
1513.76	71.7653
1514.27	71.6831
1514.79	71.461
1515.31	71.0825
1515.83	70.5801
1516.35	70.0701
1516.87	69.386
1517.39	68.7068
1517.91	68.0609
1518.43	67.4692
1518.95	66.9421
1519.46	66.5207
1519.98	66.2474
1520.5	66.1591
1521.02	66.7011
1521.54	67.5249
1522.06	68.3122
1522.58	68.9683
1523.09	69.2792
1523.61	68.2327
1524.13	67.2743
1524.65	66.4866
1525.17	65.8905
1525.68	65.6721
1526.2	65.5481
1526.72	65.5017
1527.24	65.5051
1527.75	65.476
1528.27	65.5862
1528.79	65.7036
1529.31	65.796
1529.82	65.9049
1530.34	66.0081
1530.86	66.0918
1531.37	66.1227
1531.89	66.1034
1532.41	65.9336
1532.92	65.729
1533.44	65.4349
1533.96	64.9193
1534.47	64.184
1534.99	63.5859
1535.51	63.0484
1536.02	62.6198
1536.54	62.3391
1537.06	62.908
1537.57	63.7027
1538.09	65.0293
1538.6	66.8843
1539.12	66.6079
1539.64	64.7652
1540.15	64.481
1540.67	64.3099
1541.18	63.4516
1541.7	62.6141
1542.21	61.5328
1542.73	60.5876
1543.25	60.5084
1543.76	60.7191
1544.28	61.2467
1544.79	62.1265
1545.31	62.7675
1545.82	62.5709
1546.34	61.7136
1546.85	61.7008
1547.37	61.7226
1547.88	61.7843
1548.39	61.9087
1548.91	62.0607
1549.42	62.2369
1549.94	62.27
1550.45	62.3017
1550.97	62.296
1551.48	62.2766
1552	62.247
1552.51	62.1965
1553.02	62.1584
1553.54	62.1601
1554.05	62.2248
1554.56	62.3536
1555.08	62.7254
1555.59	63.1065
1556.11	63.4165
1556.62	63.576
1557.13	63.621
1557.65	63.8806
1558.16	63.8069
1558.67	63.7011
1559.19	63.656
1559.7	63.7033
1560.21	63.9708
1560.72	64.6076
1561.24	65.3695
1561.75	66.0973
1562.26	66.6738
1562.78	66.8789
1563.29	66.8344
1563.8	66.5465
1564.31	66.2286
1564.82	66.0454
1565.34	66.1378
1565.85	66.2842
1566.36	66.5374
1566.87	66.7685
1567.39	67.0385
1567.9	67.2114
1568.41	67.3257
1568.92	67.3623
1569.43	67.3871
1569.94	67.4326
1570.46	67.5217
1570.93	67.6236
1571.45	67.7529
1571.97	67.9081
1572.49	68.0822
1573.01	68.2714
1573.53	68.4831
1574.05	68.6314
1574.57	68.9902
1575.09	69.3912
1575.61	69.8184
1576.13	70.2513
1576.64	70.6833
1577.16	71.1041
1577.68	71.5049
1578.2	71.8112
1578.72	72.0731
1579.24	71.6173
1579.76	71.2407
1580.28	70.7806
1580.8	70.3856
1581.31	70.0008
1581.83	69.9454
1582.35	70.504
1582.87	71.0479
1583.39	71.6168
1583.91	72.2096
1584.42	72.4332
1584.94	72.2765
1585.46	72.0088
1585.98	71.8198
1586.5	71.7896
1587.01	71.9851
1587.53	72.6798
1588.05	73.4969
1588.57	74.1136
1589.08	74.4093
1589.6	73.7366
1590.12	72.2827
1590.64	70.1459
1591.15	67.6411
1591.67	65.2889
1592.19	63.3122
1592.7	61.3476
1593.22	59.4492
1593.74	57.6744
1594.26	55.2164
1594.77	52.6195
1595.29	50.199
1595.81	47.8898
1596.32	46.0062
1596.84	45.0575
1597.36	44.3994
1597.87	43.7674
1598.39	43.236
1598.9	42.7713
1599.42	42.3569
1599.94	41.7507
1600.45	41.3029
1600.97	40.8982
1601.48	40.589
1602	40.3294
1602.52	40.1752
1603.03	40.1824
1603.55	40.3902
1604.06	40.7532
1604.58	41.0722
1605.09	41.3761
1605.61	41.6886
1606.12	41.5501
1606.64	40.789
1607.15	40.2414
1607.67	39.783
1608.18	39.4183
1608.7	39.2504
1609.21	39.2581
1609.73	39.2585
1610.24	39.2414
1610.76	39.3015
1611.27	39.5238
1611.79	39.7901
1612.3	40.0709
1612.81	40.3527
1613.33	40.5315
1613.84	40.6574
1614.36	40.4146
1614.87	39.7889
1615.38	39.1909
1615.9	38.6955
1616.41	38.6828
1616.93	39.0353
1617.44	39.3841
1617.95	39.7344
1618.47	39.9038
1618.98	39.9986
1619.49	39.9692
1620.01	39.8836
1620.52	39.7972
1621.03	39.7114
1621.55	39.5385
1622.06	39.4637
1622.57	39.4181
1623.09	39.4131
1623.6	39.4224
1624.11	39.447
1624.62	39.4908
1625.14	39.5554
1625.65	39.7984
1626.16	39.91
1626.67	39.9926
1627.19	40.0426
1627.7	40.0657
1628.21	40.0562
1628.72	39.9931
1629.23	39.7918
1629.75	39.626
1630.26	39.4685
1630.77	39.3175
1631.28	39.1724
1631.79	39.0461
1632.3	38.9472
1632.82	38.8815
1633.33	38.9611
1633.84	38.9717
1634.35	38.9803
1634.86	38.9723
1635.37	38.951
1635.89	39.1131
1636.4	39.3216
1636.91	39.5677
1637.42	39.8545
1637.93	40.1539
1638.44	40.4283
1638.95	40.3419
1639.46	40.152
1639.97	39.6093
1640.48	39.2742
1640.99	39.0007
1641.5	38.7869
1642.01	38.7691
1642.52	38.7547
1643.03	38.7214
1643.54	38.6924
1644.05	38.6795
1644.56	38.6946
1645.07	38.7355
1645.58	38.7949
1646.09	38.8647
1646.6	38.9447
1647.11	39.0301
1647.62	39.1165
1648.13	39.2043
1648.64	39.2969
1649.15	39.3781
1649.66	39.4625
1650.17	39.5553
1650.68	39.6609
1651.19	39.7707
1651.69	39.8594
1652.2	39.9806
1652.71	40.087
1653.22	40.291
1653.73	40.5177
1654.24	40.7622
1654.75	40.9869
1655.26	41.0932
1655.76	41.0249
1656.27	40.2562
1656.78	39.5508
1657.29	38.7938
1657.8	38.1756
1658.31	38.0093
1658.81	38.2941
1659.32	38.9777
1659.83	39.8
1660.34	40.583
1660.84	41.2246
1661.35	40.7581
1661.86	40.0903
1662.37	39.3623
1662.87	38.6252
1663.38	38.5712
1663.89	38.7293
1664.4	38.9964
1664.9	39.2552
1665.41	39.5635
1665.92	39.8002
1666.42	39.8609
1666.93	39.789
1667.44	39.5739
1667.94	39.3124
1668.45	39.0448
1668.96	38.7646
1669.46	38.4817
1669.97	38.2176
1670.48	37.9293
1670.98	37.7742
1671.49	37.94
1672	38.2436
1672.5	38.5577
1673.01	38.9548
1673.51	39.4999
1674.02	39.8479
1674.53	39.971
1675.03	39.7773
1675.54	39.6184
1676.04	39.4374
1676.55	39.2405
1677.05	39.0616
1677.56	38.8974
1678.06	38.7443
1678.57	38.6228
1679.08	38.5727
1679.58	38.4761
1680.09	38.3945
1680.59	38.3474
1681.09	38.3307
1681.6	38.331
1682.11	38.3363
1682.61	38.3254
1683.11	38.3066
1683.62	38.2842
1684.12	38.2664
1684.63	38.2361
1685.13	38.2476
1685.64	38.2849
1686.14	38.3421
1686.65	38.4004
1687.15	38.4602
1687.65	38.5219
1688.16	38.5833
1688.66	38.6482
1689.16	38.7235
1689.67	38.807
1690.17	38.8922
1690.68	38.9951
1691.18	39.0988
1691.68	39.1918
1692.19	39.308
1692.69	39.44
1693.19	39.5717
1693.7	39.7052
1694.2	39.8362
1694.7	39.9626
1695.2	40.0845
1695.71	40.1905
1696.21	40.2671
1696.71	40.3003
1697.22	40.2816
1697.72	40.1997
1698.22	40.0463
1698.72	39.8128
1699.23	39.3115
1699.73	38.5496
1699.98	38.0832