File: 1415CM.txt
#Acq. time (s)=	10
#Accumulations=	1
#Range (cm-¹)=	1300...1700
#Windows=	2
#Autofocus=	Off
#AutoExposure=	Off
#Spike filter=	Single accum. (Size=3)
#Delay time (s)=	0.1
#Binning=	1
#Readout mode=	Signal
#DeNoise=	Standard
#ICS correction=	On
#Dark correction=	Off
#Inst. Process=	Off
#Instrument=	LabRAM HR Evol
#Detector=	Synapse
#Objective=	x20SLWD
#Grating=	1800 gr/mm
#ND Filter=	100%
#Laser (nm)=	633
#Hole=	150.001
#Range=	Visible
#Collection=	Microscope
#StageXY=	Marzhauser
#StageZ=	Marzhauser
#X (µm)=	0
#Y (µm)=	0
#Z (µm)=	0
#Project=	20190124
#Sample=	1-2
#Site=
#Title=	D_53
#Remark=
#Date=	18.05.2019 23:40
#Acquired=	18.05.2019 23:40:32
1300.13	184.114
1300.68	189.787
1301.23	192.421
1301.78	193.227
1302.32	193.445
1302.87	193.416
1303.42	193.116
1303.97	192.638
1304.52	191.846
1305.07	190.985
1305.61	190.137
1306.16	189.295
1306.71	188.926
1307.26	188.95
1307.8	189.207
1308.35	189.463
1308.9	189.791
1309.45	190.198
1310	190.325
1310.54	190.78
1311.09	191.536
1311.64	192.409
1312.19	193.376
1312.73	194.397
1313.28	195.426
1313.83	196.44
1314.37	197.439
1314.92	198.115
1315.47	198.748
1316.01	199.164
1316.56	199.35
1317.11	199.407
1317.65	199.842
1318.2	200.612
1318.75	200.689
1319.29	201.284
1319.84	202.913
1320.39	204.403
1320.93	208.155
1321.48	211.017
1322.02	213.826
1322.57	217.031
1323.11	220.415
1323.66	223.477
1324.21	226.74
1324.75	230.583
1325.3	235.385
1325.84	241.665
1326.39	249.46
1326.93	259.284
1327.48	272.773
1328.02	293.227
1328.57	319.856
1329.11	352.383
1329.66	399.855
1330.2	473.213
1330.75	592.207
1331.29	767.996
1331.84	1019.56
1332.38	1320.35
1332.93	1646.38
1333.47	1816.56
1334.01	1828.61
1334.56	1786.46
1335.1	1645.31
1335.65	1545.13
1336.19	1441.53
1336.73	1351.11
1337.28	1272.5
1337.82	1203.81
1338.36	1143.21
1338.91	1088.98
1339.45	1040.92
1340	1004.21
1340.54	972.485
1341.08	943.084
1341.63	913.656
1342.17	882.013
1342.71	852.205
1343.26	825.177
1343.8	801.873
1344.34	780.321
1344.88	761.406
1345.43	745.625
1345.97	730.147
1346.51	715.52
1347.05	702.259
1347.6	688.959
1348.14	675.656
1348.68	665.384
1349.22	653.859
1349.77	641.933
1350.31	630.8
1350.85	620.291
1351.39	610.746
1351.93	602.394
1352.48	595.508
1353.02	591.088
1353.56	586.45
1354.1	577.626
1354.64	568.729
1355.18	560.022
1355.72	555.063
1356.26	552.221
1356.81	548.719
1357.35	544.737
1357.89	541.396
1358.43	537.415
1358.97	533.292
1359.51	529.137
1360.05	525.496
1360.59	523.991
1361.13	520.977
1361.67	515.59
1362.21	510.038
1362.75	505.158
1363.29	501.334
1363.83	498.427
1364.37	496.523
1364.91	495.519
1365.45	495.103
1365.99	492.929
1366.53	489.594
1367.07	485.421
1367.61	481.58
1368.15	479.327
1368.69	475.923
1369.23	474.122
1369.77	472.698
1370.31	471.174
1370.85	469.784
1371.39	468.517
1371.93	467.346
1372.47	466.196
1373.01	465.083
1373.55	463.856
1374.08	462.947
1374.62	462.247
1375.16	461.708
1375.7	461.201
1376.24	460.713
1376.78	460.146
1377.31	459.203
1377.85	458.098
1378.39	456.81
1378.93	455.962
1379.47	456.1
1380.01	457.167
1380.54	455.932
1381.08	453.224
1381.62	451.005
1382.16	446.714
1382.69	441.996
1383.23	439.222
1383.77	438.782
1384.31	440.71
1384.84	444.626
1385.38	447.668
1385.92	450.783
1386.46	452.904
1386.99	452.866
1387.53	451.3
1388.07	449.057
1388.6	447.095
1389.14	446.279
1389.68	446.429
1390.21	447.17
1390.75	447.985
1391.29	448.646
1391.82	449.07
1392.36	449.006
1392.9	448.358
1393.43	447.638
1393.97	446.935
1394.5	446.34
1395.04	447.347
1395.58	447.865
1396.11	447.425
1396.65	449.499
1397.18	453.987
1397.72	455.99
1398.25	455.75
1398.79	454.865
1399.32	453.985
1399.86	451.86
1400.39	451.584
1400.93	451.931
1401.46	453.417
1402	452.296
1402.53	450.639
1403.07	447.696
1403.6	443.578
1404.14	440.256
1404.67	439.101
1405.21	437.632
1405.74	436.427
1406.28	435.6
1406.81	434.377
1407.34	433.817
1407.88	434.266
1408.41	435.392
1408.95	437.296
1409.48	440.811
1410.01	445.28
1410.55	448.681
1411.08	450.892
1411.62	450.469
1412.15	447.679
1412.68	442.765
1413.22	437.211
1413.75	416.898
1414.28	389.632
1414.82	359.359
1415.35	329.111
1415.88	301.129
1416.42	279.64
1416.95	259.72
1417.48	243.506
1418.01	229.564
1418.55	218.278
1419.08	209.715
1419.61	202.556
1420.14	198.638
1420.68	196.533
1421.21	195.01
1421.74	193.789
1422.27	192.849
1422.81	192.17
1423.34	191.628
1423.87	191.5
1424.4	191.419
1424.93	191.386
1425.46	191.912
1426	191.872
1426.53	190.556
1427.06	187.944
1427.59	184.235
1428.12	184.88
1428.65	191.879
1429.18	182.531
1429.72	184.598
1430.25	187.663
1430.78	188.46
1431.31	188.448
1431.84	188.541
1432.37	189.069
1432.9	189.392
1433.43	188.938
1433.96	187.643
1434.49	186.825
1435.02	186.729
1435.55	186.139
1436.08	185.385
1436.61	184.877
1437.14	184.793
1437.67	184.847
1438.2	184.833
1438.73	184.899
1439.26	185.187
1439.79	186.17
1440.32	187.453
1440.85	184.647
1441.38	181.22
1441.91	181.924
1442.44	185.455
1442.97	187.397
1443.5	187.768
1444.03	186.227
1444.56	185.641
1445.09	185.69
1445.61	185.424
1446.14	185.355
1446.67	186.246
1447.2	186.439
1447.73	186.081
1448.26	184.64
1448.79	183.724
1449.32	183.333
1449.84	183.383
1450.37	183.709
1450.9	184.409
1451.43	185.402
1451.96	186.601
1452.48	187.684
1453.01	188.513
1453.54	188.73
1454.07	188.142
1454.6	186.585
1455.12	184.522
1455.65	182.628
1456.18	182.003
1456.71	181.791
1457.23	182.101
1457.76	183.124
1458.29	184.015
1458.81	182.902
1459.34	180.958
1459.87	180.641
1460.4	183.316
1460.92	187.416
1461.45	187.437
1461.98	185.947
1462.5	183.586
1463.03	183.787
1463.55	186.864
1464.08	187.658
1464.61	188.095
1465.13	188.223
1465.66	186.891
1466.19	185.661
1466.71	184.945
1467.24	184.567
1467.76	184.389
1468.29	186.413
1468.82	187.017
1469.34	186.712
1469.87	187.369
1470.39	187.991
1470.92	188.949
1471.44	190.196
1471.97	190.62
1472.49	190.824
1473.02	190.103
1473.54	189.299
1474.07	188.475
1474.59	187.684
1475.12	186.95
1475.64	186.382
1476.17	186.033
1476.69	185.787
1477.22	185.72
1477.74	185.771
1478.27	185.878
1478.79	186.071
1479.32	186.464
1479.84	186.926
1480.36	187.412
1480.89	187.86
1481.41	188.28
1481.93	188.281
1482.46	188.049
1482.98	187.49
1483.51	186.867
1484.03	186.363
1484.55	186.238
1485.08	186.047
1485.6	185.553
1486.12	184.587
1486.65	186.696
1487.17	189.297
1487.69	189.851
1488.22	189.208
1488.74	188.486
1489.26	187.315
1489.78	186.276
1490.31	185.637
1490.83	185.162
1491.35	184.398
1491.88	184.755
1492.4	186.244
1492.92	187.874
1493.44	189.015
1493.96	189.458
1494.49	188.985
1495.01	188.663
1495.53	187.917
1496.05	187.481
1496.57	187.456
1497.1	187.575
1497.62	187.874
1498.14	188.24
1498.66	188.164
1499.18	187.936
1499.7	187.815
1500.23	187.865
1500.75	188.25
1501.27	189.291
1501.79	190.488
1502.31	191.747
1502.83	192.317
1503.35	192.112
1503.87	191.77
1504.39	191.546
1504.91	191.365
1505.44	191.278
1505.96	190.957
1506.48	190.375
1507	189.521
1507.52	188.399
1508.04	186.924
1508.56	185.961
1509.08	187.354
1509.6	188.58
1510.12	189.561
1510.64	191.773
1511.16	192.447
1511.68	192.577
1512.2	191.88
1512.72	190.786
1513.24	189.865
1513.76	189.352
1514.27	189.279
1514.79	189.613
1515.31	190.191
1515.83	190.475
1516.35	187.748
1516.87	187.591
1517.39	188.846
1517.91	192.15
1518.43	194.19
1518.95	195.055
1519.46	191.824
1519.98	186.349
1520.5	183.444
1521.02	184.239
1521.54	189.76
1522.06	191.903
1522.58	189.507
1523.09	190.495
1523.61	192.622
1524.13	194.174
1524.65	195.16
1525.17	195.243
1525.68	194.23
1526.2	192.255
1526.72	189.767
1527.24	187.95
1527.75	186.738
1528.27	186.504
1528.79	186.744
1529.31	187.388
1529.82	188.242
1530.34	189.013
1530.86	190.013
1531.37	190.854
1531.89	191.603
1532.41	192.037
1532.92	191.841
1533.44	190.8
1533.96	189.728
1534.47	188.804
1534.99	188.654
1535.51	188.59
1536.02	189.608
1536.54	190.455
1537.06	192.24
1537.57	193.016
1538.09	193.062
1538.6	192.154
1539.12	190.97
1539.64	190.297
1540.15	189.87
1540.67	189.684
1541.18	189.778
1541.7	190.107
1542.21	188.992
1542.73	188.177
1543.25	188.754
1543.76	191.415
1544.28	195.624
1544.79	197.675
1545.31	192.018
1545.82	190.52
1546.34	189.977
1546.85	189.914
1547.37	190.232
1547.88	191.42
1548.39	193.402
1548.91	194.37
1549.42	194.335
1549.94	193.579
1550.45	193.227
1550.97	192.604
1551.48	193.218
1552	196.45
1552.51	193.696
1553.02	193.284
1553.54	194.057
1554.05	195.912
1554.56	194.892
1555.08	195.113
1555.59	196.193
1556.11	196.91
1556.62	197.26
1557.13	196.64
1557.65	197.385
1558.16	197.127
1558.67	196.737
1559.19	196.552
1559.7	196.886
1560.21	196.97
1560.72	196.905
1561.24	196.749
1561.75	196.791
1562.26	196.746
1562.78	196.64
1563.29	196.545
1563.8	196.671
1564.31	197.123
1564.82	197.638
1565.34	198.27
1565.85	198.856
1566.36	199.371
1566.87	200.331
1567.39	201.535
1567.9	202.127
1568.41	202.264
1568.92	202.161
1569.43	201.961
1569.94	201.917
1570.46	201.581
1570.93	200.744
1571.45	199.403
1571.97	197.526
1572.49	197.042
1573.01	197.875
1573.53	197.251
1574.05	196.635
1574.57	196.218
1575.09	196.129
1575.61	196.397
1576.13	196.822
1576.64	197.395
1577.16	198.116
1577.68	198.95
1578.2	199.768
1578.72	200.462
1579.24	201.207
1579.76	202.129
1580.28	209.001
1580.8	205.131
1581.31	201.025
1581.83	197.806
1582.35	197.853
1582.87	197.716
1583.39	197.876
1583.91	198.086
1584.42	198.257
1584.94	198.388
1585.46	198.39
1585.98	198.179
1586.5	197.778
1587.01	197.192
1587.53	196.268
1588.05	194.913
1588.57	194.311
1589.08	195.57
1589.6	196.859
1590.12	197.879
1590.64	198.768
1591.15	199.308
1591.67	199.556
1592.19	199.602
1592.7	199.492
1593.22	199.265
1593.74	198.942
1594.26	198.606
1594.77	197.937
1595.29	197.273
1595.81	196.61
1596.32	195.995
1596.84	195.505
1597.36	195.11
1597.87	194.902
1598.39	195.016
1598.9	195.335
1599.42	195.948
1599.94	196.933
1600.45	198
1600.97	199.073
1601.48	200.101
1602	201.021
1602.52	200.703
1603.03	200.382
1603.55	199.833
1604.06	199.192
1604.58	198.466
1605.09	197.697
1605.61	197.019
1606.12	196.509
1606.64	196.002
1607.15	195.564
1607.67	195.204
1608.18	194.922
1608.7	194.709
1609.21	194.568
1609.73	194.481
1610.24	194.204
1610.76	194.035
1611.27	193.964
1611.79	195.624
1612.3	197.428
1612.81	198.845
1613.33	199.185
1613.84	198.993
1614.36	198.28
1614.87	196.914
1615.38	195.279
1615.9	194.161
1616.41	194.38
1616.93	195.254
1617.44	196.404
1617.95	197.191
1618.47	196.706
1618.98	195.351
1619.49	193.408
1620.01	191.849
1620.52	192.11
1621.03	193.751
1621.55	196.585
1622.06	198.525
1622.57	198.786
1623.09	197.752
1623.6	195.04
1624.11	192.664
1624.62	191.029
1625.14	190.266
1625.65	190.308
1626.16	190.971
1626.67	192.379
1627.19	193.884
1627.7	195.369
1628.21	196.309
1628.72	196.626
1629.23	196.545
1629.75	195.803
1630.26	194.925
1630.77	194.009
1631.28	193.117
1631.79	192.657
1632.3	192.736
1632.82	193.519
1633.33	194.367
1633.84	195.201
1634.35	195.861
1634.86	195.267
1635.37	194.431
1635.89	192.804
1636.4	191.161
1636.91	189.665
1637.42	189.092
1637.93	188.978
1638.44	190.422
1638.95	192.248
1639.46	194.138
1639.97	195.646
1640.48	196.371
1640.99	196.761
1641.5	196.499
1642.01	195.826
1642.52	194.817
1643.03	193.743
1643.54	192.825
1644.05	192.212
1644.56	192.063
1645.07	192.278
1645.58	193.479
1646.09	195.269
1646.6	196.595
1647.11	197.93
1647.62	197.874
1648.13	194.661
1648.64	195.544
1649.15	196.619
1649.66	197.576
1650.17	198.256
1650.68	198.43
1651.19	197.731
1651.69	196.204
1652.2	194.653
1652.71	193.849
1653.22	193.476
1653.73	193.302
1654.24	193.293
1654.75	193.38
1655.26	193.316
1655.76	193.235
1656.27	193.086
1656.78	192.851
1657.29	193.359
1657.8	195.566
1658.31	197.784
1658.81	199.908
1659.32	201.703
1659.83	200.157
1660.34	196.497
1660.84	195.389
1661.35	195.869
1661.86	196.315
1662.37	196.412
1662.87	195.607
1663.38	194.951
1663.89	195.485
1664.4	197.448
1664.9	199.709
1665.41	200.103
1665.92	196.607
1666.42	198.636
1666.93	198.388
1667.44	197.824
1667.94	196.946
1668.45	195.706
1668.96	194.111
1669.46	192.65
1669.97	191.508
1670.48	191.062
1670.98	191.639
1671.49	193.217
1672	194.912
1672.5	196.502
1673.01	197.383
1673.51	197.486
1674.02	197.044
1674.53	196.326
1675.03	195.266
1675.54	194.197
1676.04	193.371
1676.55	193.014
1677.05	192.935
1677.56	193.506
1678.06	195.074
1678.57	197.194
1679.08	198.888
1679.58	199.635
1680.09	200.315
1680.59	200.83
1681.09	201.149
1681.6	201.195
1682.11	200.913
1682.61	200.329
1683.11	199.096
1683.62	197.726
1684.12	196.246
1684.63	194.908
1685.13	194.538
1685.64	194.414
1686.14	194.419
1686.65	194.53
1687.15	194.711
1687.65	194.731
1688.16	194.909
1688.66	195.738
1689.16	196.639
1689.67	197.555
1690.17	198.277
1690.68	197.805
1691.18	196.637
1691.68	195.348
1692.19	194.286
1692.69	194.299
1693.19	194.757
1693.7	195.436
1694.2	196.251
1694.7	197.141
1695.2	197.308
1695.71	197.192
1696.21	197.01
1696.71	196.963
1697.22	197.332
1697.72	197.909
1698.22	198.457
1698.72	198.961
1699.23	199.155
1699.73	197.307
1699.98	194.889