File: 145GPa.txt
#Acq. time (s)=	10
#Accumulations=	1
#Range (cm-¹)=	1300...1700
#Windows=	2
#Autofocus=	Off
#AutoExposure=	Off
#Spike filter=	Single accum. (Size=3)
#Delay time (s)=	0.1
#Binning=	1
#Readout mode=	Signal
#DeNoise=	Standard
#ICS correction=	On
#Dark correction=	Off
#Inst. Process=	Off
#Instrument=	LabRAM HR Evol
#Detector=	Synapse
#Objective=	x20SLWD
#Grating=	1800 gr/mm
#ND Filter=	100%
#Laser (nm)=	633
#Hole=	150.001
#Range=	Visible
#Collection=	Microscope
#StageXY=	Marzhauser
#StageZ=	Marzhauser
#X (µm)=	0
#Y (µm)=	0
#Z (µm)=	0
#Project=	20190124
#Sample=	1-2
#Site=
#Title=	D_48
#Remark=
#Date=	18.05.2019 23:26
#Acquired=	18.05.2019 23:26:21
1300.13	42.652
1300.68	43.1078
1301.23	43.2143
1301.78	43.0944
1302.32	42.8979
1302.87	42.5668
1303.42	41.9715
1303.97	41.3826
1304.52	41.2205
1305.07	41.8298
1305.61	43.431
1306.16	50.6441
1306.71	45.1108
1307.26	45.3877
1307.8	43.8172
1308.35	44.5955
1308.9	45.3416
1309.45	45.2401
1310	45.0084
1310.54	44.7407
1311.09	44.5071
1311.64	44.3383
1312.19	44.2736
1312.73	44.9759
1313.28	45.9648
1313.83	47.0671
1314.37	48.3061
1314.92	49.2952
1315.47	49.4975
1316.01	49.6462
1316.56	49.8151
1317.11	50.0726
1317.65	50.4931
1318.2	51.5326
1318.75	52.699
1319.29	54.3689
1319.84	56.1692
1320.39	57.4798
1320.93	58.3143
1321.48	59.0424
1322.02	59.8408
1322.57	60.9642
1323.11	62.8367
1323.66	65.9536
1324.21	70.3342
1324.75	75.2891
1325.3	81.6082
1325.84	87.8222
1326.39	94.772
1326.93	102.102
1327.48	113.609
1328.02	124.644
1328.57	141.927
1329.11	166.982
1329.66	209.451
1330.2	267.569
1330.75	353.477
1331.29	477.955
1331.84	676.654
1332.38	909.7
1332.93	1146.78
1333.47	1297.15
1334.01	1272.63
1334.56	1226.93
1335.1	1170.48
1335.65	1074.71
1336.19	983.696
1336.73	919.848
1337.28	852.49
1337.82	796.373
1338.36	746.096
1338.91	701.425
1339.45	662.3
1340	628.679
1340.54	599.635
1341.08	573.533
1341.63	549.549
1342.17	527.38
1342.71	506.876
1343.26	487.983
1343.8	470.464
1344.34	453.706
1344.88	439.271
1345.43	426.978
1345.97	416.249
1346.51	407.018
1347.05	398.216
1347.6	390.352
1348.14	381.438
1348.68	372.304
1349.22	363.435
1349.77	354.14
1350.31	345.653
1350.85	338.526
1351.39	332.172
1351.93	324.682
1352.48	318.628
1353.02	313.584
1353.56	309
1354.1	304.231
1354.64	297.772
1355.18	291.476
1355.72	285.796
1356.26	280.228
1356.81	274.303
1357.35	269.296
1357.89	266.295
1358.43	264.937
1358.97	263.542
1359.51	261.875
1360.05	259.897
1360.59	257.069
1361.13	252.978
1361.67	248.075
1362.21	242.786
1362.75	238.144
1363.29	234.626
1363.83	231.547
1364.37	228.664
1364.91	226.372
1365.45	224.127
1365.99	222.152
1366.53	220.416
1367.07	217.357
1367.61	214.277
1368.15	330.997
1368.69	320.58
1369.23	207.757
1369.77	207.685
1370.31	201.638
1370.85	200.062
1371.39	198.817
1371.93	197.471
1372.47	196.181
1373.01	194.85
1373.55	193.689
1374.08	192.556
1374.62	191.404
1375.16	190.136
1375.7	188.759
1376.24	187.481
1376.78	185.593
1377.31	183.556
1377.85	181.363
1378.39	179.147
1378.93	177.158
1379.47	175.932
1380.01	174.775
1380.54	173.838
1381.08	172.984
1381.62	172.18
1382.16	171.386
1382.69	170.579
1383.23	168.947
1383.77	167.253
1384.31	165.488
1384.84	163.751
1385.38	162.201
1385.92	161.198
1386.46	160.458
1386.99	159.862
1387.53	159.384
1388.07	158.908
1388.6	158.317
1389.14	157.119
1389.68	155.547
1390.21	153.38
1390.75	152.288
1391.29	151.407
1391.82	150.748
1392.36	149.166
1392.9	146.082
1393.43	142.985
1393.97	146.107
1394.5	145.999
1395.04	145.432
1395.58	144.91
1396.11	143.789
1396.65	140.658
1397.18	138.92
1397.72	137.672
1398.25	136.682
1398.79	137.822
1399.32	139.039
1399.86	140.74
1400.39	143.273
1400.93	142.165
1401.46	138.917
1402	134.394
1402.53	131.144
1403.07	129.951
1403.6	129.882
1404.14	129.917
1404.67	130.114
1405.21	130.473
1405.74	130.254
1406.28	129.826
1406.81	129.126
1407.34	128.206
1407.88	127.773
1408.41	127.369
1408.95	127.23
1409.48	127.055
1410.01	126.828
1410.55	126.357
1411.08	125.782
1411.62	124.883
1412.15	123.858
1412.68	122.823
1413.22	121.792
1413.75	120.765
1414.28	119.716
1414.82	118.857
1415.35	118.333
1415.88	117.966
1416.42	117.946
1416.95	118.148
1417.48	118.346
1418.01	118.463
1418.55	118.141
1419.08	117.481
1419.61	116.333
1420.14	115.02
1420.68	113.757
1421.21	112.571
1421.74	112.317
1422.27	112.232
1422.81	112.139
1423.34	111.795
1423.87	111.221
1424.4	110.408
1424.93	109.511
1425.46	108.523
1426	107.526
1426.53	106.564
1427.06	105.674
1427.59	104.898
1428.12	104.448
1428.65	104.24
1429.18	104.372
1429.72	104.794
1430.25	105.345
1430.78	105.69
1431.31	105.373
1431.84	104.746
1432.37	104.168
1432.9	103.513
1433.43	103.073
1433.96	102.869
1434.49	102.652
1435.02	102.521
1435.55	102.471
1436.08	101.991
1436.61	101.38
1437.14	100.691
1437.67	100.045
1438.2	99.4159
1438.73	98.7917
1439.26	98.1964
1439.79	97.743
1440.32	97.6006
1440.85	97.4912
1441.38	97.393
1441.91	97.3235
1442.44	97.2692
1442.97	97.2464
1443.5	97.2088
1444.03	97.0634
1444.56	96.8774
1445.09	96.6473
1445.61	96.2835
1446.14	95.6731
1446.67	95.0133
1447.2	94.5478
1447.73	94.0794
1448.26	93.6377
1448.79	93.2109
1449.32	93.1247
1449.84	92.7849
1450.37	92.4972
1450.9	91.9504
1451.43	91.184
1451.96	90.4472
1452.48	89.6702
1453.01	88.9237
1453.54	88.2095
1454.07	87.5511
1454.6	87.0678
1455.12	86.9931
1455.65	87.2943
1456.18	87.7964
1456.71	88.2733
1457.23	88.734
1457.76	88.9048
1458.29	88.8877
1458.81	88.7714
1459.34	88.6008
1459.87	88.3864
1460.4	87.9384
1460.92	87.3571
1461.45	86.6186
1461.98	85.8297
1462.5	85.0188
1463.03	84.1964
1463.55	83.4721
1464.08	83.0895
1464.61	82.7287
1465.13	83.0466
1465.66	83.3855
1466.19	83.8117
1466.71	84.2029
1467.24	84.4572
1467.76	84.2642
1468.29	83.4919
1468.82	82.7521
1469.34	81.999
1469.87	81.2515
1470.39	80.5471
1470.92	79.9364
1471.44	79.7476
1471.97	79.5858
1472.49	79.5489
1473.02	79.7922
1473.54	80.4359
1474.07	81.0779
1474.59	81.6324
1475.12	81.9111
1475.64	80.9656
1476.17	79.7264
1476.69	78.4062
1477.22	77.1046
1477.74	75.6843
1478.27	75.8486
1478.79	76.2427
1479.32	76.7293
1479.84	77.2047
1480.36	77.6032
1480.89	77.6354
1481.41	77.7024
1481.93	77.6851
1482.46	77.6084
1482.98	77.4846
1483.51	77.2895
1484.03	77.0249
1484.55	76.7131
1485.08	76.4557
1485.6	75.9596
1486.12	75.4251
1486.65	74.8531
1487.17	74.2314
1487.69	73.6427
1488.22	73.1869
1488.74	72.9066
1489.26	73.3798
1489.78	73.2866
1490.31	73.1701
1490.83	73.0234
1491.35	72.8263
1491.88	72.4256
1492.4	72.0834
1492.92	72.2107
1493.44	72.5825
1493.96	72.9157
1494.49	73.1143
1495.01	73.1237
1495.53	72.9245
1496.05	72.5941
1496.57	72.2281
1497.1	71.8343
1497.62	71.4559
1498.14	71.125
1498.66	70.8598
1499.18	70.6941
1499.7	70.7938
1500.23	70.9647
1500.75	71.0899
1501.27	71.1279
1501.79	70.9125
1502.31	69.4452
1502.83	68.2697
1503.35	67.3799
1503.87	67.8372
1504.39	67.5281
1504.91	67.7288
1505.44	68.0599
1505.96	68.183
1506.48	67.6136
1507	67.2205
1507.52	66.8212
1508.04	66.4597
1508.56	66.411
1509.08	66.3305
1509.6	66.2265
1510.12	66.1207
1510.64	66.0209
1511.16	65.9371
1511.68	65.8824
1512.2	65.8605
1512.72	65.8186
1513.24	66.1436
1513.76	66.5651
1514.27	67.0344
1514.79	67.4175
1515.31	67.5022
1515.83	67.4514
1516.35	66.6355
1516.87	66.0745
1517.39	65.6797
1517.91	65.4957
1518.43	65.3938
1518.95	65.3407
1519.46	64.8609
1519.98	64.346
1520.5	63.6541
1521.02	63.1046
1521.54	62.67
1522.06	62.5472
1522.58	63.0818
1523.09	63.823
1523.61	64.5959
1524.13	65.232
1524.65	65.4108
1525.17	65.0299
1525.68	64.6812
1526.2	64.2559
1526.72	63.8446
1527.24	63.313
1527.75	62.7515
1528.27	62.1838
1528.79	61.7107
1529.31	61.2369
1529.82	60.7996
1530.34	60.4234
1530.86	60.0953
1531.37	59.8324
1531.89	59.6168
1532.41	59.4436
1532.92	59.5601
1533.44	59.8419
1533.96	60.2243
1534.47	60.6017
1534.99	60.8979
1535.51	60.8433
1536.02	60.0156
1536.54	59.3731
1537.06	58.8547
1537.57	58.4844
1538.09	58.657
1538.6	58.9641
1539.12	59.3619
1539.64	59.9347
1540.15	60.4746
1540.67	60.9451
1541.18	60.8139
1541.7	59.8517
1542.21	58.796
1542.73	57.7356
1543.25	56.8046
1543.76	56.0355
1544.28	55.7434
1544.79	55.5778
1545.31	55.7267
1545.82	56.0473
1546.34	56.5297
1546.85	57.059
1547.37	57.5583
1547.88	58.1674
1548.39	58.1852
1548.91	58.0035
1549.42	57.8683
1549.94	57.6506
1550.45	57.4678
1550.97	57.357
1551.48	57.1716
1552	57.2175
1552.51	57.3533
1553.02	57.4351
1553.54	57.4561
1554.05	57.4228
1554.56	57.3833
1555.08	57.5159
1555.59	57.4661
1556.11	57.2236
1556.62	57.1819
1557.13	57.2513
1557.65	57.1774
1558.16	57.0803
1558.67	56.8485
1559.19	56.8518
1559.7	56.9176
1560.21	56.7997
1560.72	56.5655
1561.24	56.5256
1561.75	56.7005
1562.26	56.8003
1562.78	56.6889
1563.29	56.4912
1563.8	56.3602
1564.31	56.4019
1564.82	56.4102
1565.34	56.4251
1565.85	56.5408
1566.36	56.7186
1566.87	56.7884
1567.39	56.7227
1567.9	56.8972
1568.41	57.2902
1568.92	57.3526
1569.43	57.2019
1569.94	56.6387
1570.46	56.1561
1570.93	55.8419
1571.45	55.5614
1571.97	54.8731
1572.49	54.5712
1573.01	54.7997
1573.53	55.5585
1574.05	55.8093
1574.57	56.4313
1575.09	57.1206
1575.61	58.2459
1576.13	58.8417
1576.64	58.7427
1577.16	58.7142
1577.68	59.2556
1578.2	59.5402
1578.72	58.8933
1579.24	58.4068
1579.76	58.2163
1580.28	58.1376
1580.8	58.4484
1581.31	58.7286
1581.83	59.2461
1582.35	59.7884
1582.87	60.0256
1583.39	59.6084
1583.91	59.1239
1584.42	58.3463
1584.94	57.9449
1585.46	57.9645
1585.98	58.1716
1586.5	58.4659
1587.01	59.0305
1587.53	59.3825
1588.05	59.6256
1588.57	60.2055
1589.08	60.7623
1589.6	60.9611
1590.12	61.1362
1590.64	60.8468
1591.15	60.4082
1591.67	59.8705
1592.19	59.7036
1592.7	60.0474
1593.22	60.9224
1593.74	61.6101
1594.26	61.8296
1594.77	61.9641
1595.29	62.4314
1595.81	62.8136
1596.32	62.9551
1596.84	62.9269
1597.36	62.6876
1597.87	62.0162
1598.39	61.0199
1598.9	59.919
1599.42	58.8406
1599.94	58.2296
1600.45	58.0762
1600.97	58.1364
1601.48	58.211
1602	58.6544
1602.52	59.6645
1603.03	59.9154
1603.55	59.7057
1604.06	59.6812
1604.58	59.6438
1605.09	59.2792
1605.61	59.2805
1606.12	59.1475
1606.64	59.3237
1607.15	59.0747
1607.67	58.5156
1608.18	57.0196
1608.7	55.0692
1609.21	53.1285
1609.73	51.1244
1610.24	49.0936
1610.76	47.0883
1611.27	44.5775
1611.79	42.63
1612.3	41.2607
1612.81	40.2995
1613.33	39.7469
1613.84	39.2676
1614.36	38.8469
1614.87	38.7329
1615.38	38.481
1615.9	38.2556
1616.41	37.9452
1616.93	37.9837
1617.44	38.2476
1617.95	38.3995
1618.47	38.5497
1618.98	38.4135
1619.49	38.1926
1620.01	38.0337
1620.52	37.5364
1621.03	37.3396
1621.55	37.3405
1622.06	37.3539
1622.57	37.46
1623.09	37.8663
1623.6	37.9611
1624.11	38.122
1624.62	38.0178
1625.14	37.6343
1625.65	37.2255
1626.16	36.8409
1626.67	36.5373
1627.19	36.0508
1627.7	35.924
1628.21	35.7392
1628.72	35.7704
1629.23	35.5243
1629.75	35.0704
1630.26	34.8658
1630.77	34.9425
1631.28	34.8668
1631.79	34.8849
1632.3	35.6695
1632.82	36.3684
1633.33	36.3627
1633.84	35.9654
1634.35	35.8549
1634.86	35.7445
1635.37	35.492
1635.89	35.1717
1636.4	34.9784
1636.91	34.9818
1637.42	35.2341
1637.93	35.6807
1638.44	36.2043
1638.95	36.9517
1639.46	37.3699
1639.97	37.4969
1640.48	37.557
1640.99	37.7421
1641.5	37.7102
1642.01	37.5018
1642.52	37.2924
1643.03	37.3342
1643.54	37.151
1644.05	36.7696
1644.56	36.213
1645.07	35.7852
1645.58	36.191
1646.09	36.7605
1646.6	37.1212
1647.11	37.0518
1647.62	36.9581
1648.13	36.2396
1648.64	35.2792
1649.15	34.9227
1649.66	35.2461
1650.17	35.6594
1650.68	36.2167
1651.19	36.736
1651.69	37.0266
1652.2	37.0708
1652.71	36.728
1653.22	36.6386
1653.73	36.4895
1654.24	36.4135
1654.75	36.4514
1655.26	36.699
1655.76	36.7404
1656.27	36.8897
1656.78	37.0123
1657.29	37.1916
1657.8	37.2973
1658.31	37.2706
1658.81	36.9382
1659.32	36.9558
1659.83	36.8899
1660.34	36.8939
1660.84	37.0868
1661.35	37.5394
1661.86	37.5075
1662.37	37.4366
1662.87	37.3162
1663.38	37.2901
1663.89	37.1515
1664.4	36.8654
1664.9	36.4783
1665.41	36.812
1665.92	36.2246
1666.42	35.4192
1666.93	34.5803
1667.44	33.9373
1667.94	33.678
1668.45	33.9326
1668.96	34.5798
1669.46	34.8435
1669.97	35.2738
1670.48	35.6441
1670.98	36.2881
1671.49	37.2799
1672	37.604
1672.5	37.8041
1673.01	37.9579
1673.51	37.3432
1674.02	36.6268
1674.53	36.0893
1675.03	36.4701
1675.54	37.1497
1676.04	37.3934
1676.55	36.4908
1677.05	36.1043
1677.56	35.8346
1678.06	35.5794
1678.57	35.334
1679.08	35.0971
1679.58	35.0843
1680.09	35.2301
1680.59	35.4591
1681.09	35.9303
1681.6	36.2667
1682.11	36.5023
1682.61	36.5705
1683.11	36.8266
1683.62	37.1884
1684.12	37.0259
1684.63	36.5669
1685.13	36.4204
1685.64	36.3118
1686.14	36.155
1686.65	35.6229
1687.15	35.0337
1687.65	35.2647
1688.16	35.9992
1688.66	36.5392
1689.16	36.6986
1689.67	36.4896
1690.17	36.1105
1690.68	35.6204
1691.18	35.1163
1691.68	34.7621
1692.19	35.0417
1692.69	36.4033
1693.19	37.0099
1693.7	36.9078
1694.2	36.4516
1694.7	36.1879
1695.2	35.797
1695.71	36.0562
1696.21	36.164
1696.71	36.296
1697.22	36.4737
1697.72	36.7374
1698.22	36.9982
1698.72	37.1
1699.23	37.3111
1699.73	36.6893
1699.98	36.6771