File: 154GPa.txt
#Acq. time (s)=	10
#Accumulations=	1
#Range (cm-¹)=	1300...1700
#Windows=	2
#Autofocus=	Off
#AutoExposure=	Off
#Spike filter=	Single accum. (Size=3)
#Delay time (s)=	0.1
#Binning=	1
#Readout mode=	Signal
#DeNoise=	Standard
#ICS correction=	On
#Dark correction=	Off
#Inst. Process=	Off
#Instrument=	LabRAM HR Evol
#Detector=	Synapse
#Objective=	x20SLWD
#Grating=	1800 gr/mm
#ND Filter=	100%
#Laser (nm)=	633
#Hole=	150.001
#Range=	Visible
#Collection=	Microscope
#StageXY=	Marzhauser
#StageZ=	Marzhauser
#X (µm)=	0
#Y (µm)=	0
#Z (µm)=	0
#Project=	20190124
#Sample=	1-2
#Site=
#Title=	D_23
#Remark=
#Date=	18.05.2019 21:48
#Acquired=	18.05.2019 21:48:52
1300.13	43.7325
1300.68	40.937
1301.23	39.8049
1301.78	39.7947
1302.32	40.5017
1302.87	41.3374
1303.42	42.1878
1303.97	42.9672
1304.52	43.6522
1305.07	44.244
1305.61	44.5631
1306.16	44.5399
1306.71	44.385
1307.26	44.1837
1307.8	43.9516
1308.35	43.7146
1308.9	43.475
1309.45	43.2836
1310	43.2466
1310.54	43.4083
1311.09	43.9243
1311.64	44.5277
1312.19	45.2026
1312.73	45.9216
1313.28	46.6423
1313.83	47.3948
1314.37	47.8188
1314.92	48.226
1315.47	48.5046
1316.01	48.7473
1316.56	48.9858
1317.11	49.2092
1317.65	49.4565
1318.2	49.7562
1318.75	50.1328
1319.29	50.6291
1319.84	51.5582
1320.39	52.5093
1320.93	53.6322
1321.48	55.0299
1322.02	56.5545
1322.57	58.2752
1323.11	60.2521
1323.66	62.4973
1324.21	65.1035
1324.75	70.6019
1325.3	75.498
1325.84	79.2132
1326.39	74.3966
1326.93	84.6273
1327.48	92.3264
1328.02	104.455
1328.57	120.06
1329.11	140.282
1329.66	166.926
1330.2	206.341
1330.75	273.889
1331.29	373.999
1331.84	517.871
1332.38	698.72
1332.93	868.549
1333.47	980.524
1334.01	987.277
1334.56	971.678
1335.1	903.111
1335.65	836.232
1336.19	770.487
1336.73	726.977
1337.28	687.293
1337.82	646.193
1338.36	608.607
1338.91	573.825
1339.45	541.828
1340	513.436
1340.54	488.023
1341.08	466.036
1341.63	448.122
1342.17	433.8
1342.71	422.382
1343.26	412
1343.8	401.452
1344.34	391.211
1344.88	379.407
1345.43	366.593
1345.97	357.268
1346.51	348.978
1347.05	341.745
1347.6	336.968
1348.14	332.851
1348.68	327.483
1349.22	319.549
1349.77	312.717
1350.31	306.069
1350.85	300.102
1351.39	294.231
1351.93	289.055
1352.48	285.011
1353.02	280.877
1353.56	276.055
1354.1	271.306
1354.64	266.963
1355.18	262.488
1355.72	258.322
1356.26	254.431
1356.81	249.973
1357.35	246.74
1357.89	243.804
1358.43	242.031
1358.97	240.914
1359.51	240.179
1360.05	238.954
1360.59	236.105
1361.13	232.341
1361.67	228.225
1362.21	224.598
1362.75	223.392
1363.29	222.75
1363.83	219.362
1364.37	216.929
1364.91	218.676
1365.45	218.825
1365.99	215.547
1366.53	209.09
1367.07	206.699
1367.61	203.735
1368.15	200.853
1368.69	198.305
1369.23	196.508
1369.77	195.285
1370.31	194.275
1370.85	193.507
1371.39	192.78
1371.93	192.066
1372.47	190.941
1373.01	189.264
1373.55	186.519
1374.08	183.589
1374.62	181.108
1375.16	179.311
1375.7	178.209
1376.24	178.19
1376.78	178.673
1377.31	178.751
1377.85	178.44
1378.39	177.774
1378.93	176.671
1379.47	175.19
1380.01	174.238
1380.54	174.143
1381.08	171.995
1381.62	170.002
1382.16	168.445
1382.69	167.544
1383.23	167.296
1383.77	167.093
1384.31	166.839
1384.84	166.986
1385.38	166.855
1385.92	165.775
1386.46	164.261
1386.99	162.627
1387.53	161.127
1388.07	158.969
1388.6	156.692
1389.14	155.373
1389.68	154.69
1390.21	154.343
1390.75	154.441
1391.29	155.773
1391.82	153.403
1392.36	150.393
1392.9	148.108
1393.43	147.394
1393.97	147.326
1394.5	146.951
1395.04	147.655
1395.58	148.382
1396.11	147.753
1396.65	146.918
1397.18	145.994
1397.72	144.983
1398.25	144.279
1398.79	143.832
1399.32	143.366
1399.86	142.917
1400.39	142.444
1400.93	141.93
1401.46	141.366
1402	140.759
1402.53	140.114
1403.07	139.358
1403.6	138.647
1404.14	137.933
1404.67	137.213
1405.21	136.49
1405.74	135.789
1406.28	135.128
1406.81	134.503
1407.34	133.976
1407.88	133.491
1408.41	132.967
1408.95	132.427
1409.48	131.889
1410.01	131.339
1410.55	130.714
1411.08	129.964
1411.62	128.665
1412.15	127.558
1412.68	126.929
1413.22	127.875
1413.75	127.493
1414.28	126.142
1414.82	125.081
1415.35	124.233
1415.88	124.389
1416.42	126.079
1416.95	127.103
1417.48	127.368
1418.01	126.845
1418.55	125.5
1419.08	123.969
1419.61	122.41
1420.14	121.663
1420.68	121.139
1421.21	120.709
1421.74	120.293
1422.27	119.879
1422.81	119.468
1423.34	119.055
1423.87	118.526
1424.4	118.036
1424.93	117.588
1425.46	117.164
1426	116.766
1426.53	116.397
1427.06	116.056
1427.59	115.742
1428.12	115.458
1428.65	115.195
1429.18	114.946
1429.72	114.706
1430.25	114.472
1430.78	114.233
1431.31	113.986
1431.84	113.725
1432.37	113.444
1432.9	113.045
1433.43	112.733
1433.96	112.402
1434.49	112.043
1435.02	111.64
1435.55	111.195
1436.08	110.644
1436.61	110.033
1437.14	109.114
1437.67	107.734
1438.2	106.881
1438.73	106.184
1439.26	105.862
1439.79	105.674
1440.32	105.23
1440.85	104.766
1441.38	104.187
1441.91	103.8
1442.44	103.566
1442.97	103.534
1443.5	104.005
1444.03	104.75
1444.56	105.476
1445.09	106.029
1445.61	106.112
1446.14	105.099
1446.67	103.887
1447.2	102.64
1447.73	101.426
1448.26	100.691
1448.79	100.277
1449.32	99.6935
1449.84	99.1606
1450.37	98.6642
1450.9	98.3834
1451.43	98.2142
1451.96	98.6921
1452.48	99.6534
1453.01	100.435
1453.54	101.086
1454.07	100.594
1454.6	99.7895
1455.12	98.9363
1455.65	98.0736
1456.18	97.2878
1456.71	96.7247
1457.23	96.4675
1457.76	96.313
1458.29	96.1982
1458.81	96.1223
1459.34	96.0636
1459.87	95.9999
1460.4	95.9102
1460.92	95.7872
1461.45	95.4579
1461.98	95.1413
1462.5	94.8172
1463.03	94.4565
1463.55	94.2882
1464.08	94.1522
1464.61	94.015
1465.13	93.8262
1465.66	93.5279
1466.19	93.0466
1466.71	91.4996
1467.24	89.7913
1467.76	90.4857
1468.29	90.3801
1468.82	90.1093
1469.34	89.8498
1469.87	89.6057
1470.39	89.3642
1470.92	89.1266
1471.44	88.8961
1471.97	88.6717
1472.49	88.4494
1473.02	88.2244
1473.54	87.991
1474.07	87.7844
1474.59	87.5688
1475.12	87.1801
1475.64	86.7606
1476.17	86.3166
1476.69	85.8566
1477.22	85.391
1477.74	84.9355
1478.27	84.486
1478.79	84.0964
1479.32	83.816
1479.84	83.6948
1480.36	84.1369
1480.89	84.379
1481.41	84.655
1481.93	84.8459
1482.46	84.9072
1482.98	84.1665
1483.51	83.2241
1484.03	81.8731
1484.55	80.1996
1485.08	80.2236
1485.6	81.3876
1486.12	82.8254
1486.65	80.4525
1487.17	79.9236
1487.69	79.7955
1488.22	79.846
1488.74	79.9904
1489.26	80.2617
1489.78	80.9227
1490.31	81.502
1490.83	81.5418
1491.35	81.4317
1491.88	81.3045
1492.4	81.2272
1492.92	81.4775
1493.44	81.3549
1493.96	80.5095
1494.49	79.5653
1495.01	78.6091
1495.53	77.9356
1496.05	77.9813
1496.57	78.7914
1497.1	79.9295
1497.62	80.133
1498.14	79.5053
1498.66	78.1458
1499.18	76.4805
1499.7	74.8899
1500.23	73.7708
1500.75	73.4484
1501.27	73.9833
1501.79	75.5838
1502.31	76.9316
1502.83	77.7373
1503.35	78.1334
1503.87	78.0781
1504.39	77.6059
1504.91	77.0334
1505.44	76.3901
1505.96	75.8122
1506.48	75.4071
1507	75.5486
1507.52	76.0051
1508.04	76.4644
1508.56	76.5232
1509.08	75.4846
1509.6	74.3059
1510.12	72.7495
1510.64	71.0154
1511.16	69.4122
1511.68	68.1977
1512.2	67.7138
1512.72	68.1311
1513.24	68.8093
1513.76	69.8228
1514.27	70.3202
1514.79	70.4262
1515.31	69.9047
1515.83	69.0447
1516.35	68.8423
1516.87	68.71
1517.39	68.4477
1517.91	68.3528
1518.43	69.2219
1518.95	69.2139
1519.46	68.6732
1519.98	67.8249
1520.5	67.1312
1521.02	67.0476
1521.54	67.2898
1522.06	67.2506
1522.58	66.6646
1523.09	66.5534
1523.61	66.4314
1524.13	66.1785
1524.65	66.1359
1525.17	66.1191
1525.68	66.1209
1526.2	66.133
1526.72	66.1486
1527.24	66.1608
1527.75	66.1639
1528.27	66.153
1528.79	66.1244
1529.31	66.0742
1529.82	65.9997
1530.34	65.9
1530.86	65.7762
1531.37	65.631
1531.89	65.4676
1532.41	65.2902
1532.92	65.1048
1533.44	64.917
1533.96	64.7321
1534.47	64.5546
1534.99	64.3909
1535.51	64.2481
1536.02	64.1309
1536.54	64.0447
1537.06	63.9886
1537.57	63.959
1538.09	63.9504
1538.6	63.9453
1539.12	63.9402
1539.64	63.9751
1540.15	63.9502
1540.67	63.8924
1541.18	63.7931
1541.7	63.646
1542.21	63.4659
1542.73	63.2592
1543.25	63.0313
1543.76	62.7878
1544.28	62.4717
1544.79	62.2279
1545.31	61.9997
1545.82	61.8475
1546.34	61.7794
1546.85	61.7054
1547.37	61.644
1547.88	61.5985
1548.39	61.5697
1548.91	61.6076
1549.42	61.606
1549.94	61.6163
1550.45	61.6497
1550.97	61.6702
1551.48	61.6436
1552	61.4766
1552.51	61.3662
1553.02	61.2817
1553.54	61.209
1554.05	61.1995
1554.56	61.3053
1555.08	61.3602
1555.59	61.2513
1556.11	61.0651
1556.62	61.1164
1557.13	61.0707
1557.65	60.9252
1558.16	60.833
1558.67	60.8468
1559.19	61.0292
1559.7	61.0396
1560.21	60.5296
1560.72	59.8342
1561.24	59.6065
1561.75	59.7054
1562.26	59.0716
1562.78	58.6645
1563.29	58.3432
1563.8	58.2082
1564.31	58.4974
1564.82	58.214
1565.34	57.7651
1565.85	57.5635
1566.36	57.5363
1566.87	57.6924
1567.39	58.5035
1567.9	59.1635
1568.41	59.0882
1568.92	58.9257
1569.43	58.3411
1569.94	57.3575
1570.46	56.666
1570.93	57.7386
1571.45	58.3555
1571.97	58.8311
1572.49	59.1725
1573.01	59.0632
1573.53	58.5193
1574.05	57.9575
1574.57	57.3431
1575.09	57.3429
1575.61	57.6526
1576.13	57.9444
1576.64	58.2273
1577.16	58.1219
1577.68	57.3834
1578.2	57.0745
1578.72	56.8029
1579.24	56.9453
1579.76	57.3052
1580.28	58.0394
1580.8	58.852
1581.31	58.9991
1581.83	59.2407
1582.35	59.0395
1582.87	58.5458
1583.39	57.8065
1583.91	57.7225
1584.42	57.9053
1584.94	56.8687
1585.46	56.5267
1585.98	56.2289
1586.5	56.1393
1587.01	56.3077
1587.53	56.3638
1588.05	56.5221
1588.57	56.8864
1589.08	57.4643
1589.6	57.911
1590.12	58.1865
1590.64	57.9731
1591.15	57.8586
1591.67	57.8385
1592.19	58.9737
1592.7	60.1097
1593.22	62.2566
1593.74	62.7554
1594.26	62.1746
1594.77	57.6976
1595.29	57.171
1595.81	59.951
1596.32	60.7684
1596.84	58.5644
1597.36	57.3179
1597.87	57.4754
1598.39	57.0701
1598.9	56.7929
1599.42	56.9101
1599.94	57.281
1600.45	57.6426
1600.97	57.7213
1601.48	57.5675
1602	57.6335
1602.52	57.7792
1603.03	58.2071
1603.55	58.4706
1604.06	59.0081
1604.58	59.8474
1605.09	60.3253
1605.61	60.4448
1606.12	60.2611
1606.64	59.3303
1607.15	58.6123
1607.67	58.5504
1608.18	58.0494
1608.7	57.3066
1609.21	57.5825
1609.73	58.4076
1610.24	58.7332
1610.76	57.2414
1611.27	57.6968
1611.79	58.3934
1612.3	59.039
1612.81	59.3907
1613.33	59.6007
1613.84	59.3937
1614.36	59.377
1614.87	59.2611
1615.38	58.675
1615.9	59.182
1616.41	59.1408
1616.93	58.8994
1617.44	58.2572
1617.95	56.9282
1618.47	55.5989
1618.98	55.2349
1619.49	55.6264
1620.01	57.1718
1620.52	57.5746
1621.03	57.3338
1621.55	55.0545
1622.06	53.2272
1622.57	51.0375
1623.09	48.7858
1623.6	46.6015
1624.11	44.8291
1624.62	43.1781
1625.14	41.8466
1625.65	40.7393
1626.16	39.8534
1626.67	39.0433
1627.19	38.2497
1627.7	37.8449
1628.21	37.5173
1628.72	37.5001
1629.23	37.8507
1629.75	38.4406
1630.26	38.8258
1630.77	39.3162
1631.28	39.7818
1631.79	39.8791
1632.3	39.4799
1632.82	38.9931
1633.33	38.4929
1633.84	37.8179
1634.35	37.5057
1634.86	37.4758
1635.37	37.6885
1635.89	38.0614
1636.4	38.3132
1636.91	38.7176
1637.42	39.1578
1637.93	39.7543
1638.44	39.9189
1638.95	39.6461
1639.46	39.1442
1639.97	38.4612
1640.48	37.949
1640.99	37.6153
1641.5	37.5714
1642.01	37.5914
1642.52	37.4885
1643.03	37.5749
1643.54	37.3376
1644.05	37.1173
1644.56	36.9177
1645.07	36.9681
1645.58	37.3253
1646.09	37.6434
1646.6	38.0705
1647.11	38.483
1647.62	38.7607
1648.13	39.0144
1648.64	39.0309
1649.15	38.8286
1649.66	38.7444
1650.17	38.127
1650.68	37.9787
1651.19	38.1699
1651.69	38.6307
1652.2	39.1436
1652.71	39.2043
1653.22	39.0825
1653.73	38.8142
1654.24	38.4172
1654.75	38.0957
1655.26	37.7135
1655.76	37.669
1656.27	37.4111
1656.78	37.3307
1657.29	37.4692
1657.8	37.78
1658.31	37.8748
1658.81	38.089
1659.32	38.3376
1659.83	38.6323
1660.34	38.5395
1660.84	38.2735
1661.35	37.6851
1661.86	37.5551
1662.37	37.5391
1662.87	37.5166
1663.38	37.5468
1663.89	37.9647
1664.4	38.4685
1664.9	38.9227
1665.41	39.0799
1665.92	39.0258
1666.42	38.8245
1666.93	38.7011
1667.44	38.5951
1667.94	38.2176
1668.45	37.7543
1668.96	37.592
1669.46	37.6477
1669.97	37.6712
1670.48	37.4854
1670.98	37.2284
1671.49	37.3158
1672	37.6415
1672.5	37.6808
1673.01	37.6771
1673.51	37.8438
1674.02	38.0905
1674.53	38.1728
1675.03	37.9092
1675.54	38.0843
1676.04	38.2728
1676.55	38.2835
1677.05	38.4792
1677.56	38.4465
1678.06	38.4673
1678.57	38.2862
1679.08	37.9529
1679.58	37.4917
1680.09	37.4233
1680.59	37.5349
1681.09	37.5727
1681.6	38.0058
1682.11	38.5807
1682.61	38.6171
1683.11	38.2074
1683.62	37.5489
1684.12	36.8894
1684.63	36.4907
1685.13	36.6326
1685.64	36.9265
1686.14	37.6675
1686.65	38.5887
1687.15	38.9798
1687.65	38.9881
1688.16	38.8122
1688.66	38.3444
1689.16	38.0866
1689.67	38.0777
1690.17	38.3003
1690.68	38.4054
1691.18	38.6366
1691.68	38.4906
1692.19	38.0554
1692.69	37.6443
1693.19	37.1458
1693.7	36.4341
1694.2	35.6818
1694.7	35.3137
1695.2	35.4794
1695.71	35.8846
1696.21	36.452
1696.71	36.9222
1697.22	37.3855
1697.72	37.7906
1698.22	37.7494
1698.72	37.4575
1699.23	37.2018
1699.73	37.856
1699.98	38.5374