File: 160.txt
#Acq. time (s)=	20
#Accumulations=	1
#Range (cm-¹)=	50...4500
#Windows=	24
#Autofocus=	Off
#AutoExposure=	Off
#Spike filter=	Single accum. (Size=3)
#Delay time (s)=	0.1
#Binning=	1
#Readout mode=	Signal
#DeNoise=	Standard
#ICS correction=	On
#Dark correction=	Off
#Inst. Process=	Off
#Instrument=	LabRAM HR Evol
#Detector=	Synapse
#Objective=	x20SLWD
#Grating=	1800 gr/mm
#ND Filter=	100%
#Laser (nm)=	633
#Hole=	150.001
#Range=	Visible
#Collection=	Microscope
#StageXY=	Marzhauser
#StageZ=	Marzhauser
#X (µm)=	0
#Y (µm)=	0
#Z (µm)=	0
#Project=	20190124
#Sample=	1-2
#Site=
#Title=	D_9
#Remark=
#Date=	18.05.2019 18:06
#Acquired=	18.05.2019 18:06:16
#Edit:Spike=	18.05.2019 19:19:26
#Edit:Spike=	18.05.2019 19:19:27
#Edit:Spike=	18.05.2019 19:19:27
#Edit:Spike=	18.05.2019 19:19:28
#Edit:Spike=	18.05.2019 19:19:28
#Edit:Spike=	18.05.2019 19:19:29
#Edit:Spike=	18.05.2019 19:19:29
#Edit:Spike=	18.05.2019 19:19:29
#Edit:Spike=	18.05.2019 19:19:29
#Edit:Spike=	18.05.2019 19:19:29
#Edit:Spike=	18.05.2019 19:19:30
#Edit:Spike=	18.05.2019 19:19:30
#Edit:Spike=	18.05.2019 19:19:30
#Edit:Spike=	18.05.2019 19:19:30
#Edit:Spike=	18.05.2019 19:19:31
#Edit:Spike=	18.05.2019 19:19:31
#Edit:Spike=	18.05.2019 19:19:31
#Edit:Spike=	18.05.2019 19:19:31
#Edit:Spike=	18.05.2019 19:19:32
#Edit:Spike=	18.05.2019 19:19:32
#Edit:Spike=	18.05.2019 19:19:32
#Edit:Spike=	18.05.2019 19:19:32
#Edit:Spike=	18.05.2019 19:19:33
#Edit:Spike=	18.05.2019 19:19:33
#Edit:Spike=	18.05.2019 19:19:33
#Edit:Spike=	18.05.2019 19:19:33
#Edit:Spike=	18.05.2019 19:19:34
#Edit:Spike=	18.05.2019 19:19:34
#Edit:Spike=	18.05.2019 19:19:34
#Edit:Spike=	18.05.2019 19:19:35
#Edit:Spike=	18.05.2019 19:19:35
#Edit:Spike=	18.05.2019 19:19:35
#Edit:Spike=	18.05.2019 19:19:35
#Edit:Spike=	18.05.2019 19:19:35
#Edit:Spike=	18.05.2019 19:19:36
#Edit:Spike=	18.05.2019 19:19:36
#Edit:Spike=	18.05.2019 19:19:36
#Edit:Spike=	18.05.2019 19:19:36
#Edit:Spike=	18.05.2019 19:19:36
#Edit:Spike=	18.05.2019 19:19:37
#Edit:Spike=	18.05.2019 19:19:37
#Edit:Spike=	18.05.2019 19:19:38
#Edit:Spike=	18.05.2019 19:19:38
#Edit:Spike=	18.05.2019 19:19:38
#Edit:Spike=	18.05.2019 19:19:39
#Edit:Spike=	18.05.2019 19:19:39
#Edit:Spike=	18.05.2019 19:19:40
#Edit:Spike=	18.05.2019 19:19:40
52.2641	104.184
57.3937	51.9914
62.5185	30.0726
67.6384	26.1331
72.752	26.0975
77.8607	27.5798
82.9631	38.4693
88.0622	45.2185
93.1535	51.7216
98.2415	54.0901
103.323	53.8994
108.399	56.0592
113.471	56.0511
118.536	56.3787
123.596	55.3293
128.651	53.7793
133.701	52.0404
138.746	55.5801
143.785	54.3066
148.818	56.2008
153.848	58.0508
158.869	56.5984
163.888	55.4565
168.901	55.7629
173.908	56.6479
178.91	57.1273
183.907	54.4304
188.897	57.513
193.883	56.0632
198.865	55.8364
203.84	55.8561
208.81	55.9299
213.775	54.3531
218.735	55.6345
223.69	55.9107
228.639	57.4533
233.582	56.8968
238.521	55.1867
243.454	56.1682
248.383	56.0307
253.306	59.2327
258.223	58.2444
263.135	57.9915
268.043	56.6595
272.945	59.7297
277.842	59.5689
282.733	58.922
287.62	60.7245
292.5	60.7935
297.376	60.1194
302.246	60.1268
307.112	61.3489
311.973	59.8453
316.828	60.7386
321.677	59.3575
326.521	60.7989
331.362	63.7717
336.196	62.4445
341.024	60.3186
345.849	63.5756
350.667	62.5506
355.48	62.2274
360.289	63.1769
365.092	64.6919
369.891	63.1101
374.683	63.9559
379.471	61.9886
384.254	61.9485
389.032	64.4836
393.797	63.7169
398.634	61.9871
403.465	64.8229
408.293	65.5631
413.114	62.8014
417.932	61.761
422.744	65.0199
427.55	64.0715
432.352	62.5206
437.149	63.0485
441.94	62.3532
446.727	62.1517
451.51	62.7676
456.286	64.0121
461.058	62.9997
465.825	63.4042
470.587	63.0238
475.343	64.0545
480.095	64.1916
484.842	65.2647
489.583	64.3462
494.319	65.2338
499.052	65.4358
503.779	63.6188
508.5	65.5071
513.217	65.7975
517.929	64.9237
522.635	66.9236
527.338	64.0604
532.035	64.6368
536.727	66.484
541.414	66.6054
546.097	65.5913
550.773	67.0697
555.446	64.4823
560.113	66.9714
564.775	66.9428
569.433	67.4379
574.086	66.2169
578.733	67.2036
583.375	68.3158
588.014	68.0451
592.646	67.4551
597.274	65.9999
601.896	68.051
606.515	69.5403
611.128	68.483
615.737	63.5146
620.34	67.0218
624.938	70.1259
629.531	65.4865
634.12	65.7791
638.704	67.0301
643.284	68.2521
647.857	67.0143
652.426	67.3899
656.99	67.263
661.55	67.8086
666.105	69.1022
670.654	69.7072
675.198	67.2433
679.739	66.8228
684.185	68.3901
688.785	67.6267
693.377	67.8721
697.967	67.5488
702.551	68.042
707.131	69.3155
711.705	66.8165
716.275	70.3133
720.84	68.9461
725.401	68.2065
729.956	69.056
734.508	68.5627
739.053	69.1135
743.595	67.8509
748.132	68.0779
752.663	70.3419
757.191	67.1768
761.714	70.1776
766.232	68.036
770.745	70.0726
775.253	70.1385
779.757	68.2551
784.256	67.9971
788.751	69.4994
793.24	68.4454
797.725	67.6628
802.205	68.9156
806.681	67.1083
811.151	68.1737
815.618	67.6698
820.079	66.7975
824.536	67.1866
828.988	68.2916
833.436	67.0636
837.878	66.5054
842.316	67.5017
846.75	68.0306
851.179	67.6417
855.603	67.1345
860.022	68.6734
864.438	68.6452
868.848	67.1075
873.252	67.7914
877.653	66.6849
882.049	66.4913
886.44	68.2626
890.828	67.8684
895.211	67.5833
899.588	68.0168
903.961	67.97
908.329	65.2004
912.693	66.8434
917.053	67.879
921.406	67.7605
925.757	68.7609
930.101	65.5201
934.442	67.1823
938.778	68.2466
943.11	67.8616
947.437	67.2803
951.759	68.5284
955.954	67.9077
960.333	69.9048
964.708	69.7685
969.078	68.021
973.444	68.4874
977.807	69.9875
982.163	67.6375
986.516	68.5599
990.864	67.3375
995.207	68.5562
999.547	69.8495
1003.88	68.3014
1008.21	66.885
1012.54	67.2335
1016.86	68.238
1021.17	65.8674
1025.49	68.7493
1029.79	67.8909
1034.1	69.6446
1038.4	66.4762
1042.69	68.7489
1046.98	68.4466
1051.27	68.532
1055.55	69.0852
1059.82	69.2834
1064.09	68.6788
1068.36	70.7238
1072.63	67.5031
1076.88	67.015
1081.14	68.2664
1085.39	67.3035
1089.63	68.3664
1093.87	69.3877
1098.11	69.0202
1102.34	68.4363
1106.57	68.463
1110.79	67.3614
1115.01	68.6646
1119.23	66.7788
1123.44	67.5182
1127.64	67.4541
1131.84	67.4551
1136.04	71.3836
1140.23	66.9443
1144.42	68.5649
1148.6	68.6564
1152.78	66.9254
1156.96	68.4478
1161.13	69.6209
1165.29	71.1176
1169.45	69.6664
1173.61	69.2311
1177.76	69.5128
1181.91	68.1316
1186.06	68.2719
1190.2	68.6957
1194.33	70.1827
1198.46	70.0489
1202.59	69.5065
1206.71	68.4358
1210.83	69.5347
1214.87	70.9724
1219.04	70.9973
1223.21	71.4375
1227.38	69.7955
1231.54	69.6669
1235.7	70.4465
1239.85	70.3714
1244	71.0663
1248.15	71.9522
1252.29	71.3322
1256.42	73.3989
1260.56	72.9659
1264.68	74.7124
1268.81	75.4109
1272.92	73.5389
1277.04	75.5544
1281.15	75.0337
1285.26	73.2943
1289.36	74.7963
1293.46	78.1178
1297.55	78.1658
1301.64	79.7322
1305.73	81.1342
1309.81	86.8294
1313.88	89.7544
1317.96	98.5577
1322.03	115.823
1326.09	155.188
1330.15	394.751
1334.21	2250.43
1338.26	2195.98
1342.31	1900.89
1346.35	1699.07
1350.39	1541.3
1354.42	1393.74
1358.45	1284.69
1362.48	1173.06
1366.5	1091.23
1370.52	1007.36
1374.53	933.853
1378.54	861.304
1382.55	793.147
1386.55	731.027
1390.55	667.498
1394.54	620.468
1398.53	575.557
1402.51	536.591
1406.49	507.144
1410.47	476.194
1414.44	453.5
1418.41	433.908
1422.37	421.395
1426.33	400.387
1430.29	387.389
1434.24	380.579
1438.19	362.619
1442.13	355.838
1446.07	349.791
1450	339.731
1453.93	337.187
1457.86	330.946
1461.78	329.689
1465.54	327.194
1469.52	317.385
1473.49	306.63
1477.46	303.242
1481.43	297.823
1485.39	294.967
1489.35	293.294
1493.3	279.046
1497.25	277.187
1501.2	271.229
1505.14	265.222
1509.08	265.766
1513.01	257.157
1516.94	254.049
1520.87	246.908
1524.79	244.26
1528.71	237.21
1532.63	230.685
1536.54	230.054
1540.44	225.189
1544.34	220.072
1548.24	220.422
1552.14	211.775
1556.03	208.585
1559.91	212.066
1563.79	200.043
1567.67	200.441
1571.54	194.225
1575.42	193.801
1579.28	194.273
1583.14	190.342
1587	186.089
1590.85	184.767
1594.7	183.306
1598.55	179.642
1602.39	176.933
1606.23	174.475
1610.06	174.638
1613.89	167.766
1617.72	160.815
1621.54	157.395
1625.36	148.41
1629.17	125.263
1632.99	95.251
1636.79	79.4437
1640.59	71.8756
1644.39	67.188
1648.19	65.7877
1651.97	66.4354
1655.76	65.9959
1659.54	64.7118
1663.32	65.1501
1667.1	66.3417
1670.87	66.0509
1674.63	65.4202
1678.4	65.0929
1682.16	65.7596
1685.91	65.5167
1689.66	65.5457
1693.41	66.3732
1697.15	65.7396
1700.89	65.8109
1704.65	66.5246
1708.45	66.3027
1712.24	65.7731
1716.02	64.5106
1719.81	64.5404
1723.59	65.1199
1727.36	63.3165
1731.13	65.3052
1734.9	65.6831
1738.67	65.5381
1742.43	64.1485
1746.18	63.708
1749.93	62.9131
1753.68	63.8099
1757.43	63.645
1761.17	62.9985
1764.91	64.2057
1768.64	65.1608
1772.37	64.0357
1776.09	63.7232
1779.82	64.5211
1783.53	65.0589
1787.25	64.191
1790.96	63.5618
1794.66	65.2037
1798.37	62.3441
1802.06	65.5138
1805.76	61.5177
1809.45	64.54
1813.14	62.7385
1816.82	64.5931
1820.5	62.749
1824.18	64.4016
1827.85	63.2173
1831.52	66.1769
1835.18	63.6007
1838.84	63.5262
1842.5	63.869
1846.15	63.515
1849.8	63.5851
1853.45	62.5562
1857.09	63.4712
1860.73	62.1578
1864.36	64.1285
1867.99	62.4205
1871.62	63.5058
1875.24	62.5226
1878.86	62.4429
1882.48	61.5729
1886.09	64.048
1889.7	62.1461
1893.3	62.0171
1896.9	62.183
1900.5	63.3173
1904.09	61.7809
1907.68	64.7486
1911.26	62.0328
1914.84	63.3528
1918.42	62.607
1922	63.1475
1925.57	62.6441
1929.13	64.4113
1932.57	62.8306
1936.19	66.6045
1939.81	63.7465
1943.42	65.2421
1947.03	63.2161
1950.64	63.8654
1954.24	63.8671
1957.84	61.5277
1961.44	63.321
1965.03	65.6159
1968.62	64.2121
1972.21	64.459
1975.79	61.7119
1979.36	64.6095
1982.94	62.9256
1986.51	66.3352
1990.08	63.96
1993.64	65.665
1997.2	63.0946
2000.75	62.7022
2004.31	62.4648
2007.85	63.3108
2011.4	65.4027
2014.94	64.0091
2018.48	63.1708
2022.01	64.6392
2025.54	62.4473
2029.07	64.3136
2032.59	63.255
2036.11	64.1092
2039.63	64.31
2043.14	62.3279
2046.65	64.4044
2050.15	63.1509
2053.65	63.6112
2057.15	62.8397
2060.64	62.8919
2064.13	64.6625
2067.62	61.8367
2071.1	63.4397
2074.58	63.542
2078.06	62.591
2081.53	61.2632
2085	62.1811
2088.47	63.4187
2091.93	61.9967
2095.39	62.6262
2098.84	61.4982
2102.29	64.3374
2105.74	62.5885
2109.18	62.4225
2112.62	64.1912
2116.06	61.6515
2119.49	62.7362
2122.92	61.4692
2126.35	61.177
2129.77	64.2966
2133.19	60.5378
2136.6	63.8639
2140.01	64.8879
2143.42	63.3276
2146.82	64.0089
2150.26	65.848
2153.71	64.923
2157.17	66.1598
2160.62	64.3078
2164.07	62.7333
2167.51	64.4088
2170.95	66.0409
2174.39	66.0707
2177.82	63.6501
2181.25	65.1853
2184.68	65.2512
2188.1	65.8176
2191.52	65.7322
2194.94	65.9939
2198.35	67.6115
2201.76	67.009
2205.17	67.0343
2208.57	68.1606
2211.97	66.2665
2215.36	67.2031
2218.75	65.6606
2222.14	69.802
2225.53	67.8197
2228.91	68.775
2232.29	70.3982
2235.66	65.7375
2239.03	68.8275
2242.4	68.8756
2245.76	68.1743
2249.12	68.2404
2252.48	72.6455
2255.83	68.4627
2259.18	69.8704
2262.53	69.6401
2265.87	72.8438
2269.21	70.9932
2272.55	70.2926
2275.88	73.584
2279.21	71.9873
2282.54	72.8736
2285.86	73.4408
2289.18	74.9215
2292.5	72.9589
2295.81	75.6479
2299.12	76.2013
2302.42	75.8821
2305.73	73.0384
2309.02	75.2307
2312.32	76.3405
2315.61	76.6109
2318.9	75.9163
2322.18	77.8034
2325.46	77.8706
2328.74	78.1141
2332.02	80.6382
2335.29	80.2747
2338.56	80.5464
2341.82	81.6048
2345.08	83.2267
2348.34	82.7362
2351.59	83.192
2354.84	86.4065
2357.98	85.0538
2361.28	83.376
2364.58	85.857
2367.88	82.8827
2371.17	86.8711
2374.46	87.389
2377.75	89.4945
2381.03	87.4742
2384.31	87.2193
2387.59	89.2629
2390.86	87.5248
2394.13	90.9785
2397.4	92.419
2400.66	93.9718
2403.92	90.1593
2407.18	93.4401
2410.43	91.9184
2413.68	92.933
2416.93	92.8077
2420.18	96.522
2423.42	91.9785
2426.65	95.8245
2429.89	95.073
2433.12	97.6859
2436.34	95.418
2439.57	95.7574
2442.79	97.557
2446	99.6238
2449.22	99.3563
2452.43	100.767
2455.64	99.036
2458.84	101.622
2462.04	104.271
2465.24	104.349
2468.43	106.321
2471.62	104.574
2474.81	109.781
2477.99	109.17
2481.17	108.099
2484.35	106.473
2487.53	107.822
2490.7	108.572
2493.86	107.489
2497.03	109.37
2500.19	112.321
2503.35	110.593
2506.5	107.649
2509.65	108.675
2512.8	110.933
2515.94	106.969
2519.09	106.53
2522.22	104.785
2525.36	108.765
2528.49	105.119
2531.62	107.117
2534.74	107.555
2537.87	107.081
2540.98	105.493
2544.1	107.143
2547.21	103.3
2550.32	104.668
2553.34	104.034
2556.5	101.762
2559.66	103.237
2562.82	104.779
2565.97	101.513
2569.12	99.2896
2572.26	104.846
2575.41	99.0858
2578.55	96.8992
2581.68	101.16
2584.82	96.7059
2587.94	99.2393
2591.07	95.2868
2594.19	97.7271
2597.31	97.0214
2600.43	94.6655
2603.54	97.004
2606.66	91.0404
2609.76	94.6687
2612.87	102.075
2615.97	91.4681
2619.07	90.9322
2622.16	89.6387
2625.25	96.0423
2628.34	94.7286
2631.43	96.5485
2634.51	92.038
2637.59	90.9897
2640.66	91.8534
2643.73	88.2187
2646.8	94.7882
2649.87	89.1078
2652.93	89.6494
2655.99	91.3603
2659.05	87.5279
2662.1	87.5554
2665.15	90.2888
2668.2	88.0731
2671.24	90.0158
2674.28	86.992
2677.32	88.4392
2680.36	86.9507
2683.39	89.2786
2686.41	85.3022
2689.44	86.6254
2692.46	86.7005
2695.48	81.2968
2698.5	82.3316
2701.51	80.1385
2704.52	82.6935
2707.52	79.6875
2710.53	77.195
2713.53	80.7562
2716.52	76.6927
2719.52	80.1338
2722.51	79.1541
2725.49	79.3024
2728.48	77.1067
2731.46	75.3345
2734.44	77.162
2737.41	76.8818
2740.38	75.5529
2743.3	77.3124
2746.33	73.4473
2749.35	76.0914
2752.37	73.2743
2755.38	72.7978
2758.39	72.0058
2761.4	71.4014
2764.41	75.0747
2767.41	72.64
2770.41	72.6496
2773.4	72.917
2776.4	73.3789
2779.39	69.7681
2782.37	73.3742
2785.36	74.6907
2788.34	72.1319
2791.32	78.9709
2794.29	70.2232
2797.26	72.4716
2800.23	71.0282
2803.2	71.0819
2806.16	77.1871
2809.12	72.5238
2812.08	71.0506
2815.03	69.6922
2817.98	70.992
2820.93	69.5726
2823.87	71.2954
2826.81	69.8509
2829.75	70.7321
2832.69	70.8416
2835.62	71.548
2838.55	70.5293
2841.47	70.2978
2844.4	70.487
2847.32	69.9598
2850.23	68.1162
2853.15	72.4851
2856.06	69.8031
2858.97	70.9794
2861.87	70.8878
2864.77	69.7421
2867.67	69.3099
2870.57	72.0237
2873.46	69.4671
2876.35	72.7454
2879.24	71.659
2882.12	70.6831
2885	73.8275
2887.88	70.2852
2890.75	70.4689
2893.63	72.5878
2896.5	71.771
2899.36	71.586
2902.22	71.8847
2905.08	69.5661
2907.94	71.424
2910.79	75.4061
2913.64	73.2199
2916.49	73.5519
2919.34	73.138
2922.19	73.927
2925.09	72.9496
2927.98	72.3782
2930.88	74.5414
2933.76	72.0429
2936.65	74.1808
2939.53	74.7262
2942.41	74.8167
2945.29	75.1599
2948.16	73.6258
2951.03	73.1937
2953.9	71.6487
2956.76	75.0102
2959.62	71.3017
2962.48	70.4566
2965.33	73.5875
2968.19	73.8632
2971.04	76.9865
2973.88	73.7019
2976.73	73.3859
2979.57	73.4006
2982.41	73.4849
2985.24	71.0928
2988.07	74.476
2990.9	71.3975
2993.73	73.6994
2996.55	75.7052
2999.37	72.4817
3002.19	73.5232
3005.01	72.4415
3007.82	74.1048
3010.63	72.1897
3013.43	72.1924
3016.23	72.6215
3019.03	73.1333
3021.83	73.7196
3024.63	73.8336
3027.42	71.7341
3030.2	72.8927
3032.99	75.4584
3035.77	72.5548
3038.55	72.4142
3041.33	71.431
3044.1	73.8875
3046.87	71.037
3049.64	72.2775
3052.41	70.2008
3055.17	72.6964
3057.93	73.8637
3060.69	70.5786
3063.44	73.4856
3066.19	74.8702
3068.94	70.5099
3071.68	97.9176
3074.42	75.5006
3077.16	70.6074
3079.9	71.7206
3082.63	72.6979
3085.36	71.793
3088.09	71.4073
3090.82	75.5661
3093.54	69.0721
3096.13	71.4794
3098.9	73.6657
3101.67	72.4798
3104.44	72.1905
3107.2	74.4263
3109.97	72.4681
3112.72	71.802
3115.48	72.4889
3118.23	75.0325
3120.98	71.7096
3123.73	71.8196
3126.48	72.2422
3129.22	72.5233
3131.96	72.2194
3134.69	71.2087
3137.43	71.889
3140.16	68.7935
3142.88	73.4057
3145.61	71.6985
3148.33	71.551
3151.05	71.19
3153.77	70.6516
3156.48	72.0071
3159.19	71.6004
3161.9	73.7386
3164.6	74.2269
3167.31	73.1042
3170.01	68.7418
3172.7	74.9963
3175.4	72.4119
3178.09	70.8635
3180.78	71.8429
3183.46	71.1499
3186.15	72.6386
3188.83	74.1563
3191.5	70.5212
3194.18	71.54
3196.85	69.7318
3199.52	69.6715
3202.19	71.3314
3204.85	72.544
3207.51	72.3756
3210.17	71.1183
3212.82	71.6457
3215.47	71.2195
3218.12	72.1148
3220.77	69.0123
3223.41	70.4098
3226.05	72.3869
3228.69	71.9819
3231.33	72.0504
3233.96	72.0514
3236.59	71.3564
3239.22	71.5898
3241.84	68.0913
3244.46	71.1367
3247.08	70.6639
3249.7	72.683
3252.31	72.8707
3254.92	73.0308
3257.53	71.8724
3260.13	72.2572
3262.73	75.9741
3265.39	73.3451
3268.04	76.378
3270.69	74.2805
3273.34	74.5775
3275.98	73.8258
3278.62	74.0069
3281.26	73.5507
3283.9	74.4016
3286.53	74.8108
3289.16	72.9708
3291.79	77.2021
3294.42	71.067
3297.04	74.8101
3299.66	72.5348
3302.28	74.8017
3304.89	73.9262
3307.5	70.6999
3310.11	74.8874
3312.72	72.0476
3315.32	75.5982
3317.92	70.1652
3320.52	76.3564
3323.12	70.8597
3325.71	73.5458
3328.3	75.8429
3330.89	77.4187
3333.47	75.646
3336.06	74.2651
3338.64	71.6048
3341.21	75.2238
3343.79	72.9733
3346.36	75.6716
3348.93	72.5944
3351.49	75.5083
3354.06	78.643
3356.62	77.876
3359.18	70.6611
3361.73	73.5767
3364.28	75.6768
3366.83	78.0149
3369.38	76.7879
3371.92	76.394
3374.47	76.4822
3377.01	77.0238
3379.54	72.9074
3382.08	74.9079
3384.61	74.6064
3387.14	77.5346
3389.66	78.9769
3392.19	74.2573
3394.71	86.011
3397.22	77.3458
3399.74	75.8817
3402.25	79.3524
3404.76	76.1256
3407.27	77.5574
3409.77	74.0538
3412.27	74.814
3414.77	77.8471
3417.27	75.0421
3419.68	74.6807
3422.23	75.6929
3424.77	76.2379
3427.31	74.2154
3429.85	79.3339
3432.39	77.4514
3434.92	75.2311
3437.45	78.2046
3439.98	77.7469
3442.51	79.2798
3445.03	79.4066
3447.55	81.9295
3450.07	79.6461
3452.58	78.4531
3455.09	78.8343
3457.6	80.4446
3460.11	77.0049
3462.62	80.363
3465.12	82.7227
3467.62	79.7962
3470.12	79.2006
3472.61	77.8852
3475.1	79.4978
3477.59	86.6188
3480.08	80.4738
3482.56	79.5497
3485.04	82.5205
3487.52	78.6816
3490	78.8363
3492.47	79.133
3494.94	78.0487
3497.41	78.5627
3499.88	80.203
3502.34	78.7578
3504.8	80.2947
3507.26	80.6511
3509.72	76.1879
3512.17	79.1394
3514.62	81.4798
3517.07	77.6793
3519.51	80.2237
3521.95	78.8633
3524.39	76.9829
3526.83	77.5233
3529.27	80.1812
3531.7	81.7364
3534.13	78.6983
3536.56	79.6061
3538.98	81.7331
3541.4	80.1923
3543.82	79.3151
3546.24	79.639
3548.65	78.0447
3551.06	79.7934
3553.47	74.7306
3555.88	82.5165
3558.28	77.1945
3560.69	78.2354
3563.08	78.7245
3565.48	78.0029
3567.87	76.3866
3570.26	78.6299
3572.61	77.7725
3575.05	76.8453
3577.49	77.7926
3579.93	76.7898
3582.36	77.9801
3584.79	79.0876
3587.22	79.0977
3589.65	75.0626
3592.07	81.7384
3594.49	84.1906
3596.91	77.8768
3599.32	76.3105
3601.74	77.0338
3604.15	77.5269
3606.56	78.6513
3608.96	76.8815
3611.36	78.2338
3613.76	78.0555
3616.16	79.3524
3618.56	77.3638
3620.95	79.8755
3623.34	76.0668
3625.73	74.8764
3628.12	78.4241
3630.5	78.794
3632.88	78.2346
3635.26	78.0063
3637.63	77.8006
3640.01	81.3533
3642.38	77.0542
3644.74	76.6331
3647.11	78.6391
3649.47	77.5799
3651.83	76.5072
3654.19	77.453
3656.55	79.9838
3658.9	78.3044
3661.25	80.3865
3663.6	77.7489
3665.94	78.5969
3668.29	79.5675
3670.63	75.8848
3672.97	78.6309
3675.3	77.519
3677.64	80.0518
3679.97	78.4611
3682.29	75.4787
3684.62	79.5591
3686.94	79.2084
3689.26	75.3381
3691.58	76.1222
3693.9	79.546
3696.21	78.987
3698.52	76.9718
3700.83	97.4536
3703.14	76.7008
3705.44	80.1258
3707.74	78.9958
3710.04	80.0232
3712.33	80.9246
3714.63	82.585
3716.92	80.3368
3719.19	83.1444
3721.53	80.7095
3723.87	81.0281
3726.21	84.7464
3728.54	82.7183
3730.87	82.4244
3733.2	79.1936
3735.52	79.9196
3737.85	81.1403
3740.17	80.2574
3742.49	82.9823
3744.8	79.9655
3747.11	85.6295
3749.43	81.9361
3751.73	98.2556
3754.04	80.8091
3756.34	82.3688
3758.64	80.332
3760.94	82.858
3763.24	80.6286
3765.53	80.1334
3767.83	86.3348
3770.12	85.3082
3772.4	81.6059
3774.69	80.8633
3776.97	81.2273
3779.25	82.4255
3781.52	80.755
3783.8	79.1331
3786.07	83.5867
3788.34	81.4345
3790.61	81.8772
3792.87	80.1657
3795.14	78.409
3797.4	85.8522
3799.65	79.0066
3801.91	84.143
3804.16	80.5948
3806.41	80.1141
3808.66	85.7611
3810.91	81.0926
3813.15	80.8627
3815.39	84.4191
3817.63	80.5359
3819.86	83.6928
3822.1	82.3009
3824.33	80.2187
3826.56	80.7752
3828.78	82.2437
3831.01	82.1206
3833.23	80.6199
3835.45	83.7049
3837.67	79.2554
3839.88	82.5873
3842.09	80.2976
3844.3	79.1294
3846.51	81.0473
3848.71	81.3145
3850.92	80.9258
3853.12	80.4524
3855.31	83.9851
3857.51	80.8038
3859.64	84.9983
3861.89	83.8364
3864.13	80.7883
3866.37	81.7014
3868.6	83.9741
3870.84	79.0219
3873.07	83.5181
3875.3	85.7871
3877.53	83.9501
3879.75	86.7157
3881.97	81.3808
3884.19	83.3984
3886.41	80.9075
3888.63	79.9844
3890.84	82.3985
3893.05	86.1903
3895.26	83.9838
3897.47	84.7386
3899.67	85.4845
3901.87	80.7807
3904.07	83.2734
3906.27	83.581
3908.46	84.5017
3910.66	83.6413
3912.85	85.8051
3915.03	84.5127
3917.22	83.5334
3919.4	85.3715
3921.58	85.0975
3923.76	84.7243
3925.94	80.6351
3928.11	84.955
3930.28	87.422
3932.45	83.1842
3934.62	85.2857
3936.78	81.4188
3938.94	81.3342
3941.1	85.7234
3943.26	85.0974
3945.41	84.0148
3947.57	84.4813
3949.72	86.1486
3951.86	84.4402
3954.01	85.0029
3956.15	82.5111
3958.29	84.6915
3960.43	85.4631
3962.57	82.4071
3964.7	85.2696
3966.83	83.1472
3968.96	82.892
3971.09	81.0439
3973.22	82.3555
3975.34	84.2574
3977.46	83.3501
3979.58	84.3333
3981.69	82.4593
3983.8	81.4756
3985.92	81.5289
3988.02	80.7663
3990.13	82.3388
3992.23	79.9783
3994.27	84.6346
3996.42	80.5078
3998.57	79.4434
4000.72	81.4198
4002.86	83.2813
4005.01	78.8754
4007.15	83.5899
4009.29	81.2765
4011.42	81.4166
4013.56	78.7792
4015.69	86.3522
4017.82	81.2321
4019.94	80.9598
4022.07	83.0546
4024.19	80.4039
4026.31	80.2099
4028.43	86.8117
4030.54	84.5511
4032.66	83.6999
4034.77	83.2083
4036.88	81.6149
4038.98	81.6259
4041.09	80.9019
4043.19	79.6892
4045.29	80.3916
4047.39	83.9403
4049.48	80.7162
4051.58	85.5752
4053.67	80.8037
4055.75	83.5196
4057.84	80.3448
4059.92	81.2273
4062.01	82.4297
4064.09	80.4123
4066.16	80.1812
4068.24	82.833
4070.31	83.379
4072.38	81.833
4074.45	81.0612
4076.51	79.7181
4078.58	80.7889
4080.64	83.919
4082.7	86.2449
4084.76	80.506
4086.81	82.5889
4088.86	80.0639
4090.91	84.2319
4092.96	77.6739
4095.01	79.8364
4097.05	82.8295
4099.09	81.8058
4101.13	81.4375
4103.17	81.5084
4105.2	82.0079
4107.23	82.4603
4109.26	79.8002
4111.29	78.5067
4113.32	77.983
4115.34	79.7468
4117.36	82.884
4119.38	78.9709
4121.28	77.751
4123.35	75.8792
4125.41	82.6149
4127.48	78.0282
4129.54	82.2859
4131.59	80.0779
4133.65	79.8017
4135.7	76.6736
4137.75	81.4674
4139.8	80.3347
4141.85	81.8427
4143.9	82.2868
4145.94	78.4173
4147.98	78.4659
4150.02	76.3178
4152.05	78.2337
4154.08	80.7081
4156.12	78.7084
4158.15	77.013
4160.17	77.6511
4162.2	82.6571
4164.22	79.6475
4166.24	81.5493
4168.26	80.5427
4170.27	79.4628
4172.29	82.7282
4174.3	77.7756
4176.31	78.3549
4178.32	81.9914
4180.32	82.0104
4182.32	77.2836
4184.32	79.1129
4186.32	80.408
4188.32	76.6776
4190.31	79.8648
4192.31	78.7917
4194.3	78.9389
4196.28	84.0472
4198.27	80.5165
4200.25	79.2614
4202.23	77.8403
4204.21	81.0014
4206.19	84.6728
4208.16	82.2581
4210.14	80.1478
4212.11	80.1708
4214.07	78.6497
4216.04	79.7355
4218	78.8169
4219.96	76.6707
4221.92	79.6372
4223.88	82.3985
4225.84	80.091
4227.79	79.5024
4229.74	79.5143
4231.69	77.4311
4233.63	81.6172
4235.58	76.1652
4237.52	78.1862
4239.46	77.9254
4241.4	78.8188
4243.33	82.5744
4245.3	80.2007
4247.28	81.6048
4249.26	79.9825
4251.24	79.9474
4253.22	80.7895
4255.19	77.8624
4257.16	80.0161
4259.13	78.3438
4261.1	82.4232
4263.07	80.3415
4265.03	81.4817
4266.99	80.6495
4268.95	81.4549
4270.91	79.0236
4272.86	83.8167
4274.81	80.303
4276.76	78.7734
4278.71	81.1294
4280.66	79.3594
4282.6	81.2878
4284.55	81.5311
4286.49	78.7387
4288.42	79.5749
4290.36	78.68
4292.29	79.412
4294.22	83.2164
4296.15	79.9625
4298.08	80.6364
4300.01	78.8489
4301.93	83.1782
4303.85	80.0755
4305.77	82.3806
4307.69	79.8326
4309.6	80.89
4311.51	81.2999
4313.42	78.179
4315.33	78.2961
4317.24	79.0123
4319.14	78.9605
4321.04	77.0398
4322.94	82.6716
4324.84	77.6065
4326.74	81.23
4328.63	83.2183
4330.52	86.8015
4332.41	78.6077
4334.3	74.8622
4336.18	80.0173
4338.06	79.3295
4339.94	78.7272
4341.82	80.0287
4343.7	78.3075
4345.57	79.4912
4347.45	78.6383
4349.32	76.9131
4351.19	78.0027
4353.05	79.0258
4354.91	77.9705
4356.78	76.9266
4358.64	77.5403
4360.49	77.8214
4362.3	74.9216
4364.21	80.9858
4366.11	79.5915
4368.01	78.1619
4369.91	78.2783
4371.8	79.0343
4373.7	80.1408
4375.59	79.4329
4377.48	76.7969
4379.37	76.4697
4381.26	78.7563
4383.14	76.4168
4385.02	82.427
4386.9	80.3001
4388.78	79.025
4390.66	81.2842
4392.53	79.9445
4394.4	74.1669
4396.27	77.6862
4398.14	79.8349
4400	82.0655
4401.87	79.4161
4403.73	78.9086
4405.59	81.2831
4407.44	80.4914
4409.3	106.862
4411.15	78.1013
4413	78.7208
4414.85	78.7821
4416.7	78.7503
4418.54	77.3549
4420.39	80.3339
4422.23	77.4391
4424.06	80.1411
4425.9	78.2195
4427.74	81.0584
4429.57	78.6043
4431.4	76.8901
4433.23	78.3945
4435.05	77.6906
4436.88	78.9052
4438.7	77.5108
4440.52	76.3547
4442.34	80.5717
4444.15	82.4324
4445.97	79.5369
4447.78	77.4318
4449.59	77.5791
4451.4	80.4603
4453.2	75.4006
4455.01	77.1983
4456.81	79.0285
4458.61	78.1976
4460.41	78.7133
4462.2	75.8341
4463.99	75.0571
4465.79	76.4492
4467.57	75.6253
4469.36	78.0581
4471.15	75.7788
4472.93	78.9867
4474.71	77.8171
4476.46	77.311
4478.29	78.3904
4480.11	76.9405
4481.94	74.979
4483.76	77.0277
4485.58	79.6474
4487.4	80.6727
4489.21	75.8473
4491.03	78.311
4492.84	78.0622
4494.65	79.5055
4496.46	77.4507
4498.26	76.5306
4499.95	76.7733