File: 28.3GPa.txt
#Acq. time (s)=	10
#Accumulations=	1
#Range (cm-¹)=	1300...1700
#Windows=	2
#Autofocus=	Off
#AutoExposure=	Off
#Spike filter=	Single accum. (Size=3)
#Delay time (s)=	0.1
#Binning=	1
#Readout mode=	Signal
#DeNoise=	Standard
#ICS correction=	On
#Dark correction=	Off
#Inst. Process=	Off
#Instrument=	LabRAM HR Evol
#Detector=	Synapse
#Objective=	x20SLWD
#Grating=	1800 gr/mm
#ND Filter=	100%
#Laser (nm)=	633
#Hole=	150.001
#Range=	Visible
#Collection=	Microscope
#StageXY=	Marzhauser
#StageZ=	Marzhauser
#X (µm)=	0
#Y (µm)=	0
#Z (µm)=	0
#Project=	20190124
#Sample=	1-2
#Site=
#Title=	D_59
#Remark=
#Date=	19.05.2019 00:01
#Acquired=	19.05.2019 00:01:55
1300.13	175.622
1300.68	176.894
1301.23	176.43
1301.78	175.975
1302.32	175.741
1302.87	176.24
1303.42	177.403
1303.97	178.918
1304.52	180.608
1305.07	182.271
1305.61	183.621
1306.16	184.589
1306.71	184.473
1307.26	184.133
1307.8	183.584
1308.35	183.06
1308.9	182.963
1309.45	182.948
1310	183.089
1310.54	183.295
1311.09	183.573
1311.64	183.949
1312.19	184.306
1312.73	184.664
1313.28	185.074
1313.83	185.48
1314.37	186.032
1314.92	186.737
1315.47	187.746
1316.01	189.364
1316.56	191.276
1317.11	193.343
1317.65	194.304
1318.2	195.185
1318.75	194.967
1319.29	194.456
1319.84	193.869
1320.39	195.401
1320.93	198.993
1321.48	204.382
1322.02	208.934
1322.57	213.004
1323.11	216.398
1323.66	220.082
1324.21	223.944
1324.75	228.531
1325.3	234.522
1325.84	241.768
1326.39	251.569
1326.93	265.167
1327.48	282.801
1328.02	305.435
1328.57	335.901
1329.11	372.305
1329.66	425.785
1330.2	506.049
1330.75	652.42
1331.29	863.756
1331.84	1177.31
1332.38	1532.05
1332.93	1872.05
1333.47	2020.17
1334.01	1996.48
1334.56	1875.84
1335.1	1714.42
1335.65	1560.59
1336.19	1443.83
1336.73	1348.22
1337.28	1259.39
1337.82	1183.8
1338.36	1111.83
1338.91	1061.49
1339.45	1018.9
1340	979.965
1340.54	938.763
1341.08	902.319
1341.63	866.434
1342.17	834.577
1342.71	806.986
1343.26	782.78
1343.8	760.549
1344.34	741.528
1344.88	723.381
1345.43	708.131
1345.97	693.419
1346.51	680.215
1347.05	667.895
1347.6	654.561
1348.14	642.129
1348.68	631.659
1349.22	621.207
1349.77	611.564
1350.31	603.631
1350.85	597.571
1351.39	591.158
1351.93	583.706
1352.48	577.02
1353.02	571.328
1353.56	567.062
1354.1	560.914
1354.64	553.976
1355.18	550.133
1355.72	546.554
1356.26	543.519
1356.81	540.569
1357.35	539.055
1357.89	537.791
1358.43	534.798
1358.97	530.614
1359.51	525.16
1360.05	522.187
1360.59	520.986
1361.13	518.349
1361.67	514.614
1362.21	509.46
1362.75	504.182
1363.29	501.975
1363.83	499.467
1364.37	497.457
1364.91	496.371
1365.45	495.991
1365.99	495.152
1366.53	494.484
1367.07	495.018
1367.61	496.096
1368.15	497.298
1368.69	497.831
1369.23	497.737
1369.77	496.772
1370.31	494.661
1370.85	491.199
1371.39	487.799
1371.93	485.497
1372.47	484.731
1373.01	485.567
1373.55	485.907
1374.08	487.464
1374.62	489.807
1375.16	491.924
1375.7	493.327
1376.24	494.514
1376.78	496.086
1377.31	497.325
1377.85	498.375
1378.39	498.125
1378.93	498.742
1379.47	501.261
1380.01	503.801
1380.54	506.446
1381.08	509.97
1381.62	513.402
1382.16	514.684
1382.69	515.833
1383.23	515.397
1383.77	516.244
1384.31	517.988
1384.84	519.936
1385.38	521.078
1385.92	522.789
1386.46	523.476
1386.99	522.381
1387.53	519.727
1388.07	515.299
1388.6	512.502
1389.14	513.921
1389.68	512.261
1390.21	510.193
1390.75	506.414
1391.29	501.532
1391.82	499.522
1392.36	498.86
1392.9	499.446
1393.43	502.154
1393.97	508.356
1394.5	515.654
1395.04	522.779
1395.58	526.086
1396.11	522.739
1396.65	513.542
1397.18	492.695
1397.72	454.364
1398.25	409.258
1398.79	366.507
1399.32	334.034
1399.86	300.243
1400.39	269.858
1400.93	245.219
1401.46	227.032
1402	216.07
1402.53	207.79
1403.07	201.427
1403.6	196.217
1404.14	191.904
1404.67	190.094
1405.21	188.641
1405.74	187.354
1406.28	184.44
1406.81	182.919
1407.34	183.534
1407.88	184.908
1408.41	186.147
1408.95	186.98
1409.48	187.097
1410.01	186.685
1410.55	185.452
1411.08	184.127
1411.62	182.759
1412.15	181.406
1412.68	180.275
1413.22	179.398
1413.75	178.919
1414.28	178.832
1414.82	178.907
1415.35	179.081
1415.88	179.317
1416.42	179.58
1416.95	179.854
1417.48	179.92
1418.01	179.95
1418.55	179.871
1419.08	179.686
1419.61	179.059
1420.14	178.299
1420.68	177.551
1421.21	176.722
1421.74	176.204
1422.27	176.703
1422.81	177.225
1423.34	177.799
1423.87	178.405
1424.4	179.003
1424.93	179.557
1425.46	179.794
1426	180.037
1426.53	180.238
1427.06	180.062
1427.59	179.728
1428.12	179.295
1428.65	178.605
1429.18	178.163
1429.72	177.729
1430.25	177.327
1430.78	177.57
1431.31	177.492
1431.84	177.385
1432.37	177.25
1432.9	177.108
1433.43	176.766
1433.96	176.573
1434.49	176.419
1435.02	176.303
1435.55	176.215
1436.08	176.143
1436.61	176.08
1437.14	176.06
1437.67	176.012
1438.2	175.959
1438.73	175.902
1439.26	175.84
1439.79	175.775
1440.32	175.706
1440.85	175.633
1441.38	175.558
1441.91	175.464
1442.44	175.353
1442.97	175.228
1443.5	175.096
1444.03	174.967
1444.56	174.834
1445.09	174.695
1445.61	174.544
1446.14	174.389
1446.67	174.207
1447.2	174.054
1447.73	173.969
1448.26	174.027
1448.79	174.904
1449.32	175.884
1449.84	176.601
1450.37	176.301
1450.9	176.52
1451.43	175.83
1451.96	174.895
1452.48	174.92
1453.01	175.845
1453.54	176.362
1454.07	176.648
1454.6	176.593
1455.12	176.113
1455.65	175.521
1456.18	175.019
1456.71	174.878
1457.23	175.745
1457.76	177.259
1458.29	178.749
1458.81	178.66
1459.34	178.244
1459.87	177.198
1460.4	176.06
1460.92	175.437
1461.45	175.07
1461.98	174.776
1462.5	174.53
1463.03	174.557
1463.55	174.859
1464.08	175.43
1464.61	176.355
1465.13	178.119
1465.66	179.986
1466.19	179.83
1466.71	179.085
1467.24	176.413
1467.76	175.023
1468.29	174.728
1468.82	176.817
1469.34	177.167
1469.87	177.979
1470.39	178.159
1470.92	177.601
1471.44	176.162
1471.97	175.481
1472.49	174.778
1473.02	175.141
1473.54	174.947
1474.07	175.35
1474.59	176.16
1475.12	176.797
1475.64	177.135
1476.17	177.355
1476.69	177.418
1477.22	177.295
1477.74	177.043
1478.27	176.205
1478.79	175.007
1479.32	173.836
1479.84	172.774
1480.36	172.017
1480.89	172.743
1481.41	173.809
1481.93	175.582
1482.46	177.182
1482.98	177.56
1483.51	177.308
1484.03	177.717
1484.55	177.657
1485.08	177.361
1485.6	181.115
1486.12	182.786
1486.65	180.596
1487.17	177.268
1487.69	176.721
1488.22	177.141
1488.74	178.305
1489.26	179.517
1489.78	180.374
1490.31	180.6
1490.83	180.027
1491.35	179.069
1491.88	178.968
1492.4	179.436
1492.92	179.783
1493.44	180.312
1493.96	180.858
1494.49	180.812
1495.01	179.743
1495.53	176.487
1496.05	174.513
1496.57	174.014
1497.1	174.505
1497.62	176.17
1498.14	178.393
1498.66	178.676
1499.18	178.864
1499.7	179.369
1500.23	179.446
1500.75	179.083
1501.27	178.619
1501.79	177.889
1502.31	177.083
1502.83	176.811
1503.35	177.042
1503.87	178.076
1504.39	177.864
1504.91	177.969
1505.44	177.535
1505.96	178.229
1506.48	179.689
1507	181.071
1507.52	181.169
1508.04	179.278
1508.56	179.008
1509.08	178.841
1509.6	179.052
1510.12	179.528
1510.64	180.1
1511.16	180.621
1511.68	180.942
1512.2	180.953
1512.72	180.748
1513.24	180.318
1513.76	179.747
1514.27	179.072
1514.79	178.444
1515.31	178.044
1515.83	177.888
1516.35	178.081
1516.87	180.585
1517.39	183.709
1517.91	183.846
1518.43	181.867
1518.95	179.907
1519.46	182.432
1519.98	182.725
1520.5	182.769
1521.02	182.638
1521.54	182.594
1522.06	182.614
1522.58	181.637
1523.09	181.123
1523.61	181.372
1524.13	182.172
1524.65	182.429
1525.17	181.908
1525.68	181.293
1526.2	180.734
1526.72	180.227
1527.24	179.884
1527.75	179.839
1528.27	179.902
1528.79	180
1529.31	180.122
1529.82	180.421
1530.34	180.404
1530.86	180.335
1531.37	179.836
1531.89	179.874
1532.41	180.004
1532.92	180.391
1533.44	180.744
1533.96	180.688
1534.47	180.312
1534.99	179.569
1535.51	178.999
1536.02	178.49
1536.54	178.109
1537.06	178.431
1537.57	178.781
1538.09	179.224
1538.6	179.727
1539.12	180.231
1539.64	180.703
1540.15	181.043
1540.67	181.375
1541.18	181.55
1541.7	181.736
1542.21	181.854
1542.73	181.907
1543.25	181.828
1543.76	181.511
1544.28	181.065
1544.79	180.378
1545.31	179.52
1545.82	179.041
1546.34	179.248
1546.85	180.079
1547.37	181.436
1547.88	182.502
1548.39	182.429
1548.91	182.67
1549.42	182.321
1549.94	181.762
1550.45	180.814
1550.97	179.978
1551.48	179.825
1552	180.006
1552.51	180.595
1553.02	181.782
1553.54	183.304
1554.05	184.923
1554.56	186.503
1555.08	187.676
1555.59	188.305
1556.11	188.398
1556.62	188.074
1557.13	187.343
1557.65	186.506
1558.16	185.72
1558.67	185.617
1559.19	186.195
1559.7	187.749
1560.21	188.555
1560.72	189.159
1561.24	189.889
1561.75	189.702
1562.26	188.498
1562.78	187.569
1563.29	187.566
1563.8	188.074
1564.31	188.705
1564.82	188.923
1565.34	189.133
1565.85	189.38
1566.36	189.447
1566.87	189.469
1567.39	189.483
1567.9	189.448
1568.41	189.615
1568.92	189.91
1569.43	190.448
1569.94	190.917
1570.46	191.052
1570.93	191.072
1571.45	191.019
1571.97	190.743
1572.49	190.474
1573.01	190.481
1573.53	190.718
1574.05	191.275
1574.57	191.655
1575.09	191.948
1575.61	192.15
1576.13	192.131
1576.64	191.306
1577.16	190.311
1577.68	189.123
1578.2	188.023
1578.72	187.629
1579.24	187.867
1579.76	188.938
1580.28	191.154
1580.8	192.489
1581.31	193.888
1581.83	194.543
1582.35	193.119
1582.87	191.42
1583.39	190.35
1583.91	189.761
1584.42	189.896
1584.94	190.268
1585.46	190.588
1585.98	190.593
1586.5	189.86
1587.01	189.059
1587.53	188.335
1588.05	187.753
1588.57	187.518
1589.08	187.542
1589.6	187.816
1590.12	188.401
1590.64	189.206
1591.15	190.215
1591.67	191.12
1592.19	190.562
1592.7	189.472
1593.22	190.148
1593.74	190.806
1594.26	191.218
1594.77	191.212
1595.29	190.752
1595.81	189.855
1596.32	188.93
1596.84	188.149
1597.36	188.146
1597.87	188.869
1598.39	190.171
1598.9	191.143
1599.42	190.331
1599.94	189.743
1600.45	188.868
1600.97	187.566
1601.48	187.369
1602	187.348
1602.52	187.4
1603.03	187.505
1603.55	187.709
1604.06	187.755
1604.58	187.727
1605.09	187.599
1605.61	187.38
1606.12	187.122
1606.64	186.869
1607.15	186.652
1607.67	186.459
1608.18	186.318
1608.7	186.378
1609.21	186.426
1609.73	186.611
1610.24	187.155
1610.76	189.827
1611.27	192.104
1611.79	193.492
1612.3	192.913
1612.81	191.337
1613.33	189.268
1613.84	187.252
1614.36	186.114
1614.87	185.476
1615.38	185.161
1615.9	184.871
1616.41	184.984
1616.93	185.737
1617.44	186.584
1617.95	187.302
1618.47	187.718
1618.98	187.372
1619.49	186.606
1620.01	185.798
1620.52	185.201
1621.03	184.944
1621.55	185.273
1622.06	186.118
1622.57	187.443
1623.09	188.743
1623.6	189.897
1624.11	190.665
1624.62	190.417
1625.14	189.653
1625.65	188.465
1626.16	187.191
1626.67	185.973
1627.19	185.469
1627.7	185.192
1628.21	185.356
1628.72	185.836
1629.23	186.702
1629.75	187.384
1630.26	186.606
1630.77	185.592
1631.28	185.003
1631.79	184.936
1632.3	185.434
1632.82	185.981
1633.33	186.348
1633.84	186.323
1634.35	185.309
1634.86	183.623
1635.37	182.033
1635.89	181.027
1636.4	180.399
1636.91	180.166
1637.42	180.384
1637.93	181.142
1638.44	182.383
1638.95	183.768
1639.46	183.906
1639.97	184.409
1640.48	185.022
1640.99	185.618
1641.5	186.062
1642.01	186.103
1642.52	185.611
1643.03	184.53
1643.54	183.372
1644.05	182.209
1644.56	181.887
1645.07	182.361
1645.58	183.255
1646.09	184.175
1646.6	185.066
1647.11	185.309
1647.62	185.403
1648.13	184.772
1648.64	184.081
1649.15	183.255
1649.66	182.848
1650.17	182.731
1650.68	182.775
1651.19	182.821
1651.69	182.94
1652.2	183.121
1652.71	183.175
1653.22	183.223
1653.73	183.273
1654.24	183.198
1654.75	183.016
1655.26	183.309
1655.76	183.66
1656.27	184.061
1656.78	184.525
1657.29	185.213
1657.8	185.719
1658.31	185.957
1658.81	185.97
1659.32	185.928
1659.83	185.863
1660.34	185.793
1660.84	185.665
1661.35	185.567
1661.86	185.516
1662.37	185.49
1662.87	185.656
1663.38	185.799
1663.89	185.9
1664.4	185.959
1664.9	186.011
1665.41	185.956
1665.92	185.875
1666.42	185.761
1666.93	185.5
1667.44	185.335
1667.94	185.19
1668.45	185.128
1668.96	185.22
1669.46	186.001
1669.97	186.43
1670.48	186.583
1670.98	185.393
1671.49	184.421
1672	183.982
1672.5	182.516
1673.01	183.023
1673.51	185.016
1674.02	187.747
1674.53	188.859
1675.03	188.782
1675.54	187.249
1676.04	185.345
1676.55	184.482
1677.05	183.725
1677.56	183.716
1678.06	185.38
1678.57	185.858
1679.08	186.239
1679.58	186.461
1680.09	186.583
1680.59	186.589
1681.09	186.523
1681.6	186.266
1682.11	185.798
1682.61	185.157
1683.11	184.297
1683.62	183.281
1684.12	182.439
1684.63	182.296
1685.13	182.905
1685.64	183.828
1686.14	184.687
1686.65	184.253
1687.15	183.71
1687.65	183.29
1688.16	183.232
1688.66	183.287
1689.16	183.463
1689.67	183.899
1690.17	184.383
1690.68	185.257
1691.18	186.117
1691.68	186.923
1692.19	187.603
1692.69	188.084
1693.19	188.408
1693.7	188.261
1694.2	187.993
1694.7	187.678
1695.2	187.306
1695.71	186.687
1696.21	185.966
1696.71	185.222
1697.22	184.486
1697.72	183.841
1698.22	183.719
1698.72	183.918
1699.23	184.34
1699.73	185.044
1699.98	185.687