File: 38.86GPa(break).txt
#Acq. time (s)=	10
#Accumulations=	1
#Range (cm-¹)=	1300...1700
#Windows=	2
#Autofocus=	Off
#AutoExposure=	Off
#Spike filter=	Single accum. (Size=3)
#Delay time (s)=	0.1
#Binning=	1
#Readout mode=	Signal
#DeNoise=	Standard
#ICS correction=	On
#Dark correction=	Off
#Inst. Process=	Off
#Instrument=	LabRAM HR Evol
#Detector=	Synapse
#Objective=	x20SLWD
#Grating=	1800 gr/mm
#ND Filter=	100%
#Laser (nm)=	633
#Hole=	150.001
#Range=	Visible
#Collection=	Microscope
#StageXY=	Marzhauser
#StageZ=	Marzhauser
#X (µm)=	0
#Y (µm)=	0
#Z (µm)=	0
#Project=	20190124
#Sample=	1-2
#Site=
#Title=	D_78
#Remark=
#Date=	19.05.2019 01:10
#Acquired=	19.05.2019 01:10:33
1300.13	127.615
1300.68	126.356
1301.23	124.945
1301.78	125.338
1302.32	125.38
1302.87	125.589
1303.42	125.801
1303.97	125.73
1304.52	126.1
1305.07	126.601
1305.61	127.287
1306.16	127.72
1306.71	127.754
1307.26	128.737
1307.8	128.817
1308.35	129.163
1308.9	129.122
1309.45	129.538
1310	130.025
1310.54	130.445
1311.09	131.88
1311.64	131.665
1312.19	130.895
1312.73	129.997
1313.28	129.712
1313.83	130.535
1314.37	131.596
1314.92	134.103
1315.47	135.676
1316.01	136.63
1316.56	137.868
1317.11	138.92
1317.65	140.547
1318.2	142.39
1318.75	144.724
1319.29	146.984
1319.84	148.815
1320.39	150.497
1320.93	151.862
1321.48	154.099
1322.02	158.712
1322.57	163.206
1323.11	167.557
1323.66	172.641
1324.21	178.214
1324.75	184.711
1325.3	192.174
1325.84	201.533
1326.39	212.918
1326.93	224.534
1327.48	236.68
1328.02	265.875
1328.57	309.506
1329.11	344.387
1329.66	398.838
1330.2	495.973
1330.75	657.49
1331.29	954.412
1331.84	1573.78
1332.38	2548.18
1332.93	3546.86
1333.47	3930.25
1334.01	3647.42
1334.56	3248.2
1335.1	2838.65
1335.65	2515.92
1336.19	2266.69
1336.73	2059.1
1337.28	1886.72
1337.82	1734.87
1338.36	1605.49
1338.91	1496.41
1339.45	1402.1
1340	1322.29
1340.54	1252.17
1341.08	1193.41
1341.63	1143.7
1342.17	1098.19
1342.71	1055.46
1343.26	1015.61
1343.8	976.745
1344.34	940.257
1344.88	906.816
1345.43	875.163
1345.97	846.171
1346.51	819.617
1347.05	796.826
1347.6	776.631
1348.14	758.584
1348.68	741.978
1349.22	729.824
1349.77	722.655
1350.31	712.624
1350.85	681.983
1351.39	670.682
1351.93	659.5
1352.48	649.633
1353.02	640.269
1353.56	630.591
1354.1	619.088
1354.64	606.706
1355.18	593.055
1355.72	581.981
1356.26	570.787
1356.81	561.379
1357.35	554.208
1357.89	546.643
1358.43	539.652
1358.97	533.246
1359.51	527.527
1360.05	522.547
1360.59	517.484
1361.13	512.987
1361.67	508.499
1362.21	504.12
1362.75	500.361
1363.29	495.747
1363.83	491.512
1364.37	487.296
1364.91	482.892
1365.45	477.708
1365.99	473.815
1366.53	471.52
1367.07	469.196
1367.61	467.871
1368.15	465.646
1368.69	460.894
1369.23	456.626
1369.77	451.905
1370.31	448.923
1370.85	446.802
1371.39	445.744
1371.93	444.222
1372.47	441.922
1373.01	437.732
1373.55	435.331
1374.08	433.765
1374.62	432.992
1375.16	433.698
1375.7	433.987
1376.24	433.353
1376.78	432.239
1377.31	429.378
1377.85	425.496
1378.39	422.525
1378.93	420.886
1379.47	419.322
1380.01	418.653
1380.54	419.681
1381.08	418.829
1381.62	418.99
1382.16	418.81
1382.69	419.263
1383.23	419.71
1383.77	419.914
1384.31	419.088
1384.84	419.564
1385.38	421.333
1385.92	424.131
1386.46	427.203
1386.99	431.151
1387.53	436.721
1388.07	441.338
1388.6	445.628
1389.14	450.031
1389.68	454.338
1390.21	459.664
1390.75	469.219
1391.29	481.661
1391.82	500.486
1392.36	523.897
1392.9	550.965
1393.43	577.166
1393.97	589.446
1394.5	584.286
1395.04	568.915
1395.58	551.325
1396.11	533.055
1396.65	517.051
1397.18	501.704
1397.72	486.901
1398.25	473.635
1398.79	463.022
1399.32	455.868
1399.86	449.443
1400.39	444.655
1400.93	439.61
1401.46	433.614
1402	427.461
1402.53	421.63
1403.07	416.388
1403.6	411.533
1404.14	407.928
1404.67	406.009
1405.21	404.453
1405.74	403.154
1406.28	401.356
1406.81	399.783
1407.34	398.861
1407.88	398.256
1408.41	397.148
1408.95	397.218
1409.48	399.504
1410.01	402.343
1410.55	404.783
1411.08	406.168
1411.62	407.359
1412.15	408.693
1412.68	409.466
1413.22	411.209
1413.75	413.861
1414.28	416.815
1414.82	418.222
1415.35	419.262
1415.88	418.95
1416.42	416.605
1416.95	412.277
1417.48	404.563
1418.01	395.805
1418.55	383.984
1419.08	370.179
1419.61	354.095
1420.14	338.506
1420.68	322.216
1421.21	306.463
1421.74	289.887
1422.27	273.695
1422.81	258.284
1423.34	243.797
1423.87	229.901
1424.4	217.822
1424.93	207.968
1425.46	200.021
1426	193.433
1426.53	186.847
1427.06	180.995
1427.59	175.443
1428.12	171.003
1428.65	166.394
1429.18	161.747
1429.72	157.596
1430.25	154.434
1430.78	152.32
1431.31	150.739
1431.84	149.992
1432.37	149.575
1432.9	148.961
1433.43	148.453
1433.96	146.932
1434.49	144.013
1435.02	142.597
1435.55	141.599
1436.08	141.291
1436.61	141.384
1437.14	140.831
1437.67	139.436
1438.2	136.28
1438.73	134.266
1439.26	133.621
1439.79	133.022
1440.32	132.952
1440.85	133.54
1441.38	133.634
1441.91	133.299
1442.44	131.885
1442.97	130.78
1443.5	130.396
1444.03	130.955
1444.56	131.699
1445.09	132.955
1445.61	133.849
1446.14	134.92
1446.67	135.041
1447.2	134.336
1447.73	132.84
1448.26	131.659
1448.79	130.404
1449.32	128.863
1449.84	128.634
1450.37	129.066
1450.9	129.907
1451.43	130.3
1451.96	129.751
1452.48	130.184
1453.01	130.419
1453.54	130.402
1454.07	131.097
1454.6	130.98
1455.12	130.648
1455.65	130.032
1456.18	129.271
1456.71	127.866
1457.23	126.99
1457.76	126.892
1458.29	126.676
1458.81	126.392
1459.34	126.319
1459.87	125.971
1460.4	125.606
1460.92	125.387
1461.45	125.037
1461.98	125.408
1462.5	125.616
1463.03	123.86
1463.55	121.647
1464.08	122.433
1464.61	125.079
1465.13	130.519
1465.66	130.47
1466.19	123.034
1466.71	124.826
1467.24	123.044
1467.76	125.801
1468.29	125.856
1468.82	126.004
1469.34	126.445
1469.87	126.754
1470.39	127.134
1470.92	127.177
1471.44	127.328
1471.97	127.612
1472.49	126.98
1473.02	126.612
1473.54	125.916
1474.07	124.056
1474.59	123.126
1475.12	122.399
1475.64	122.543
1476.17	123.073
1476.69	123.953
1477.22	125.171
1477.74	126.06
1478.27	126.389
1478.79	125.556
1479.32	124.696
1479.84	124.532
1480.36	124.098
1480.89	123.641
1481.41	123.194
1481.93	123.063
1482.46	123.349
1482.98	123.344
1483.51	122.859
1484.03	122.172
1484.55	123.097
1485.08	124.042
1485.6	125.912
1486.12	125.846
1486.65	125.105
1487.17	124.713
1487.69	125.188
1488.22	126.468
1488.74	127.57
1489.26	127.339
1489.78	126.576
1490.31	125.111
1490.83	123.698
1491.35	122.461
1491.88	121.654
1492.4	122.361
1492.92	123.963
1493.44	125.243
1493.96	126.455
1494.49	127.204
1495.01	127.28
1495.53	126.916
1496.05	126.165
1496.57	125.905
1497.1	125.412
1497.62	125.178
1498.14	125.164
1498.66	125.264
1499.18	125.31
1499.7	124.621
1500.23	124.214
1500.75	122.514
1501.27	120.632
1501.79	119.903
1502.31	120.029
1502.83	120.954
1503.35	123.229
1503.87	125.436
1504.39	126.919
1504.91	126.97
1505.44	126.746
1505.96	125.719
1506.48	124.069
1507	122.607
1507.52	121.323
1508.04	120.592
1508.56	121.056
1509.08	121.882
1509.6	122.175
1510.12	122.386
1510.64	122.876
1511.16	123.196
1511.68	123.117
1512.2	122.589
1512.72	122.497
1513.24	122.264
1513.76	122.609
1514.27	123.001
1514.79	123.545
1515.31	123.632
1515.83	124.018
1516.35	123.989
1516.87	124.193
1517.39	123.803
1517.91	122.904
1518.43	122.593
1518.95	122.203
1519.46	121.773
1519.98	121.954
1520.5	122.373
1521.02	122.985
1521.54	123.204
1522.06	123.408
1522.58	123.527
1523.09	123.903
1523.61	123.529
1524.13	123.633
1524.65	123.284
1525.17	122.398
1525.68	121.758
1526.2	120.992
1526.72	120.941
1527.24	121.509
1527.75	120.788
1528.27	121.835
1528.79	123.782
1529.31	124.95
1529.82	123.296
1530.34	122.908
1530.86	124.818
1531.37	124.756
1531.89	124.417
1532.41	124.16
1532.92	124.283
1533.44	124.632
1533.96	124.201
1534.47	123.369
1534.99	122.702
1535.51	121.839
1536.02	121.47
1536.54	120.802
1537.06	120.368
1537.57	120.966
1538.09	122.172
1538.6	123.138
1539.12	123.404
1539.64	123.726
1540.15	123.502
1540.67	123.217
1541.18	122.736
1541.7	121.901
1542.21	121.77
1542.73	122.056
1543.25	122.616
1543.76	123.081
1544.28	123.693
1544.79	124.217
1545.31	124.365
1545.82	124.649
1546.34	124.454
1546.85	123.763
1547.37	123.363
1547.88	122.937
1548.39	122.922
1548.91	123.011
1549.42	123.001
1549.94	123.385
1550.45	123.729
1550.97	123.83
1551.48	123.275
1552	123.067
1552.51	122.929
1553.02	123.189
1553.54	123.763
1554.05	124.233
1554.56	124.773
1555.08	124.758
1555.59	124.521
1556.11	124.345
1556.62	124.398
1557.13	124.194
1557.65	124.07
1558.16	124.603
1558.67	124.962
1559.19	125.287
1559.7	125.545
1560.21	125.611
1560.72	125.739
1561.24	125.64
1561.75	125.564
1562.26	125.115
1562.78	124.975
1563.29	125.124
1563.8	125.508
1564.31	126.046
1564.82	126.736
1565.34	127.141
1565.85	126.829
1566.36	126.419
1566.87	125.832
1567.39	125.077
1567.9	124.517
1568.41	124.536
1568.92	124.677
1569.43	124.921
1569.94	125.263
1570.46	125.584
1570.93	125.84
1571.45	125.981
1571.97	126.136
1572.49	126.392
1573.01	126.657
1573.53	126.916
1574.05	127.165
1574.57	127.404
1575.09	127.666
1575.61	127.893
1576.13	128.006
1576.64	128.202
1577.16	128.16
1577.68	126.807
1578.2	125.534
1578.72	124.416
1579.24	123.596
1579.76	123.382
1580.28	124.287
1580.8	125.732
1581.31	127.632
1581.83	129.421
1582.35	130.744
1582.87	131.435
1583.39	131.422
1583.91	130.463
1584.42	128.509
1584.94	126.249
1585.46	124.618
1585.98	123.531
1586.5	122.99
1587.01	122.987
1587.53	123.553
1588.05	124.455
1588.57	125.443
1589.08	126.44
1589.6	127.326
1590.12	127.742
1590.64	127.487
1591.15	127.043
1591.67	126.51
1592.19	126.062
1592.7	125.686
1593.22	125.633
1593.74	125.475
1594.26	125.311
1594.77	125.156
1595.29	125.017
1595.81	124.894
1596.32	124.78
1596.84	124.696
1597.36	124.645
1597.87	124.599
1598.39	124.556
1598.9	124.468
1599.42	124.56
1599.94	124.717
1600.45	124.922
1600.97	125.244
1601.48	125.442
1602	125.602
1602.52	125.735
1603.03	125.844
1603.55	125.348
1604.06	125.548
1604.58	125.801
1605.09	126.351
1605.61	126.617
1606.12	126.723
1606.64	126.543
1607.15	125.546
1607.67	124.568
1608.18	123.559
1608.7	122.766
1609.21	122.841
1609.73	122.974
1610.24	123.162
1610.76	123.432
1611.27	123.733
1611.79	123.787
1612.3	123.505
1612.81	123.142
1613.33	123.24
1613.84	125.007
1614.36	125.669
1614.87	125.083
1615.38	124.407
1615.9	123.709
1616.41	123.048
1616.93	122.631
1617.44	122.835
1617.95	123.226
1618.47	123.753
1618.98	124.34
1619.49	124.897
1620.01	124.949
1620.52	125.192
1621.03	125.5
1621.55	125.819
1622.06	126.112
1622.57	126.275
1623.09	126.17
1623.6	125.042
1624.11	121.769
1624.62	118.469
1625.14	119.268
1625.65	123.171
1626.16	125.744
1626.67	127.351
1627.19	126.279
1627.7	126.723
1628.21	127.048
1628.72	126.971
1629.23	126.674
1629.75	125.874
1630.26	125.017
1630.77	124.217
1631.28	123.562
1631.79	123.158
1632.3	123.449
1632.82	123.954
1633.33	124.392
1633.84	124.959
1634.35	124.902
1634.86	124.279
1635.37	123.674
1635.89	123.311
1636.4	123.212
1636.91	123.587
1637.42	123.843
1637.93	124.147
1638.44	124.108
1638.95	123.982
1639.46	123.588
1639.97	123.298
1640.48	123.112
1640.99	123.163
1641.5	124.057
1642.01	124.998
1642.52	125.885
1643.03	125.266
1643.54	124.417
1644.05	123.719
1644.56	123.275
1645.07	123.248
1645.58	123.735
1646.09	124.705
1646.6	125.527
1647.11	126.139
1647.62	125.702
1648.13	125.234
1648.64	124.7
1649.15	124.238
1649.66	123.959
1650.17	124.127
1650.68	124.717
1651.19	125.188
1651.69	125.415
1652.2	123.58
1652.71	121.401
1653.22	119.552
1653.73	120.199
1654.24	121.655
1654.75	122.971
1655.26	122.911
1655.76	120.985
1656.27	121.717
1656.78	122.869
1657.29	123.774
1657.8	124.362
1658.31	124.524
1658.81	124.103
1659.32	122.949
1659.83	122.056
1660.34	122.461
1660.84	123.361
1661.35	124.182
1661.86	125.153
1662.37	125.886
1662.87	126.182
1663.38	125.718
1663.89	125.198
1664.4	124.785
1664.9	124.488
1665.41	124.307
1665.92	124.209
1666.42	124.18
1666.93	124.171
1667.44	124.14
1667.94	124.35
1668.45	124.61
1668.96	124.917
1669.46	125.23
1669.97	125.22
1670.48	125.149
1670.98	124.832
1671.49	124.489
1672	124.176
1672.5	123.885
1673.01	123.639
1673.51	123.438
1674.02	123.411
1674.53	123.328
1675.03	123.452
1675.54	123.313
1676.04	123.156
1676.55	122.982
1677.05	122.796
1677.56	122.63
1678.06	122.493
1678.57	122.247
1679.08	122.289
1679.58	122.42
1680.09	123.002
1680.59	123.444
1681.09	123.9
1681.6	124.158
1682.11	124.325
1682.61	123.984
1683.11	123.899
1683.62	124.279
1684.12	124.918
1684.63	125.485
1685.13	125.82
1685.64	126.002
1686.14	125.837
1686.65	125.426
1687.15	124.914
1687.65	124.387
1688.16	123.669
1688.66	122.961
1689.16	122.28
1689.67	121.678
1690.17	121.437
1690.68	121.574
1691.18	121.971
1691.68	122.822
1692.19	123.793
1692.69	124.764
1693.19	125.451
1693.7	125.681
1694.2	125.839
1694.7	125.861
1695.2	125.885
1695.71	125.866
1696.21	125.81
1696.71	125.719
1697.22	125.612
1697.72	125.486
1698.22	125.521
1698.72	125.434
1699.23	125.35
1699.73	125.341
1699.98	125.43