File: 54.txt
#Acq. time (s)=	20
#Accumulations=	1
#Range (cm-¹)=	100...4500
#Windows=	24
#Autofocus=	Off
#AutoExposure=	Off
#Spike filter=	Single accum. (Size=3)
#Delay time (s)=	0.1
#Binning=	1
#Readout mode=	Signal
#DeNoise=	Standard
#ICS correction=	On
#Dark correction=	Off
#Inst. Process=	Off
#Instrument=	LabRAM HR Evol
#Detector=	Synapse
#Objective=	x20SLWD
#Grating=	1800 gr/mm
#ND Filter=	100%
#Laser (nm)=	633
#Hole=	150.001
#Range=	Visible
#Collection=	Microscope
#StageXY=	Marzhauser
#StageZ=	Marzhauser
#X (µm)=	0
#Y (µm)=	0
#Z (µm)=	0
#Project=	20190124
#Sample=	1-2
#Site=
#Title=	D_6
#Remark=
#Date=	18.05.2019 17:49
#Acquired=	18.05.2019 17:49:59
#Edit:Spike=	18.05.2019 17:54:25
#Edit:Spike=	18.05.2019 17:54:25
#Edit:Spike=	18.05.2019 17:54:26
#Edit:Spike=	18.05.2019 17:54:31
#Edit:Spike=	18.05.2019 17:54:31
#Edit:Spike=	18.05.2019 17:54:32
#Edit:Spike=	18.05.2019 17:54:32
#Edit:Spike=	18.05.2019 17:54:33
#Edit:Spike=	18.05.2019 17:54:34
#Edit:Spike=	18.05.2019 17:54:35
#Edit:Spike=	18.05.2019 17:54:35
#Edit:Spike=	18.05.2019 17:54:36
#Edit:Spike=	18.05.2019 17:55:08
#Edit:Spike=	18.05.2019 17:56:10
#Edit:Spike=	18.05.2019 17:56:10
#Edit:Spike=	18.05.2019 17:56:10
#Edit:Spike=	18.05.2019 17:56:11
#Edit:Spike=	18.05.2019 17:56:11
#Edit:Spike=	18.05.2019 17:56:11
#Edit:Spike=	18.05.2019 17:56:12
#Edit:Spike=	18.05.2019 17:56:12
#Edit:Spike=	18.05.2019 17:56:13
#Edit:Spike=	18.05.2019 17:56:13
#Edit:Spike=	18.05.2019 17:56:13
#Edit:Spike=	18.05.2019 17:56:14
#Edit:Spike=	18.05.2019 17:56:15
#Edit:Spike=	18.05.2019 17:56:16
#Edit:Spike=	18.05.2019 17:56:16
#Edit:Spike=	18.05.2019 17:56:17
#Edit:Spike=	18.05.2019 17:56:18
#Edit:Spike=	18.05.2019 17:56:19
#Edit:Spike=	18.05.2019 17:56:20
#Edit:Spike=	18.05.2019 17:56:20
#Edit:Spike=	18.05.2019 17:56:21
#Edit:Spike=	18.05.2019 17:56:21
#Edit:Spike=	18.05.2019 17:56:23
#Edit:Spike=	18.05.2019 17:56:23
#Edit:Spike=	18.05.2019 17:57:30
#Edit:Spike=	18.05.2019 17:57:30
#Edit:Spike=	18.05.2019 17:57:30
#Edit:Spike=	18.05.2019 17:57:30
#Edit:Spike=	18.05.2019 17:57:31
#Edit:Spike=	18.05.2019 17:57:31
#Edit:Spike=	18.05.2019 17:57:31
#Edit:Spike=	18.05.2019 17:57:31
#Edit:Spike=	18.05.2019 17:57:32
#Edit:Spike=	18.05.2019 17:57:32
#Edit:Spike=	18.05.2019 17:57:32
#Edit:Spike=	18.05.2019 17:57:33
#Edit:Spike=	18.05.2019 17:58:21
#Edit:Spike=	18.05.2019 17:58:21
101.205	151.813
106.294	155.102
111.376	154.725
116.455	151.146
121.527	147.744
126.595	144.612
131.657	145.827
136.714	143.108
141.766	135.806
146.812	130.479
151.852	123.108
156.889	118.92
161.919	119.925
166.943	112.419
171.964	106.581
176.977	105.725
181.987	97.0623
186.991	93.2894
191.99	91.9249
196.983	93.4715
201.971	92.2067
206.954	91.6132
211.931	91.9751
216.904	93.8816
221.87	93.6873
226.832	96.9446
231.79	98.357
236.741	100.581
241.686	100.328
246.628	100.375
251.564	103.739
256.494	105.33
261.419	106.054
266.339	105.919
271.255	110.355
276.163	110.872
281.069	113.485
285.967	110.945
290.861	118.7
295.75	116.257
300.633	120.419
305.511	118.157
310.385	122.107
315.253	122.041
320.116	123.893
324.973	125.715
329.826	127.485
334.673	128.331
339.515	128.985
344.351	130.917
349.183	134.356
354.011	132.774
358.832	134.153
363.648	132.009
368.459	132.695
373.265	133.024
378.066	130.897
382.862	131.068
387.653	130.978
392.439	133.007
397.219	129.157
401.993	133.464
406.764	131.224
411.528	129.502
416.288	132.576
421.043	129.916
425.793	129.426
430.538	129.303
435.277	130.784
439.912	131.59
444.71	129.957
449.504	127.639
454.294	127.355
459.077	128.808
463.856	130.189
468.629	127.933
473.398	127.642
478.163	127.075
482.921	128.266
487.675	130.281
492.424	130.202
497.168	129.221
501.908	129.973
506.641	131.217
511.37	131.521
516.095	129.111
520.813	133.685
525.528	133.221
530.237	134.293
534.941	134.303
539.64	136.352
544.335	135.293
549.024	141.441
553.709	139.703
558.388	143.751
563.063	141.86
567.734	141.433
572.398	148.795
577.058	144.052
581.713	142.896
586.363	145.599
591.008	147.182
595.649	142.261
600.284	141.944
604.914	145.402
609.541	142.343
614.16	147.267
618.777	145.191
623.388	147.558
627.994	142.283
632.595	142.348
637.191	140.07
641.783	138.186
646.369	144.346
650.951	143.296
655.528	140.168
660.1	145.068
664.667	147.088
669.229	143.052
673.786	143.168
678.339	147.738
682.886	147.296
687.429	143.817
691.968	141.979
696.502	143.334
701.03	140.634
705.553	137.593
710.072	135.052
714.586	134.95
719.095	134.939
723.607	130.197
728.174	128.215
732.735	126.727
737.293	126.366
741.846	121.097
746.394	122.541
750.938	124.535
755.476	117.379
760.01	116.967
764.54	120.008
769.065	113.43
773.585	111.949
778.1	111.3
782.611	112.489
787.116	110.367
791.617	109.729
796.113	108.701
800.605	107.847
805.093	107.683
809.575	105.689
814.052	104.17
818.526	103.499
822.994	104.745
827.457	97.4437
831.916	103.117
836.37	99.3619
840.82	98.9784
845.266	101.59
849.707	100.514
854.142	97.7312
858.573	97.1463
862.999	96.5947
867.421	96.5088
871.839	94.9072
876.251	97.5281
880.659	96.1188
885.062	94.6055
889.461	94.9291
893.855	92.4244
898.244	96.2918
902.629	93.6063
907.01	91.7688
911.385	92.2052
915.756	93.0697
920.122	92.215
924.483	90.9916
928.84	92.0287
933.194	90.5357
937.542	89.2335
941.885	92.3183
946.224	88.9226
950.557	89.9692
954.887	89.4561
959.212	88.9544
963.533	87.9558
967.848	85.6036
972.16	86.3384
976.466	83.5686
980.768	84.42
985.065	84.9198
989.359	85.0887
993.647	83.9367
997.707	84.5603
1002.05	88.5543
1006.4	83.2847
1010.73	82.4504
1015.07	81.1548
1019.39	82.6664
1023.72	82.3999
1028.04	82.6151
1032.35	81.4784
1036.67	81.4548
1040.97	81.468
1045.27	80.617
1049.57	80.8808
1053.86	79.8483
1058.15	78.7477
1062.44	80.0022
1066.72	81.8201
1070.99	78.8607
1075.26	79.5956
1079.53	79.9251
1083.79	80.056
1088.05	80.5442
1092.3	78.2078
1096.55	77.4637
1100.8	78.8572
1105.04	76.7212
1109.27	77.3631
1113.5	77.9783
1117.73	77.8673
1121.95	74.8932
1126.17	76.556
1130.38	74.7427
1134.59	74.989
1138.8	76.4887
1143	72.3166
1147.19	74.4133
1151.38	73.7235
1155.57	76.6229
1159.75	73.6897
1163.93	73.4118
1168.11	73.4414
1172.28	74.3523
1176.44	71.8204
1180.6	74.6041
1184.76	73.156
1188.91	72.8007
1193.06	71.8753
1197.2	71.8797
1201.34	72.5674
1205.48	71.8227
1209.61	71.8632
1213.73	70.94
1217.85	72.9568
1221.97	71.3295
1226.08	71.6834
1230.19	72.8295
1234.3	70.9263
1238.4	72.3405
1242.49	71.6479
1246.58	72.6064
1250.67	73.9536
1254.75	73.8991
1258.78	75.5739
1262.92	72.75
1267.06	74.9124
1271.19	75.2525
1275.32	72.4573
1279.44	75.4663
1283.56	74.3415
1287.67	76.8803
1291.78	76.6969
1295.88	78.5197
1299.99	80.0883
1304.08	83.9661
1308.18	88.3794
1312.26	92.634
1316.35	101.849
1320.43	117.732
1324.51	156.935
1328.58	301.324
1332.64	2248.38
1336.71	2906.78
1340.77	2290.27
1344.82	1937.77
1348.87	1673.19
1352.92	1473.13
1356.96	1299.6
1361	1184.16
1365.03	1094.77
1369.06	1006.75
1373.09	932.606
1377.11	875.941
1381.13	831.615
1385.14	786.109
1389.15	756.518
1393.16	725.192
1397.16	698.053
1401.15	680.246
1405.14	657.416
1409.13	658.333
1413.12	646.465
1417.1	641.098
1421.07	655.92
1425.04	661.468
1429.01	676.12
1432.97	648.268
1436.93	502.405
1440.89	481.65
1444.84	534.096
1448.79	490.944
1452.73	116.154
1456.67	80.8358
1460.6	73.8155
1464.53	70.0752
1468.46	67.1584
1472.38	66.5139
1476.3	65.0366
1480.21	66.9726
1484.12	64.4867
1488.02	63.6135
1491.93	64.9946
1495.82	65.364
1499.72	65.6171
1503.44	64.3336
1507.39	64.3357
1511.34	64.7884
1515.28	63.7805
1519.22	63.3461
1523.15	63.0119
1527.08	62.966
1531	62.5968
1534.93	61.8372
1538.84	61.557
1542.75	61.3294
1546.66	59.8522
1550.57	63.2708
1554.47	62.5979
1558.37	63.1289
1562.26	61.7381
1566.15	61.2623
1570.04	60.7674
1573.92	60.6652
1577.79	62.0588
1581.67	62.4396
1585.54	61.6331
1589.4	60.2722
1593.26	62.4366
1597.12	60.3254
1600.97	61.7652
1604.82	59.9448
1608.67	61.2032
1612.51	59.3929
1616.34	60.7249
1620.18	59.6048
1624.01	58.6339
1627.83	59.811
1631.65	60.3206
1635.47	60.3807
1639.29	59.3035
1643.1	60.0032
1646.9	59.2141
1650.7	59.4903
1654.5	59.3011
1658.29	58.7086
1662.08	60.9417
1665.87	60.4856
1669.65	60.1224
1673.43	59.5927
1677.2	59.526
1680.97	59.5198
1684.74	60.9878
1688.5	59.536
1692.26	59.2825
1696.01	58.8285
1699.76	61.9756
1703.51	60.5753
1707.25	59.8328
1710.99	60.5921
1714.73	59.6408
1718.46	59.1764
1722.18	61.5696
1725.91	60.0426
1729.63	60.8503
1733.34	61.286
1737.05	61.0662
1740.74	61.5617
1744.51	60.1769
1748.27	60.8182
1752.03	61.7273
1755.79	60.9298
1759.54	61.0093
1763.29	63.8677
1767.03	61.6464
1770.77	60.8258
1774.51	62.3229
1778.24	62.1702
1781.97	61.3364
1785.69	61.9453
1789.41	61.7245
1793.13	62.348
1796.84	64.4561
1800.55	66.775
1804.26	64.4836
1807.96	63.9319
1811.66	62.3881
1815.35	62.4227
1819.04	64.7869
1822.73	60.1588
1826.41	63.9171
1830.09	65.8747
1833.77	64.8595
1837.44	63.9037
1841.11	64.3812
1844.77	66.1094
1848.43	63.8058
1852.09	65.1866
1855.74	65.5945
1859.39	61.9374
1863.03	64.8202
1866.67	64.7618
1870.31	64.0134
1873.95	64.9995
1877.58	64.8036
1881.2	65.8283
1884.82	64.3345
1888.44	63.5064
1892.06	64.4979
1895.67	64.8853
1899.28	66.2627
1902.88	62.033
1906.48	65.6385
1910.08	66.8481
1913.67	64.6434
1917.26	66.1249
1920.84	66.2913
1924.42	66.2655
1928	65.5533
1931.58	65.5621
1935.15	65.6324
1938.71	67.5588
1942.28	66.2936
1945.83	67.5064
1949.39	68.5973
1952.94	66.959
1956.49	67.8573
1960.03	66.3935
1963.57	68.9653
1966.97	69.5814
1970.56	67.5167
1974.16	68.0515
1977.74	69.0708
1981.33	68.0515
1984.91	67.5298
1988.49	68.1743
1992.06	67.7754
1995.63	68.7053
1999.19	68.9824
2002.76	67.7217
2006.31	70.0895
2009.87	68.8814
2013.42	73.536
2016.97	66.6217
2020.51	70.6629
2024.05	68.7634
2027.59	69.6507
2031.12	66.7479
2034.65	69.734
2038.18	72.1087
2041.7	68.48
2045.22	67.9823
2048.74	71.4661
2052.25	70.0963
2055.76	70.9973
2059.26	69.8823
2062.76	69.8695
2066.26	70.7934
2069.75	72.1685
2073.24	68.5076
2076.73	71.7404
2080.21	72.0157
2083.69	71.9055
2087.16	69.4536
2090.64	70.165
2094.11	69.9135
2097.57	70.0952
2101.03	71.6206
2104.49	71.0446
2107.94	71.4623
2111.39	74.16
2114.84	71.6271
2118.28	70.1199
2121.72	71.815
2125.16	72.2205
2128.59	75.5801
2132.02	70.5073
2135.45	71.9658
2138.87	73.6802
2142.29	72.0762
2145.7	73.8651
2149.11	73.7665
2152.52	70.7025
2155.92	72.4565
2159.32	74.3006
2162.72	73.6223
2166.11	75.6419
2169.5	74.7727
2172.89	76.5969
2176.27	76.3849
2179.56	77.3673
2183	77.8791
2186.43	75.3953
2189.86	77.0705
2193.29	76.0686
2196.71	75.3995
2200.13	76.5469
2203.54	78.7247
2206.96	78.5712
2210.36	77.9981
2213.77	77.514
2217.17	78.9561
2220.57	78.1531
2223.96	81.819
2227.35	78.1349
2230.74	80.163
2234.13	77.4356
2237.51	79.9708
2240.89	79.8148
2244.26	81.6983
2247.63	82.2269
2251	78.8477
2254.36	80.5976
2257.72	83.6339
2261.08	82.4489
2264.43	82.0052
2267.78	80.9117
2271.13	82.0453
2274.47	83.4975
2277.81	83.1338
2281.15	82.0006
2284.48	81.4254
2287.81	87.4326
2291.13	86.7385
2294.46	83.7451
2297.77	84.7686
2301.09	83.9567
2304.4	85.5374
2307.71	86.9787
2311.02	85.2988
2314.32	85.6121
2317.61	87.5667
2320.91	86.6208
2324.2	89.9939
2327.49	88.4747
2330.77	86.3966
2334.06	86.6167
2337.33	87.2414
2340.61	90.8734
2343.88	90.3399
2347.15	90.7611
2350.41	92.0842
2353.67	89.138
2356.93	90.0988
2360.18	88.6419
2363.43	94.9945
2366.68	94.5389
2369.92	94.404
2373.16	94.5582
2376.4	97.1578
2379.63	97.1045
2382.86	99.7303
2385.93	99.8305
2389.22	97.4563
2392.5	100.403
2395.77	99.3065
2399.05	103.559
2402.32	100.497
2405.58	97.1597
2408.85	103.81
2412.11	104.281
2415.36	101.324
2418.62	104.986
2421.87	103.721
2425.12	104.99
2428.36	104.971
2431.6	108.893
2434.84	107.669
2438.07	107.485
2441.3	109.749
2444.53	109.782
2447.75	112.896
2450.97	111.118
2454.19	114.512
2457.41	113.54
2460.62	115.504
2463.82	116.686
2467.03	117.509
2470.23	122.459
2473.43	119.632
2476.62	118.781
2479.81	118.521
2483	122.059
2486.18	123.773
2489.36	121.204
2492.54	120.828
2495.72	125.143
2498.89	119.352
2502.06	120.048
2505.22	120.026
2508.38	119.713
2511.54	121.544
2514.69	115.677
2517.85	114.965
2520.99	119.219
2524.14	117.206
2527.28	117.282
2530.42	120.044
2533.56	120.163
2536.69	117.369
2539.82	119.042
2542.94	118.888
2546.06	120.27
2549.18	114.348
2552.3	120.84
2555.41	118.895
2558.52	117.782
2561.63	119.007
2564.73	119.314
2567.83	119.842
2570.92	122.668
2574.02	122.097
2577.11	119.056
2580.05	123.061
2583.19	121.469
2586.33	124.256
2589.46	126.688
2592.6	121.712
2595.73	124.959
2598.85	121.309
2601.98	122.582
2605.1	119.44
2608.21	123.076
2611.33	119.829
2614.44	126.103
2617.55	122.142
2620.65	121.731
2623.75	132.189
2626.85	121.034
2629.94	122.433
2633.03	119.021
2636.12	118.972
2639.21	121.516
2642.29	119.789
2645.37	125.307
2648.45	136.433
2651.52	116.906
2654.59	118.405
2657.65	117.985
2660.72	119.331
2663.78	116.524
2666.83	119.329
2669.89	123.682
2672.94	121.095
2675.99	120.253
2679.03	119.456
2682.07	118.593
2685.11	117.409
2688.14	115.167
2691.17	117.747
2694.2	115.004
2697.23	113.952
2700.25	119.429
2703.27	115.618
2706.29	117.602
2709.3	114.91
2712.31	116.568
2715.32	118.681
2718.32	112.787
2721.32	113.897
2724.32	116.665
2727.31	116.805
2730.3	115.221
2733.29	113.355
2736.27	114.132
2739.26	114.533
2742.23	114.084
2745.21	114.707
2748.18	112.924
2751.15	113.527
2754.12	113.635
2757.08	113.136
2760.04	112.374
2763	115.311
2765.95	113.101
2768.74	113.084
2771.75	110.83
2774.75	112.858
2777.75	109.745
2780.75	116.928
2783.74	114
2786.73	111.293
2789.72	112.689
2792.7	115.524
2795.69	111.986
2798.66	113.776
2801.64	112.204
2804.61	117.625
2807.58	125.718
2810.55	112.629
2813.51	115.344
2816.47	113.171
2819.43	115.587
2822.38	115.418
2825.33	112.1
2828.28	109.619
2831.23	114.791
2834.17	114.072
2837.11	117.311
2840.04	115.331
2842.98	118.876
2845.91	115.456
2848.83	114.177
2851.76	114.846
2854.68	116.654
2857.6	114.119
2860.51	112.906
2863.42	115.552
2866.33	116.111
2869.24	112.855
2872.14	115.329
2875.04	110.488
2877.94	116.152
2880.83	112.848
2883.72	115.395
2886.61	111.787
2889.5	118.317
2892.38	114.598
2895.26	119.12
2898.13	118.33
2901	114.954
2903.87	117.516
2906.74	118.537
2909.6	114.404
2912.47	117.713
2915.32	116.991
2918.18	117.777
2921.03	116.427
2923.88	120.569
2926.72	116.679
2929.57	119.01
2932.41	117.492
2935.24	121.822
2938.08	119.189
2940.91	123.788
2943.74	119.613
2946.56	119.392
2949.39	123.585
2952.27	122.082
2955.14	123.281
2958.01	122.727
2960.88	121.252
2963.75	122.838
2966.61	120.111
2969.47	122.169
2972.32	125.97
2975.18	122.773
2978.03	120.56
2980.87	122.468
2983.72	120.001
2986.56	124.79
2989.4	121.397
2992.23	126.835
2995.07	121.301
2997.9	119.381
3000.72	124.37
3003.55	123.428
3006.37	123.704
3009.19	122.407
3012	125.643
3014.81	125.182
3017.62	126.933
3020.43	126.163
3023.23	123.839
3026.03	130.622
3028.83	124.027
3031.63	125.55
3034.42	128.109
3037.21	124.541
3039.99	127.436
3042.78	127.685
3045.56	125.904
3048.33	125.587
3051.11	128.422
3053.88	130.557
3056.65	125.375
3059.42	129.298
3062.18	128.139
3064.94	127.133
3067.7	128.966
3070.45	124.601
3073.2	126.179
3075.95	128.4
3078.7	123.527
3081.44	129.646
3084.18	123.955
3086.92	129.218
3089.65	123.598
3092.38	130.232
3095.11	129.691
3097.84	127.552
3100.56	125.605
3103.28	128.594
3106	128.886
3108.71	129.193
3111.42	126.161
3114.13	131.26
3116.84	127.376
3119.49	129.032
3122.24	124.688
3125	128.084
3127.75	129.397
3130.49	129.227
3133.24	133.431
3135.98	127.135
3138.72	135.679
3141.46	130.729
3144.19	129.839
3146.92	125.527
3149.65	130.914
3152.37	130.034
3155.1	131.067
3157.82	133.843
3160.53	131.65
3163.25	125.62
3165.96	130.608
3168.67	129.212
3171.37	131.17
3174.08	129.422
3176.78	127.862
3179.47	131.359
3182.17	131.503
3184.86	129.013
3187.55	131.499
3190.23	128.323
3192.92	125.873
3195.6	130.09
3198.27	126.049
3200.95	133.647
3203.62	130.57
3206.29	131.783
3208.96	133.293
3211.62	130.215
3214.28	130.608
3216.94	127.335
3219.6	129.347
3222.25	127.441
3224.9	133.073
3227.55	131.215
3230.19	128.953
3232.83	126.277
3235.47	126.48
3238.11	129.974
3240.74	128.978
3243.37	133.604
3246	130.357
3248.62	125.691
3251.25	132.978
3253.86	125.765
3256.48	129.312
3259.09	130.243
3261.71	135.919
3264.31	130.824
3266.92	131.09
3269.52	130.746
3272.12	132.926
3274.72	136.335
3277.31	131.831
3279.91	136.628
3282.5	138.346
3285.03	133.23
3287.67	135.188
3290.31	135.978
3292.94	134.206
3295.57	134.242
3298.2	135.79
3300.83	132.208
3303.45	131.654
3306.07	130.326
3308.69	139.778
3311.31	133.403
3313.92	137.447
3316.53	135.227
3319.14	131.027
3321.74	136.785
3324.35	140.533
3326.95	142.299
3329.54	137.625
3332.14	141.552
3334.73	134.194
3337.32	133.941
3339.9	141.342
3342.49	136.125
3345.07	139.104
3347.64	139.256
3350.22	135.085
3352.79	138.563
3355.36	139.094
3357.93	136.26
3360.49	138.74
3363.06	141.339
3365.62	140.393
3368.17	135.978
3370.73	139.975
3373.28	135.278
3375.83	140.224
3378.37	138.446
3380.92	139.089
3383.46	139.056
3385.99	138.167
3388.53	136.681
3391.06	137.073
3393.59	135.85
3396.12	142.622
3398.64	136.938
3401.16	139.488
3403.68	138.242
3406.2	140.641
3408.71	135.577
3411.22	134.443
3413.73	135.726
3416.24	138.814
3418.74	135.221
3421.24	141.426
3423.74	137.559
3426.24	141.705
3428.73	138.656
3431.22	140.55
3433.71	141.76
3436.19	138.828
3438.67	141.177
3441.15	139.612
3443.52	138.291
3446.05	146.44
3448.58	138.599
3451.1	143.309
3453.62	141.326
3456.14	138.247
3458.66	142.163
3461.17	136.858
3463.68	146.758
3466.19	141.062
3468.7	141.197
3471.2	139.151
3473.7	142.013
3476.2	146.744
3478.69	148.841
3481.19	139.919
3483.68	141.54
3486.16	141.793
3488.65	137.452
3491.13	141.728
3493.61	140.613
3496.09	138.388
3498.56	148.692
3501.03	144.746
3503.5	139.448
3505.97	141.266
3508.43	137.881
3510.9	137.256
3513.35	141.45
3515.81	141.027
3518.26	139.443
3520.72	142.563
3523.17	134.088
3525.61	143.166
3528.05	140.651
3530.5	138.791
3532.93	142.781
3535.37	137.128
3537.8	141.954
3540.23	144.666
3542.66	144.326
3545.09	139.52
3547.51	140.485
3549.93	140.148
3552.35	137.988
3554.76	139.609
3557.18	138.357
3559.59	140.711
3561.99	136.864
3564.4	145.256
3566.8	142.29
3569.2	134.852
3571.6	131.968
3573.99	143.846
3576.38	142.576
3578.77	142.003
3581.16	139.743
3583.55	143.033
3585.93	144.257
3588.31	141.312
3590.68	145.306
3592.93	147.46
3595.35	139.086
3597.78	144.392
3600.2	144.687
3602.62	139.836
3605.03	140.833
3607.45	145.479
3609.86	142.57
3612.27	141.54
3614.67	141.461
3617.08	140.356
3619.48	146.623
3621.88	142.159
3624.27	146.101
3626.67	141.819
3629.06	147.214
3631.45	144.831
3633.83	145.231
3636.22	146.075
3638.6	143.733
3640.98	139.565
3643.35	141.48
3645.73	143.154
3648.1	142.271
3650.47	144.954
3652.83	138.922
3655.2	138.948
3657.56	144.974
3659.92	146.322
3662.27	140.645
3664.63	143.698
3666.98	141.693
3669.33	141.27
3671.67	143.56
3674.02	141.78
3676.36	143.496
3678.7	142.764
3681.03	140.856
3683.37	141.449
3685.7	140.896
3688.03	142.868
3690.35	138.851
3692.68	147.941
3695	141.885
3697.32	140.686
3699.63	141.567
3701.95	148.765
3704.26	147.764
3706.57	138.887
3708.87	138.47
3711.18	139.628
3713.48	139.589
3715.78	141.778
3718.08	140.168
3720.37	144.528
3722.66	143.074
3724.95	143.007
3727.24	157.383
3729.52	142.738
3731.8	144.58
3734.08	141.524
3736.36	144.578
3738.55	144.774
3740.88	142.714
3743.2	143.441
3745.52	141.924
3747.84	145.721
3750.16	138.917
3752.47	146.87
3754.78	144.751
3757.09	139.141
3759.4	142.91
3761.7	142.312
3764	142.41
3766.3	141.219
3768.6	141.119
3770.89	145.066
3773.18	140.045
3775.47	139.541
3777.76	144.562
3780.05	144.182
3782.33	145.524
3784.61	144.5
3786.88	140.475
3789.16	144.335
3791.43	140.641
3793.7	139.61
3795.97	138.079
3798.24	144.456
3800.5	134.332
3802.76	138.008
3805.02	140.385
3807.27	138.366
3809.53	137.53
3811.78	140.121
3814.03	139.954
3816.27	136.262
3818.51	140.514
3820.76	140.693
3823	143.599
3825.23	140.073
3827.47	136.909
3829.7	144.398
3831.93	138.601
3834.15	138.894
3836.38	142.168
3838.6	139.374
3840.82	140.076
3843.04	144.059
3845.25	139.693
3847.46	134.241
3849.67	141.929
3851.88	139.082
3854.09	139.861
3856.29	144.565
3858.49	136.349
3860.69	137.671
3862.88	134.003
3865.08	143.001
3867.27	137.244
3869.46	137.557
3871.64	136.952
3873.83	134.913
3875.91	135.067
3878.15	140.168
3880.38	138.77
3882.6	138.524
3884.83	138.912
3887.05	138.453
3889.28	138.647
3891.49	133.079
3893.71	139.264
3895.92	139.311
3898.14	135.957
3900.35	143.283
3902.55	138.952
3904.76	133.992
3906.96	136.049
3909.16	141.574
3911.36	135.868
3913.55	131.981
3915.75	137.593
3917.94	136.164
3920.13	136.807
3922.31	134.594
3924.5	134.071
3926.68	135.979
3928.86	138.291
3931.03	135.312
3933.21	132.951
3935.38	133.086
3937.55	138.535
3939.72	135.567
3941.88	135.553
3944.05	137.82
3946.21	139.09
3948.36	137.749
3950.52	135.575
3952.67	132.486
3954.82	137.679
3956.97	130.29
3959.12	132.042
3961.26	131.817
3963.41	134.073
3965.55	132.282
3967.68	133.339
3969.82	133.112
3971.95	132.288
3974.08	129.646
3976.21	130.993
3978.34	133.049
3980.46	127.061
3982.58	130.977
3984.7	132.736
3986.81	127.089
3988.93	130.922
3991.04	129.229
3993.15	131.681
3995.26	129.384
3997.36	133.095
3999.47	130.225
4001.57	128.908
4003.66	128.825
4005.76	132.457
4007.85	129.232
4009.84	131.557
4011.98	131.392
4014.12	131.177
4016.26	128.724
4018.39	135.554
4020.53	130.145
4022.66	122.76
4024.78	131.112
4026.91	127.22
4029.03	136.795
4031.16	123.999
4033.27	130.38
4035.39	134.545
4037.5	128.064
4039.62	129.318
4041.73	128.306
4043.83	121.311
4045.94	128.311
4048.04	128.446
4050.14	133.292
4052.24	128.484
4054.34	124.988
4056.43	127.262
4058.52	128.473
4060.61	128.422
4062.7	130.293
4064.79	125.604
4066.87	128.865
4068.95	128.13
4071.03	130.662
4073.1	134.681
4075.18	127.835
4077.25	133.248
4079.32	130.133
4081.39	126.002
4083.45	127.489
4085.51	128.029
4087.57	125.46
4089.63	123.107
4091.69	125.78
4093.74	123.308
4095.79	129.231
4097.84	127.268
4099.89	121.81
4101.93	123.507
4103.98	128.022
4106.02	127.561
4108.05	121.056
4110.09	127.05
4112.12	121.23
4114.15	123.415
4116.18	125.666
4118.21	124.442
4120.23	121.793
4122.26	125.886
4124.28	120.756
4126.29	119.257
4128.31	124.617
4130.32	123.076
4132.33	125.432
4134.34	121.945
4136.26	124.673
4138.32	120.728
4140.38	121.267
4142.43	119.256
4144.48	128.193
4146.53	119.872
4148.57	119.581
4150.62	122.488
4152.66	124.422
4154.7	124.275
4156.73	124.77
4158.77	122.5
4160.8	122.598
4162.83	123.478
4164.86	117.076
4166.89	123.289
4168.91	121.825
4170.93	124.996
4172.95	124.889
4174.97	122.855
4176.99	122.934
4179	127.684
4181.01	120.789
4183.02	120.973
4185.02	121.093
4187.03	124.544
4189.03	120.016
4191.03	119.889
4193.03	118.51
4195.02	130.788
4197.02	123.233
4199.01	120.1
4201	126.231
4202.98	123.364
4204.97	122.233
4206.95	121.875
4208.93	120.278
4210.91	121.366
4212.89	121.486
4214.86	124.973
4216.83	120.458
4218.8	121.248
4220.77	127.221
4222.73	120.001
4224.7	125.807
4226.66	122.735
4228.62	117.801
4230.57	127.431
4232.53	122.209
4234.48	128.887
4236.43	124.049
4238.38	122.728
4240.32	131.313
4242.27	131.843
4244.21	138.156
4246.15	147.684
4248.08	164.399
4250.02	194.489
4251.95	250.378
4253.88	360.777
4255.81	417.204
4257.74	314.842
4259.65	223.871
4261.62	180.838
4263.59	152.91
4265.56	144.049
4267.53	138.071
4269.49	130.685
4271.46	127.908
4273.42	126.729
4275.38	120.682
4277.33	120.076
4279.29	123.282
4281.24	121.248
4283.19	120.382
4285.14	117.734
4287.08	120.329
4289.03	117.944
4290.97	115.7
4292.91	124.122
4294.85	117.123
4296.78	119.02
4298.71	115.071
4300.65	119.645
4302.57	115.786
4304.5	115.36
4306.43	117.313
4308.35	117.243
4310.27	117.707
4312.19	113.533
4314.1	114.019
4316.02	115.641
4317.93	118.223
4319.84	115.443
4321.75	121.802
4323.65	116.466
4325.56	113.322
4327.46	119.767
4329.36	111.787
4331.26	117.556
4333.15	113.569
4335.04	113.305
4336.94	110.522
4338.82	118.036
4340.71	114.101
4342.6	114.405
4344.48	112.864
4346.36	115.254
4348.24	107.872
4350.11	114.067
4351.99	113.463
4353.86	111.416
4355.73	107.991
4357.6	112.165
4359.46	113.917
4361.33	114.053
4363.19	113.486
4365.05	108.24
4366.9	112.459
4368.76	113.072
4370.61	109.893
4372.46	109.13
4374.31	110.061
4376.16	108.707
4377.93	108.474
4379.83	106.849
4381.72	114.901
4383.61	103.346
4385.5	104.815
4387.38	110.486
4389.27	107.242
4391.15	106.664
4393.03	110.261
4394.91	108.176
4396.78	107.956
4398.65	109.883
4400.53	111.683
4402.4	109.696
4404.26	110.04
4406.13	111.841
4407.99	115.242
4409.85	105.712
4411.71	113.061
4413.57	114.367
4415.42	106.951
4417.28	113.122
4419.13	111.984
4420.98	110.937
4422.82	111.037
4424.67	110.781
4426.51	113.371
4428.35	107.968
4430.19	111.82
4432.03	108.129
4433.86	108.932
4435.69	108.665
4437.52	110.032
4439.35	106.944
4441.18	110.02
4443	110.834
4444.82	111.738
4446.64	105.838
4448.46	101.397
4450.28	108.633
4452.09	107.791
4453.9	108.354
4455.71	107.961
4457.52	108.867
4459.33	107.39
4461.13	109.842
4462.93	106.555
4464.73	110.274
4466.53	103.914
4468.32	107.653
4470.12	103.525
4471.91	107.571
4473.7	110.887
4475.49	103.148
4477.27	107.243
4479.05	104.009
4480.84	106.725
4482.62	104.281
4484.39	105.124
4486.17	107.121
4487.94	102.566
4489.71	104.945
4491.48	105.222
4493.29	107.724
4495.11	105.067
4496.92	104.629
4498.74	106.036
4499.94	112.631