File: 58GPa.txt
#Acq. time (s)=	10
#Accumulations=	1
#Range (cm-¹)=	1300...1700
#Windows=	2
#Autofocus=	Off
#AutoExposure=	Off
#Spike filter=	Single accum. (Size=3)
#Delay time (s)=	0.1
#Binning=	1
#Readout mode=	Signal
#DeNoise=	Standard
#ICS correction=	On
#Dark correction=	Off
#Inst. Process=	Off
#Instrument=	LabRAM HR Evol
#Detector=	Synapse
#Objective=	x20SLWD
#Grating=	1800 gr/mm
#ND Filter=	100%
#Laser (nm)=	633
#Hole=	150.001
#Range=	Visible
#Collection=	Microscope
#StageXY=	Marzhauser
#StageZ=	Marzhauser
#X (µm)=	0
#Y (µm)=	0
#Z (µm)=	0
#Project=	20190124
#Sample=	1-2
#Site=
#Title=	D_127
#Remark=
#Date=	19.05.2019 20:22
#Acquired=	19.05.2019 20:22:25
1300.13	69.3029
1300.68	68.9863
1301.23	69.2997
1301.78	69.7575
1302.32	70.7679
1302.87	71.7982
1303.42	72.8403
1303.97	73.9452
1304.52	74.5125
1305.07	74.9248
1305.61	75.3028
1306.16	75.5711
1306.71	75.9464
1307.26	76.406
1307.8	76.974
1308.35	77.9474
1308.9	79.0198
1309.45	79.9969
1310	81.016
1310.54	82.1459
1311.09	83.2796
1311.64	84.4944
1312.19	85.8056
1312.73	87.2258
1313.28	88.8016
1313.83	90.6219
1314.37	92.5997
1314.92	94.7768
1315.47	97.2013
1316.01	99.7745
1316.56	102.57
1317.11	105.617
1317.65	108.953
1318.2	112.655
1318.75	116.693
1319.29	120.978
1319.84	125.775
1320.39	130.999
1320.93	136.807
1321.48	143.418
1322.02	151.022
1322.57	159.401
1323.11	169.047
1323.66	180.329
1324.21	194.221
1324.75	210.609
1325.3	231.099
1325.84	254.948
1326.39	285.492
1326.93	325.846
1327.48	376.037
1328.02	444.406
1328.57	530.721
1329.11	647.906
1329.66	827.133
1330.2	1113.08
1330.75	1521.53
1331.29	2185.33
1331.84	3128.65
1332.38	4262.18
1332.93	5156.54
1333.47	5445.74
1334.01	5235.26
1334.56	4799.9
1335.1	4340.37
1335.65	3983.14
1336.19	3711.84
1336.73	3467.12
1337.28	3291.73
1337.82	3063.54
1338.36	2878.78
1338.91	2703.53
1339.45	2544.2
1340	2401.84
1340.54	2276.22
1341.08	2163.67
1341.63	2062.58
1342.17	1970.69
1342.71	1888.84
1343.26	1815.28
1343.8	1748.03
1344.34	1687.02
1344.88	1638.51
1345.43	1598.91
1345.97	1568.12
1346.51	1538.19
1347.05	1515.52
1347.6	1498.69
1348.14	1483.92
1348.68	1469.55
1349.22	1466.92
1349.77	1474.3
1350.31	1487.22
1350.85	1505.22
1351.39	1511.52
1351.93	1461.22
1352.48	1389.33
1353.02	1349.57
1353.56	1333.75
1354.1	1341.4
1354.64	1368.96
1355.18	1376.29
1355.72	1388.85
1356.26	1400.19
1356.81	1428.42
1357.35	1468.78
1357.89	1479.88
1358.43	1387.45
1358.97	1203.65
1359.51	958.757
1360.05	691.922
1360.59	517.534
1361.13	391.86
1361.67	311.397
1362.21	255.996
1362.75	215.37
1363.29	181.651
1363.83	169.035
1364.37	151.43
1364.91	138.714
1365.45	129.278
1365.99	117.794
1366.53	108.896
1367.07	101.738
1367.61	96.8177
1368.15	93.1067
1368.69	90.2387
1369.23	86.1513
1369.77	83.9504
1370.31	82.2539
1370.85	80.6639
1371.39	78.0166
1371.93	75.4366
1372.47	73.5842
1373.01	72.5894
1373.55	72.4927
1374.08	73.7963
1374.62	73.6038
1375.16	72.7112
1375.7	71.4368
1376.24	69.9559
1376.78	67.8188
1377.31	66.6739
1377.85	65.8999
1378.39	65.0331
1378.93	64.4232
1379.47	64.3887
1380.01	64.3726
1380.54	64.5693
1381.08	64.566
1381.62	64.2829
1382.16	63.7934
1382.69	63.2677
1383.23	62.8498
1383.77	61.8027
1384.31	61.2925
1384.84	61.5133
1385.38	61.6891
1385.92	62.1025
1386.46	62.2056
1386.99	61.8102
1387.53	60.8253
1388.07	59.565
1388.6	58.7406
1389.14	58.3424
1389.68	58.2883
1390.21	58.6185
1390.75	59.2196
1391.29	59.5832
1391.82	59.6149
1392.36	59.2152
1392.9	58.5722
1393.43	57.9004
1393.97	57.2606
1394.5	56.6822
1395.04	56.2006
1395.58	55.8534
1396.11	55.6438
1396.65	55.7565
1397.18	56.1581
1397.72	56.8755
1398.25	57.6702
1398.79	58.4911
1399.32	59.1206
1399.86	58.5639
1400.39	57.6679
1400.93	56.2912
1401.46	54.7373
1402	55.3484
1402.53	56.6361
1403.07	56.9268
1403.6	56.1455
1404.14	55.4587
1404.67	55.5983
1405.21	56.0869
1405.74	56.3505
1406.28	56.6085
1406.81	57.0462
1407.34	57.5379
1407.88	57.6448
1408.41	57.2167
1408.95	56.5779
1409.48	56.1117
1410.01	55.5477
1410.55	54.879
1411.08	54.4855
1411.62	54.2075
1412.15	54.0055
1412.68	53.8511
1413.22	53.7244
1413.75	53.7177
1414.28	53.7508
1414.82	53.8187
1415.35	53.908
1415.88	53.9905
1416.42	54.06
1416.95	54.1387
1417.48	54.2141
1418.01	54.283
1418.55	54.3372
1419.08	54.44
1419.61	54.4026
1420.14	54.3339
1420.68	54.2238
1421.21	54.0395
1421.74	53.7521
1422.27	53.5694
1422.81	53.5514
1423.34	53.5663
1423.87	54.3333
1424.4	54.2903
1424.93	54.1757
1425.46	53.9828
1426	53.4391
1426.53	53.0712
1427.06	52.77
1427.59	52.8422
1428.12	52.653
1428.65	52.4775
1429.18	52.3026
1429.72	52.1447
1430.25	52.0282
1430.78	51.7227
1431.31	51.998
1431.84	52.3946
1432.37	53.143
1432.9	53.7399
1433.43	54.1939
1433.96	54.4262
1434.49	54.3166
1435.02	54.1827
1435.55	53.9837
1436.08	53.7409
1436.61	53.4823
1437.14	53.227
1437.67	52.9785
1438.2	52.7787
1438.73	52.579
1439.26	52.4705
1439.79	52.3684
1440.32	52.3431
1440.85	52.3965
1441.38	52.5708
1441.91	52.9179
1442.44	53.2667
1442.97	53.6442
1443.5	53.9897
1444.03	54.2188
1444.56	53.6136
1445.09	52.8749
1445.61	52.0387
1446.14	51.3165
1446.67	50.6668
1447.2	50.3778
1447.73	50.5827
1448.26	50.9429
1448.79	51.34
1449.32	51.8054
1449.84	52.1461
1450.37	52.555
1450.9	52.3782
1451.43	52.0832
1451.96	51.7781
1452.48	51.3576
1453.01	51.0576
1453.54	50.7735
1454.07	50.6579
1454.6	50.8455
1455.12	50.9895
1455.65	51.3417
1456.18	51.6835
1456.71	52.0339
1457.23	52.3917
1457.76	52.7483
1458.29	53.0955
1458.81	53.3465
1459.34	53.3628
1459.87	53.3259
1460.4	53.1082
1460.92	52.9631
1461.45	52.4922
1461.98	51.935
1462.5	51.3534
1463.03	50.8143
1463.55	50.5131
1464.08	50.6626
1464.61	51.1678
1465.13	51.872
1465.66	52.4913
1466.19	53.0075
1466.71	53.4138
1467.24	53.3998
1467.76	53.451
1468.29	53.3688
1468.82	52.9787
1469.34	52.5388
1469.87	52.0833
1470.39	51.6109
1470.92	51.1402
1471.44	50.6947
1471.97	50.309
1472.49	50.0835
1473.02	50.0107
1473.54	50.5285
1474.07	51.0514
1474.59	51.7364
1475.12	52.547
1475.64	52.6222
1476.17	52.0932
1476.69	51.5161
1477.22	50.9468
1477.74	50.4218
1478.27	50.19
1478.79	49.9847
1479.32	49.8281
1479.84	49.627
1480.36	49.7306
1480.89	49.9549
1481.41	50.2634
1481.93	50.6609
1482.46	51.155
1482.98	51.3808
1483.51	51.2581
1484.03	51.1732
1484.55	51.1569
1485.08	51.1777
1485.6	51.2301
1486.12	51.3172
1486.65	51.4933
1487.17	51.6272
1487.69	51.7278
1488.22	51.8158
1488.74	51.9002
1489.26	52.0247
1489.78	52.0681
1490.31	52.1392
1490.83	52.1203
1491.35	52.0533
1491.88	51.9387
1492.4	51.7753
1492.92	51.5336
1493.44	51.2864
1493.96	51.0639
1494.49	50.8525
1495.01	50.6576
1495.53	50.4721
1496.05	50.2869
1496.57	50.1773
1497.1	50.081
1497.62	50.0144
1498.14	49.9873
1498.66	50.0074
1499.18	50.069
1499.7	50.2155
1500.23	50.3443
1500.75	50.4928
1501.27	50.6596
1501.79	50.8198
1502.31	50.9643
1502.83	51.1027
1503.35	51.2577
1503.87	51.3884
1504.39	51.5763
1504.91	51.9122
1505.44	52.2402
1505.96	52.5316
1506.48	52.769
1507	52.763
1507.52	51.6149
1508.04	50.2626
1508.56	48.8626
1509.08	47.802
1509.6	48.1689
1510.12	49.1519
1510.64	50.3186
1511.16	51.2502
1511.68	51.7359
1512.2	51.8461
1512.72	51.8364
1513.24	51.5808
1513.76	51.2687
1514.27	50.8747
1514.79	50.5694
1515.31	50.2195
1515.83	50.3255
1516.35	50.4511
1516.87	50.6732
1517.39	50.9384
1517.91	51.241
1518.43	51.4762
1518.95	51.5303
1519.46	51.5673
1519.98	51.4196
1520.5	51.2561
1521.02	51.0366
1521.54	50.8344
1522.06	50.6245
1522.58	50.4065
1523.09	50.194
1523.61	49.9938
1524.13	49.8136
1524.65	49.6035
1525.17	49.4816
1525.68	49.3846
1526.2	49.6433
1526.72	49.8322
1527.24	50.0627
1527.75	50.3512
1528.27	50.642
1528.79	50.9636
1529.31	51.2902
1529.82	51.575
1530.34	51.5593
1530.86	51.4607
1531.37	51.0393
1531.89	50.7736
1532.41	50.562
1532.92	50.4059
1533.44	50.284
1533.96	50.3688
1534.47	50.408
1534.99	50.4277
1535.51	50.4354
1536.02	50.4965
1536.54	50.573
1537.06	50.5906
1537.57	50.7404
1538.09	50.8979
1538.6	51.0599
1539.12	51.2118
1539.64	51.3535
1540.15	51.511
1540.67	51.6218
1541.18	51.6525
1541.7	51.5848
1542.21	51.4549
1542.73	51.2578
1543.25	50.6934
1543.76	50.5642
1544.28	50.515
1544.79	50.5504
1545.31	51.0057
1545.82	51.2316
1546.34	51.4368
1546.85	51.5652
1547.37	51.6219
1547.88	51.4596
1548.39	51.3788
1548.91	51.35
1549.42	51.443
1549.94	51.3923
1550.45	51.323
1550.97	51.2727
1551.48	51.2496
1552	51.235
1552.51	51.3086
1553.02	51.3549
1553.54	51.4134
1554.05	51.4973
1554.56	51.6018
1555.08	51.6996
1555.59	51.8578
1556.11	51.9362
1556.62	51.9832
1557.13	52.001
1557.65	51.9924
1558.16	52.053
1558.67	52.1103
1559.19	51.935
1559.7	51.6659
1560.21	51.4011
1560.72	51.1498
1561.24	50.9451
1561.75	50.7953
1562.26	50.6819
1562.78	50.6987
1563.29	50.7284
1563.8	50.781
1564.31	50.8606
1564.82	50.9745
1565.34	51.1201
1565.85	51.3123
1566.36	51.5286
1566.87	51.7022
1567.39	51.8221
1567.9	51.8403
1568.41	51.8247
1568.92	51.7656
1569.43	51.5384
1569.94	51.4158
1570.46	51.2272
1570.93	51.4765
1571.45	51.7945
1571.97	52.6271
1572.49	53.2579
1573.01	53.7564
1573.53	54.1244
1574.05	54.0916
1574.57	53.5551
1575.09	52.9395
1575.61	52.2632
1576.13	51.5979
1576.64	50.9644
1577.16	50.3488
1577.68	50.1234
1578.2	50.04
1578.72	50.0985
1579.24	50.2563
1579.76	50.499
1580.28	50.8916
1580.8	51.3117
1581.31	51.7395
1581.83	52.1566
1582.35	52.552
1582.87	52.9065
1583.39	53.0895
1583.91	53.2954
1584.42	52.8961
1584.94	52.3181
1585.46	51.7184
1585.98	51.0816
1586.5	50.5788
1587.01	50.1878
1587.53	50.1823
1588.05	50.0914
1588.57	50.2047
1589.08	50.3863
1589.6	50.626
1590.12	50.8889
1590.64	51.1648
1591.15	51.4445
1591.67	51.7266
1592.19	52.0318
1592.7	52.2906
1593.22	52.5179
1593.74	52.839
1594.26	52.7801
1594.77	52.711
1595.29	52.5495
1595.81	52.2717
1596.32	52.0219
1596.84	51.7578
1597.36	51.4942
1597.87	51.2446
1598.39	51.0217
1598.9	50.844
1599.42	50.7241
1599.94	50.7921
1600.45	50.835
1600.97	50.9839
1601.48	51.12
1602	51.2864
1602.52	51.4746
1603.03	51.6756
1603.55	51.881
1604.06	52.0779
1604.58	52.2508
1605.09	52.3819
1605.61	52.4647
1606.12	52.4992
1606.64	52.491
1607.15	52.4472
1607.67	52.3721
1608.18	52.273
1608.7	52.1547
1609.21	52.0221
1609.73	51.8815
1610.24	51.7413
1610.76	51.6108
1611.27	51.5022
1611.79	51.4221
1612.3	51.3738
1612.81	51.3923
1613.33	51.3683
1613.84	51.3471
1614.36	51.3052
1614.87	51.2387
1615.38	51.1607
1615.9	50.9988
1616.41	51.0954
1616.93	51.2844
1617.44	51.5035
1617.95	52.2079
1618.47	52.1737
1618.98	52.0621
1619.49	51.4857
1620.01	51.0577
1620.52	50.9854
1621.03	51.1028
1621.55	51.255
1622.06	51.4575
1622.57	51.6439
1623.09	51.5361
1623.6	51.3798
1624.11	51.1785
1624.62	50.8954
1625.14	50.5579
1625.65	50.2787
1626.16	50.05
1626.67	49.8186
1627.19	49.6919
1627.7	49.695
1628.21	49.8274
1628.72	50.0126
1629.23	50.2376
1629.75	50.4931
1630.26	50.7295
1630.77	50.9892
1631.28	51.003
1631.79	50.9725
1632.3	50.6513
1632.82	50.3133
1633.33	50.0799
1633.84	49.8623
1634.35	49.9681
1634.86	50.3705
1635.37	50.7993
1635.89	51.2241
1636.4	51.5772
1636.91	51.8415
1637.42	52.0378
1637.93	51.8434
1638.44	51.3296
1638.95	50.7142
1639.46	50.1133
1639.97	49.581
1640.48	49.1103
1640.99	49.8661
1641.5	50.6948
1642.01	51.6322
1642.52	52.4683
1643.03	52.9063
1643.54	52.1736
1644.05	51.5185
1644.56	50.5241
1645.07	50.2756
1645.58	50.4374
1646.09	50.6214
1646.6	50.8173
1647.11	50.9978
1647.62	51.1858
1648.13	51.3201
1648.64	51.4482
1649.15	51.569
1649.66	51.512
1650.17	51.4213
1650.68	51.3007
1651.19	51.1499
1651.69	50.9881
1652.2	50.83
1652.71	50.687
1653.22	50.459
1653.73	50.3986
1654.24	50.3903
1654.75	50.4065
1655.26	50.468
1655.76	50.5678
1656.27	50.7029
1656.78	50.8701
1657.29	51.1099
1657.8	51.3081
1658.31	51.555
1658.81	51.6367
1659.32	51.6909
1659.83	51.6917
1660.34	51.5923
1660.84	51.3044
1661.35	51.0726
1661.86	50.9895
1662.37	50.916
1662.87	50.8554
1663.38	50.8064
1663.89	50.7819
1664.4	50.9633
1664.9	51.0074
1665.41	51.1187
1665.92	50.9166
1666.42	50.6698
1666.93	50.3919
1667.44	49.9326
1667.94	49.5448
1668.45	49.1863
1668.96	48.8635
1669.46	48.622
1669.97	48.4796
1670.48	48.8774
1670.98	49.2538
1671.49	49.6737
1672	50.0949
1672.5	50.48
1673.01	50.8549
1673.51	50.9242
1674.02	50.5101
1674.53	50.1828
1675.03	49.8304
1675.54	49.5004
1676.04	49.1773
1676.55	48.9183
1677.05	48.7654
1677.56	49.0954
1678.06	49.4651
1678.57	49.9085
1679.08	50.3458
1679.58	50.7541
1680.09	51.0767
1680.59	50.8543
1681.09	50.3712
1681.6	49.63
1682.11	48.7605
1682.61	49.5999
1683.11	50.1873
1683.62	50.6642
1684.12	51.0651
1684.63	51.3864
1685.13	51.5257
1685.64	51.2419
1686.14	51.0025
1686.65	50.8659
1687.15	50.5705
1687.65	49.9009
1688.16	49.5168
1688.66	49.1753
1689.16	48.9478
1689.67	49.0227
1690.17	49.1079
1690.68	49.5428
1691.18	50.3265
1691.68	50.9481
1692.19	51.5075
1692.69	52.0514
1693.19	52.4409
1693.7	52.2642
1694.2	51.6723
1694.7	50.8582
1695.2	50.1474
1695.71	49.6278
1696.21	48.9167
1696.71	48.4548
1697.22	48.2838
1697.72	48.4865
1698.22	48.6328
1698.72	49.2805
1699.23	50.3185
1699.73	52.6163
1699.98	54.2848