File: 64.7GPa.txt
#Acq. time (s)=	10
#Accumulations=	1
#Range (cm-¹)=	1300...1700
#Windows=	2
#Autofocus=	Off
#AutoExposure=	Off
#Spike filter=	Single accum. (Size=3)
#Delay time (s)=	0.1
#Binning=	1
#Readout mode=	Signal
#DeNoise=	Standard
#ICS correction=	On
#Dark correction=	Off
#Inst. Process=	Off
#Instrument=	LabRAM HR Evol
#Detector=	Synapse
#Objective=	x20SLWD
#Grating=	1800 gr/mm
#ND Filter=	100%
#Laser (nm)=	633
#Hole=	150.001
#Range=	Visible
#Collection=	Microscope
#StageXY=	Marzhauser
#StageZ=	Marzhauser
#X (µm)=	0
#Y (µm)=	0
#Z (µm)=	0
#Project=	20190124
#Sample=	1-2
#Site=
#Title=	D_235
#Remark=
#Date=	19.05.2019 18:11
#Acquired=	19.05.2019 18:11:46
1300.13	49.3045
1300.68	51.3235
1301.23	53.0524
1301.78	54.2994
1302.32	55.2996
1302.87	56.1066
1303.42	56.2274
1303.97	56.2547
1304.52	56.2212
1305.07	56.1526
1305.61	56.0428
1306.16	55.909
1306.71	56.2896
1307.26	56.9281
1307.8	57.6378
1308.35	58.3723
1308.9	59.0866
1309.45	59.649
1310	59.6171
1310.54	59.513
1311.09	59.4318
1311.64	59.3481
1312.19	60.2603
1312.73	61.5547
1313.28	63.1102
1313.83	64.7261
1314.37	66.3987
1314.92	67.7005
1315.47	68.6951
1316.01	69.8061
1316.56	71.0662
1317.11	72.5189
1317.65	74.2038
1318.2	76.3087
1318.75	78.7471
1319.29	81.5284
1319.84	84.6113
1320.39	88.0175
1320.93	91.7593
1321.48	95.8163
1322.02	100.218
1322.57	104.981
1323.11	110.115
1323.66	115.819
1324.21	124.289
1324.75	134.967
1325.3	146.482
1325.84	159.543
1326.39	176.553
1326.93	197.858
1327.48	224.591
1328.02	262.323
1328.57	312.842
1329.11	375.379
1329.66	471.225
1330.2	626.203
1330.75	866.514
1331.29	1230.05
1331.84	1748.36
1332.38	2444.05
1332.93	2991.44
1333.47	3200.25
1334.01	3077.01
1334.56	2786.82
1335.1	2504.91
1335.65	2235.95
1336.19	1997.93
1336.73	1811.71
1337.28	1662.9
1337.82	1530.72
1338.36	1414.39
1338.91	1312.9
1339.45	1224.48
1340	1148.16
1340.54	1081.55
1341.08	1017.83
1341.63	966.254
1342.17	917.836
1342.71	872.391
1343.26	829.881
1343.8	790.274
1344.34	753.546
1344.88	719.681
1345.43	688.674
1345.97	660.522
1346.51	635.206
1347.05	612.708
1347.6	592.844
1348.14	574.265
1348.68	557.222
1349.22	541.637
1349.77	527.333
1350.31	512.089
1350.85	495.934
1351.39	479.945
1351.93	465.613
1352.48	453.716
1353.02	442.834
1353.56	432.033
1354.1	422.366
1354.64	411.857
1355.18	402.715
1355.72	391.974
1356.26	382.122
1356.81	374.181
1357.35	368.351
1357.89	363.16
1358.43	355.18
1358.97	347.995
1359.51	340.785
1360.05	333.318
1360.59	326.572
1361.13	321.003
1361.67	313.419
1362.21	305.986
1362.75	299.273
1363.29	293.644
1363.83	289.032
1364.37	285.228
1364.91	282.18
1365.45	279.899
1365.99	278.3
1366.53	274.827
1367.07	269.494
1367.61	266.879
1368.15	263.401
1368.69	260.139
1369.23	256.739
1369.77	252.743
1370.31	249.031
1370.85	246.188
1371.39	242.902
1371.93	239.183
1372.47	234.984
1373.01	231.119
1373.55	226.595
1374.08	224.946
1374.62	224.938
1375.16	225.626
1375.7	224.481
1376.24	221.449
1376.78	214.932
1377.31	211.643
1377.85	212.624
1378.39	219.394
1378.93	209.225
1379.47	203.069
1380.01	203.105
1380.54	202.776
1381.08	203.293
1381.62	202.692
1382.16	201.342
1382.69	199.841
1383.23	196.921
1383.77	193.543
1384.31	190.359
1384.84	187.535
1385.38	185.399
1385.92	184.332
1386.46	183.574
1386.99	182.907
1387.53	182.235
1388.07	181.221
1388.6	180.081
1389.14	178.7
1389.68	176.92
1390.21	175.108
1390.75	173.34
1391.29	171.682
1391.82	170.367
1392.36	169.451
1392.9	168.77
1393.43	168.354
1393.97	168.18
1394.5	168.255
1395.04	168.669
1395.58	169.13
1396.11	168.497
1396.65	167.29
1397.18	165.158
1397.72	163.012
1398.25	161.496
1398.79	160.53
1399.32	160.019
1399.86	159.605
1400.39	159.195
1400.93	158.524
1401.46	157.19
1402	155.46
1402.53	153.717
1403.07	152.183
1403.6	151.307
1404.14	151.047
1404.67	151.253
1405.21	151.953
1405.74	153.259
1406.28	153.704
1406.81	152.536
1407.34	150.901
1407.88	149.782
1408.41	149.067
1408.95	148.472
1409.48	147.94
1410.01	147.439
1410.55	146.941
1411.08	146.404
1411.62	145.874
1412.15	145.352
1412.68	144.861
1413.22	144.342
1413.75	143.808
1414.28	143.255
1414.82	142.685
1415.35	142.096
1415.88	141.523
1416.42	140.959
1416.95	140.408
1417.48	139.872
1418.01	139.351
1418.55	138.845
1419.08	138.369
1419.61	137.93
1420.14	137.54
1420.68	137.21
1421.21	136.952
1421.74	136.779
1422.27	136.742
1422.81	136.805
1423.34	136.252
1423.87	134.672
1424.4	134.947
1424.93	135.529
1425.46	135.965
1426	135.935
1426.53	135.627
1427.06	135.12
1427.59	134.505
1428.12	134.074
1428.65	134.17
1429.18	134.589
1429.72	134.78
1430.25	134.252
1430.78	132.823
1431.31	130.033
1431.84	128.811
1432.37	128.506
1432.9	128.56
1433.43	128.775
1433.96	128.818
1434.49	128.684
1435.02	126.409
1435.55	126.703
1436.08	127.983
1436.61	129.101
1437.14	128.701
1437.67	128.17
1438.2	127.682
1438.73	127.473
1439.26	127.433
1439.79	127.52
1440.32	127.701
1440.85	127.947
1441.38	128.225
1441.91	128.546
1442.44	129.053
1442.97	129.549
1443.5	129.99
1444.03	130.264
1444.56	130.374
1445.09	129.921
1445.61	128.859
1446.14	127.631
1446.67	126.43
1447.2	125.301
1447.73	124.24
1448.26	124.671
1448.79	125.17
1449.32	125.686
1449.84	126.168
1450.37	126.539
1450.9	126.561
1451.43	126.522
1451.96	126.291
1452.48	125.92
1453.01	125.445
1453.54	124.965
1454.07	124.019
1454.6	122.991
1455.12	121.926
1455.65	120.826
1456.18	119.749
1456.71	118.678
1457.23	117.673
1457.76	116.861
1458.29	116.152
1458.81	115.559
1459.34	115.169
1459.87	114.822
1460.4	114.518
1460.92	114.268
1461.45	114.06
1461.98	113.881
1462.5	113.722
1463.03	113.588
1463.55	113.475
1464.08	113.366
1464.61	113.257
1465.13	113.135
1465.66	112.959
1466.19	112.739
1466.71	112.454
1467.24	112.152
1467.76	111.773
1468.29	111.287
1468.82	110.305
1469.34	108.399
1469.87	104.925
1470.39	100.283
1470.92	94.706
1471.44	87.4633
1471.97	80.2911
1472.49	73.6688
1473.02	67.8977
1473.54	62.8144
1474.07	58.4021
1474.59	54.6655
1475.12	51.5326
1475.64	49.0347
1476.17	47.0436
1476.69	45.7026
1477.22	44.9222
1477.74	44.7175
1478.27	44.7201
1478.79	44.9345
1479.32	45.0847
1479.84	45.1296
1480.36	45.0647
1480.89	44.966
1481.41	44.5786
1481.93	44.0757
1482.46	43.5294
1482.98	43.0548
1483.51	42.6972
1484.03	42.5409
1484.55	43.2676
1485.08	44.2962
1485.6	45.6082
1486.12	47.048
1486.65	45.3609
1487.17	44.7006
1487.69	44.1378
1488.22	43.4
1488.74	42.5267
1489.26	41.6594
1489.78	42.5143
1490.31	42.894
1490.83	43.068
1491.35	42.9851
1491.88	42.8323
1492.4	42.5955
1492.92	42.4906
1493.44	42.0777
1493.96	41.6391
1494.49	41.2334
1495.01	40.9111
1495.53	40.7152
1496.05	40.6805
1496.57	40.7615
1497.1	41.1404
1497.62	41.9778
1498.14	42.9175
1498.66	43.7387
1499.18	44.366
1499.7	43.786
1500.23	42.8143
1500.75	41.3348
1501.27	40.2906
1501.79	41.0183
1502.31	41.706
1502.83	41.8571
1503.35	41.9476
1503.87	41.982
1504.39	41.9747
1504.91	41.952
1505.44	41.9248
1505.96	41.8954
1506.48	41.8631
1507	41.8277
1507.52	41.7912
1508.04	41.7578
1508.56	41.7322
1509.08	41.7175
1509.6	41.7141
1510.12	41.7193
1510.64	41.7289
1511.16	41.7376
1511.68	41.7383
1512.2	41.7251
1512.72	41.6971
1513.24	41.6618
1513.76	41.6155
1514.27	41.5575
1514.79	41.4899
1515.31	41.3945
1515.83	41.3146
1516.35	41.2334
1516.87	41.1547
1517.39	41.0848
1517.91	41.0331
1518.43	41.0114
1518.95	41.0235
1519.46	41.0682
1519.98	41.1307
1520.5	41.1939
1521.02	41.2711
1521.54	41.2188
1522.06	41.1086
1522.58	40.9616
1523.09	40.6515
1523.61	40.5842
1524.13	40.7322
1524.65	42.3904
1525.17	41.4584
1525.68	40.5745
1526.2	39.7158
1526.72	39.5614
1527.24	39.5962
1527.75	39.7349
1528.27	39.8792
1528.79	40.0359
1529.31	40.2164
1529.82	40.4283
1530.34	40.6291
1530.86	40.8187
1531.37	40.9798
1531.89	41.1805
1532.41	41.1496
1532.92	41.062
1533.44	40.9692
1533.96	40.8544
1534.47	40.6947
1534.99	40.5062
1535.51	40.5153
1536.02	40.5538
1536.54	40.6207
1537.06	40.7263
1537.57	41.0846
1538.09	41.3108
1538.6	41.6041
1539.12	41.5002
1539.64	41.3426
1540.15	40.9184
1540.67	40.6148
1541.18	40.2729
1541.7	40.0012
1542.21	39.7739
1542.73	39.5967
1543.25	39.6779
1543.76	39.7543
1544.28	39.9057
1544.79	40.052
1545.31	40.2092
1545.82	40.4035
1546.34	40.5416
1546.85	40.631
1547.37	40.7096
1547.88	40.7755
1548.39	40.6348
1548.91	40.2548
1549.42	39.7438
1549.94	39.3879
1550.45	39.1084
1550.97	39.5732
1551.48	40.3468
1552	41.5465
1552.51	41.8666
1553.02	41.944
1553.54	41.7692
1554.05	41.248
1554.56	40.81
1555.08	40.5028
1555.59	40.259
1556.11	40.3774
1556.62	40.5523
1557.13	40.7157
1557.65	40.9038
1558.16	41.0548
1558.67	41.1485
1559.19	41.202
1559.7	41.2173
1560.21	41.1409
1560.72	41.0792
1561.24	41.0079
1561.75	40.9414
1562.26	40.8007
1562.78	40.7114
1563.29	40.6397
1563.8	40.6037
1564.31	40.6
1564.82	40.6397
1565.34	40.7219
1565.85	40.9218
1566.36	41.1092
1566.87	41.276
1567.39	41.4166
1567.9	41.5295
1568.41	41.6095
1568.92	41.6354
1569.43	41.5848
1569.94	41.5335
1570.46	41.4841
1570.93	41.4221
1571.45	41.3425
1571.97	41.2634
1572.49	41.1797
1573.01	41.0877
1573.53	40.9829
1574.05	40.8697
1574.57	40.754
1575.09	40.6426
1575.61	40.546
1576.13	40.4799
1576.64	40.4469
1577.16	40.448
1577.68	40.4812
1578.2	40.5362
1578.72	40.6013
1579.24	40.6687
1579.76	40.7316
1580.28	40.784
1580.8	40.8201
1581.31	40.8373
1581.83	40.834
1582.35	40.8106
1582.87	40.7691
1583.39	40.7129
1583.91	40.6471
1584.42	40.5774
1584.94	40.5096
1585.46	40.4493
1585.98	40.4025
1586.5	40.3724
1587.01	40.3608
1587.53	40.3673
1588.05	40.3894
1588.57	40.4229
1589.08	40.464
1589.6	40.5081
1590.12	40.5507
1590.64	40.5883
1591.15	40.6185
1591.67	40.6395
1592.19	40.6503
1592.7	40.6514
1593.22	40.6436
1593.74	40.627
1594.26	40.6034
1594.77	40.5752
1595.29	40.5461
1595.81	40.5208
1596.32	40.5058
1596.84	40.5047
1597.36	40.5195
1597.87	40.55
1598.39	40.5942
1598.9	40.6477
1599.42	40.7046
1599.94	40.7587
1600.45	40.8029
1600.97	40.8284
1601.48	40.8424
1602	40.8432
1602.52	40.8321
1603.03	40.812
1603.55	40.785
1604.06	40.7466
1604.58	40.6702
1605.09	40.6596
1605.61	40.6559
1606.12	40.6615
1606.64	40.6789
1607.15	40.7075
1607.67	40.7439
1608.18	40.7818
1608.7	40.8107
1609.21	40.8419
1609.73	40.7949
1610.24	40.7098
1610.76	40.4272
1611.27	39.8736
1611.79	39.373
1612.3	38.9685
1612.81	38.712
1613.33	38.7047
1613.84	39.4835
1614.36	39.9925
1614.87	40.4208
1615.38	40.4846
1615.9	40.2785
1616.41	39.9551
1616.93	39.8529
1617.44	39.8084
1617.95	39.8159
1618.47	39.9477
1618.98	40.0724
1619.49	40.1991
1620.01	40.2665
1620.52	40.2977
1621.03	40.2912
1621.55	40.2479
1622.06	40.1744
1622.57	40.078
1623.09	39.9639
1623.6	39.837
1624.11	39.6776
1624.62	39.5493
1625.14	39.4327
1625.65	39.3352
1626.16	39.2637
1626.67	39.2236
1627.19	39.2322
1627.7	39.2901
1628.21	39.392
1628.72	39.5294
1629.23	39.6919
1629.75	39.8703
1630.26	40.0531
1630.77	40.2276
1631.28	40.3813
1631.79	40.5025
1632.3	40.583
1632.82	40.6184
1633.33	40.6119
1633.84	40.5698
1634.35	40.5007
1634.86	40.4175
1635.37	40.3323
1635.89	40.2568
1636.4	40.2015
1636.91	40.1749
1637.42	40.1789
1637.93	40.2125
1638.44	40.2726
1638.95	40.3539
1639.46	40.4478
1639.97	40.5495
1640.48	40.6524
1640.99	40.7504
1641.5	40.8378
1642.01	40.8966
1642.52	40.9531
1643.03	40.9916
1643.54	41.0111
1644.05	41.0103
1644.56	40.9892
1645.07	40.9483
1645.58	40.8908
1646.09	40.817
1646.6	40.7246
1647.11	40.6078
1647.62	40.4558
1648.13	40.2436
1648.64	39.9513
1649.15	39.5598
1649.66	38.9206
1650.17	38.4074
1650.68	38.1517
1651.19	39.5742
1651.69	40.4826
1652.2	41.6357
1652.71	41.3822
1653.22	41.4696
1653.73	41.3006
1654.24	40.787
1654.75	40.1414
1655.26	39.7136
1655.76	39.3869
1656.27	39.5571
1656.78	39.7412
1657.29	39.8635
1657.8	40.0695
1658.31	40.0124
1658.81	39.906
1659.32	39.7605
1659.83	39.6019
1660.34	39.4557
1660.84	39.3008
1661.35	39.2626
1661.86	39.292
1662.37	39.3603
1662.87	39.5928
1663.38	39.8586
1663.89	40.2604
1664.4	40.7328
1664.9	41.0466
1665.41	41.1192
1665.92	41.1388
1666.42	40.8407
1666.93	40.6548
1667.44	40.3503
1667.94	40.2765
1668.45	40.2446
1668.96	40.252
1669.46	40.3563
1669.97	40.4989
1670.48	40.6329
1670.98	40.757
1671.49	40.869
1672	40.9636
1672.5	41.0362
1673.01	41.0824
1673.51	41.0988
1674.02	41.0841
1674.53	41.0379
1675.03	40.9628
1675.54	40.8635
1676.04	40.7418
1676.55	40.5943
1677.05	40.4391
1677.56	40.2729
1678.06	40.1005
1678.57	39.9297
1679.08	39.7691
1679.58	39.6275
1680.09	39.5222
1680.59	39.4688
1681.09	39.4793
1681.6	39.5492
1682.11	39.6745
1682.61	39.8542
1683.11	40.059
1683.62	40.3735
1684.12	40.7024
1684.63	41.0225
1685.13	41.3013
1685.64	41.4909
1686.14	41.5213
1686.65	40.2523
1687.15	39.2898
1687.65	38.4785
1688.16	38.4813
1688.66	39.0014
1689.16	40.1466
1689.67	40.3232
1690.17	40.2415
1690.68	40.3821
1691.18	40.2027
1691.68	39.7943
1692.19	39.254
1692.69	38.9025
1693.19	38.9694
1693.7	39.1673
1694.2	39.4629
1694.7	40.0287
1695.2	41.1446
1695.71	40.8978
1696.21	40.044
1696.71	39.2283
1697.22	38.8038
1697.72	38.8582
1698.22	40.3791
1698.72	40.972
1699.23	39.7113
1699.73	39.4518
1699.98	39.0291