File: 85GPa.txt
#Acq. time (s)=	20
#Accumulations=	1
#Range (cm-¹)=	50...4500
#Windows=	24
#Autofocus=	Off
#AutoExposure=	Off
#Spike filter=	Single accum. (Size=3)
#Delay time (s)=	0.1
#Binning=	1
#Readout mode=	Signal
#DeNoise=	Standard
#ICS correction=	On
#Dark correction=	Off
#Inst. Process=	Off
#Instrument=	LabRAM HR Evol
#Detector=	Synapse
#Objective=	x20SLWD
#Grating=	1800 gr/mm
#ND Filter=	100%
#Laser (nm)=	633
#Hole=	150.001
#Range=	Visible
#Collection=	Microscope
#StageXY=	Marzhauser
#StageZ=	Marzhauser
#X (µm)=	0
#Y (µm)=	0
#Z (µm)=	0
#Project=	20190124
#Sample=	1-2
#Site=
#Title=	D_17
#Remark=
#Date=	18.05.2019 21:02
#Acquired=	18.05.2019 21:02:57
#Edit:Spike=	18.05.2019 21:08:02
#Edit:Spike=	18.05.2019 21:08:04
#Edit:Spike=	18.05.2019 21:08:06
#Edit:Spike=	18.05.2019 21:08:08
#Edit:Spike=	18.05.2019 21:08:09
#Edit:Spike=	18.05.2019 21:08:10
#Edit:Spike=	18.05.2019 21:08:11
#Edit:Spike=	18.05.2019 21:09:14
#Edit:Spike=	18.05.2019 21:09:15
#Edit:Spike=	18.05.2019 21:09:16
#Edit:Spike=	18.05.2019 21:09:17
#Edit:Spike=	18.05.2019 21:09:18
#Edit:Spike=	18.05.2019 21:10:03
#Edit:Spike=	18.05.2019 21:10:04
#Edit:Spike=	18.05.2019 21:11:22
52.2641	99.4481
57.3937	51.4231
62.5185	36.3455
67.6384	42.4463
72.752	47.4947
77.8607	56.7253
82.9631	95.6925
88.0622	129.634
93.1535	152.342
98.2415	163.079
103.323	162.849
108.399	164.768
113.471	162.912
118.536	160.212
123.596	162.332
128.651	156.23
133.701	153.662
138.746	150.109
143.785	144.269
148.818	145.102
153.848	143.22
158.869	140.638
163.888	138.214
168.901	138.942
173.908	135.405
178.91	135.067
183.907	134.776
188.897	132.926
193.883	135.267
198.865	137.523
203.84	132.764
208.81	132.05
213.775	132.729
218.735	135.482
223.69	135.231
228.639	139.606
233.582	139.683
238.521	143.018
243.454	143.292
248.383	140.273
253.306	142.139
258.223	146.357
263.135	147.848
268.043	146.386
272.945	148.984
277.842	150.335
282.733	152.408
287.62	153.776
292.5	158.454
297.376	159.067
302.246	158.461
307.112	159.337
311.973	158.415
316.828	162.471
321.677	158.844
326.521	161.261
331.362	159.893
336.196	165.191
341.024	163.718
345.849	166.535
350.667	166.447
355.48	161.963
360.289	165.083
365.092	164.341
369.891	166.003
374.683	165.805
379.471	165.303
384.254	166.407
389.032	163.975
393.797	165.831
398.634	164.477
403.465	166.052
408.293	162.552
413.114	168.816
417.932	164.732
422.744	170.787
427.55	167.877
432.352	165.116
437.149	167.256
441.94	167.269
446.727	167.8
451.51	169.966
456.286	167.576
461.058	165.985
465.825	168.658
470.587	170.394
475.343	167.409
480.095	168.571
484.842	170.466
489.583	169.081
494.319	171.573
499.052	167.355
503.779	170.491
508.5	171.215
513.217	172.212
517.929	172.012
522.635	170.581
527.338	177.663
532.035	176.311
536.727	175.841
541.414	176.25
546.097	179.821
550.773	176.332
555.446	181.725
560.113	178.366
564.775	180.314
569.433	181.474
574.086	176.877
578.733	177.83
583.375	181.569
588.014	174.515
592.646	179.558
597.274	176.284
601.896	175.175
606.515	179.121
611.128	178.184
615.737	176.882
620.34	177.916
624.938	180.029
629.531	173.531
634.12	180.453
638.704	176.57
643.284	179.969
647.857	178.843
652.426	176.957
656.99	177.964
661.55	178.484
666.105	179.293
670.654	176.925
675.198	178.959
679.739	180.306
684.185	175.971
688.785	182.358
693.377	181.526
697.967	181.498
702.551	178.65
707.131	181.113
711.705	183.729
716.275	183.095
720.84	182.558
725.401	184.691
729.956	186.89
734.508	184.941
739.053	185.899
743.595	183.745
748.132	181.337
752.663	186.279
757.191	186.674
761.714	189.282
766.232	187.728
770.745	189.784
775.253	185.28
779.757	186.156
784.256	185.794
788.751	187.434
793.24	189.081
797.725	190.433
802.205	188.897
806.681	188.67
811.151	192.995
815.618	188.94
820.079	188.311
824.536	185.017
828.988	187.269
833.436	189.52
837.878	191.275
842.316	189.652
846.75	190.435
851.179	187.704
855.603	187.811
860.022	189.799
864.438	191.283
868.848	191.927
873.252	192.623
877.653	192.979
882.049	191.643
886.44	194.484
890.828	190.033
895.211	190.461
899.588	189.282
903.961	187.393
908.329	191.292
912.693	189.278
917.053	192.655
921.406	188.507
925.757	191.101
930.101	189.236
934.442	187.465
938.778	193.445
943.11	194.652
947.437	191.801
951.759	192.913
955.954	191.558
960.333	194.581
964.708	196.557
969.078	192.798
973.444	193.589
977.807	193.614
982.163	193.458
986.516	194.858
990.864	193.583
995.207	194.844
999.547	193.424
1003.88	193.113
1008.21	196.345
1012.54	193.844
1016.86	192.309
1021.17	194.821
1025.49	194.135
1029.79	197.634
1034.1	195.963
1038.4	196.823
1042.69	196.327
1046.98	199.274
1051.27	195.8
1055.55	199.99
1059.82	196.144
1064.09	200.18
1068.36	193.611
1072.63	197.944
1076.88	202.719
1081.14	195.275
1085.39	201.272
1089.63	192.491
1093.87	195.909
1098.11	196.619
1102.34	194.813
1106.57	192.671
1110.79	197.038
1115.01	192.903
1119.23	197.828
1123.44	196.89
1127.64	199.09
1131.84	196.578
1136.04	191.747
1140.23	194.603
1144.42	201.913
1148.6	198.118
1152.78	198.373
1156.96	201.157
1161.13	196.036
1165.29	197.993
1169.45	199.096
1173.61	198.993
1177.76	199.028
1181.91	196.829
1186.06	197.065
1190.2	201.527
1194.33	198.202
1198.46	202.387
1202.59	199.143
1206.71	199.675
1210.83	201.364
1214.87	203.658
1219.04	204.154
1223.21	201.649
1227.38	204.039
1231.54	203.251
1235.7	203.892
1239.85	204.608
1244	203.689
1248.15	204.032
1252.29	203.393
1256.42	207.861
1260.56	206.274
1264.68	206.877
1268.81	206.788
1272.92	208.073
1277.04	204.66
1281.15	209.16
1285.26	211.158
1289.36	206.75
1293.46	212.677
1297.55	212.799
1301.64	212.406
1305.73	214.341
1309.81	218.753
1313.88	224.286
1317.96	239.343
1322.03	258.452
1326.09	322.049
1330.15	719.177
1334.21	3185.34
1338.26	2251.89
1342.31	1634.78
1346.35	1328.97
1350.39	1163.49
1354.42	1040.87
1358.45	924.004
1362.48	835.427
1366.5	791.103
1370.52	764.57
1374.53	711.621
1378.54	671.721
1382.55	627.005
1386.55	597.6
1390.55	572.04
1394.54	545.776
1398.53	518.997
1402.51	496.094
1406.49	480.522
1410.47	461.912
1414.44	450.831
1418.41	438.555
1422.37	418.494
1426.33	422.349
1430.29	405.806
1434.24	397.609
1438.19	386.501
1442.13	391.67
1446.07	386.023
1450	391.239
1453.93	389.638
1457.86	388.071
1461.78	395.996
1465.54	409.579
1469.52	421.883
1473.49	436.968
1477.46	446.347
1481.43	470.283
1485.39	482.191
1489.35	464.166
1493.3	450.028
1497.25	488.671
1501.2	471.589
1505.14	390.423
1509.08	342.841
1513.01	264.551
1516.94	234.61
1520.87	216.467
1524.79	207.102
1528.71	206.686
1532.63	202.494
1536.54	205.098
1540.44	202.876
1544.34	204.528
1548.24	203.95
1552.14	206.081
1556.03	204.644
1559.91	201.929
1563.79	202.219
1567.67	204.142
1571.54	201.334
1575.42	202.769
1579.28	201.931
1583.14	201.407
1587	201.118
1590.85	199.727
1594.7	200.478
1598.55	204.134
1602.39	197.838
1606.23	198.917
1610.06	198.331
1613.89	200.516
1617.72	198.586
1621.54	200.285
1625.36	197.443
1629.17	196.617
1632.99	199.035
1636.79	199.296
1640.59	195.807
1644.39	197.89
1648.19	194.794
1651.97	197.537
1655.76	194.731
1659.54	195.984
1663.32	195.388
1667.1	198.32
1670.87	194.98
1674.63	194.721
1678.4	196.652
1682.16	198.796
1685.91	200.209
1689.66	200.685
1693.41	203.239
1697.15	203.077
1700.89	204.664
1704.65	204.117
1708.45	209.241
1712.24	203.259
1716.02	205.85
1719.81	207.567
1723.59	203.007
1727.36	206.83
1731.13	207.325
1734.9	198.49
1738.67	205.498
1742.43	203.009
1746.18	209.014
1749.93	207.01
1753.68	204.243
1757.43	202.887
1761.17	204.664
1764.91	206.106
1768.64	204.752
1772.37	204.927
1776.09	208.136
1779.82	204.583
1783.53	208.495
1787.25	207.372
1790.96	204.498
1794.66	209.536
1798.37	206.674
1802.06	205.122
1805.76	201.596
1809.45	201.643
1813.14	214.616
1816.82	206.69
1820.5	205.669
1824.18	213.57
1827.85	207.579
1831.52	205.559
1835.18	204.802
1838.84	207.183
1842.5	210.551
1846.15	209.416
1849.8	205.629
1853.45	207.288
1857.09	208.636
1860.73	206.832
1864.36	207.57
1867.99	205.414
1871.62	204.67
1875.24	206.276
1878.86	206.334
1882.48	203.932
1886.09	207.984
1889.7	207.213
1893.3	203.939
1896.9	205.182
1900.5	204.135
1904.09	211.783
1907.68	207.44
1911.26	202.82
1914.84	209.1
1918.42	212.686
1922	217.129
1925.57	216.607
1929.13	220.89
1932.57	216.952
1936.19	219.131
1939.81	216.515
1943.42	216.332
1947.03	217.539
1950.64	210.938
1954.24	217.913
1957.84	214.577
1961.44	214.305
1965.03	214.117
1968.62	214.259
1972.21	213.872
1975.79	212.703
1979.36	214.672
1982.94	218.31
1986.51	214.016
1990.08	217.713
1993.64	218.832
1997.2	216.096
2000.75	219.847
2004.31	217.973
2007.85	217.321
2011.4	214.567
2014.94	216.304
2018.48	214.087
2022.01	221.102
2025.54	219.716
2029.07	213.178
2032.59	215.768
2036.11	225.054
2039.63	216.843
2043.14	214.875
2046.65	219.387
2050.15	219.125
2053.65	217.871
2057.15	224.467
2060.64	218.335
2064.13	222.335
2067.62	215.473
2071.1	222.933
2074.58	217.767
2078.06	219.245
2081.53	221.234
2085	217.17
2088.47	217.099
2091.93	219.295
2095.39	214.188
2098.84	218.313
2102.29	219.552
2105.74	223.242
2109.18	218.376
2112.62	221.859
2116.06	215.675
2119.49	224.673
2122.92	218.413
2126.35	219.969
2129.77	222.301
2133.19	224.635
2136.6	229.164
2140.01	224.153
2143.42	229.799
2146.82	231.53
2150.26	230.835
2153.71	229.02
2157.17	236.53
2160.62	232.254
2164.07	237.625
2167.51	233.387
2170.95	232.721
2174.39	234.48
2177.82	234.417
2181.25	235.529
2184.68	237.442
2188.1	232.934
2191.52	233.833
2194.94	233.822
2198.35	233.949
2201.76	233.164
2205.17	233.556
2208.57	231.337
2211.97	231.096
2215.36	237.139
2218.75	232.68
2222.14	238.42
2225.53	234.33
2228.91	241.882
2232.29	237.001
2235.66	237.112
2239.03	238.136
2242.4	230.947
2245.76	236.486
2249.12	243.662
2252.48	239.945
2255.83	240.135
2259.18	243.078
2262.53	241.67
2265.87	237.133
2269.21	240.773
2272.55	241.279
2275.88	240.278
2279.21	243.981
2282.54	244.624
2285.86	244.957
2289.18	242.564
2292.5	246.08
2295.81	248.409
2299.12	247.827
2302.42	245.675
2305.73	241.667
2309.02	244.022
2312.32	249.373
2315.61	248.24
2318.9	249.328
2322.18	250.628
2325.46	251.458
2328.74	247.228
2332.02	249.962
2335.29	254.152
2338.56	256.33
2341.82	256.308
2345.08	259.352
2348.34	261.928
2351.59	262.527
2354.84	261.101
2357.98	263.451
2361.28	264.999
2364.58	264.085
2367.88	261.76
2371.17	265.76
2374.46	267.142
2377.75	262.311
2381.03	275.588
2384.31	269.267
2387.59	266.314
2390.86	270.958
2394.13	271.157
2397.4	264.251
2400.66	266.939
2403.92	275.822
2407.18	272.62
2410.43	271.331
2413.68	269.195
2416.93	269.179
2420.18	271.308
2423.42	276.538
2426.65	274.049
2429.89	272.242
2433.12	272.964
2436.34	277.865
2439.57	276.211
2442.79	275.984
2446	278.541
2449.22	275.578
2452.43	281.908
2455.64	276.257
2458.84	282.65
2462.04	281.101
2465.24	282.741
2468.43	287.592
2471.62	281.923
2474.81	286.865
2477.99	285.434
2481.17	282.461
2484.35	285.694
2487.53	284.286
2490.7	285.78
2493.86	289.895
2497.03	290.219
2500.19	292.925
2503.35	289.619
2506.5	280.019
2509.65	295.543
2512.8	284.652
2515.94	286.198
2519.09	286.369
2522.22	287.125
2525.36	282.158
2528.49	279.013
2531.62	279.3
2534.74	285.809
2537.87	287.182
2540.98	283.225
2544.1	286.98
2547.21	288.024
2550.32	289.48
2553.34	288.977
2556.5	285.514
2559.66	289.021
2562.82	290.844
2565.97	288.308
2569.12	286.121
2572.26	289.45
2575.41	288.457
2578.55	286.002
2581.68	284.407
2584.82	284.72
2587.94	286.156
2591.07	285.319
2594.19	290.865
2597.31	291.001
2600.43	288.264
2603.54	285.624
2606.66	290.584
2609.76	288.423
2612.87	285.793
2615.97	285.765
2619.07	285.896
2622.16	292.788
2625.25	285.869
2628.34	286.738
2631.43	291.348
2634.51	285.694
2637.59	289.635
2640.66	288.15
2643.73	287.532
2646.8	293.83
2649.87	290.567
2652.93	285.942
2655.99	290.138
2659.05	288.434
2662.1	287.014
2665.15	285.638
2668.2	291.642
2671.24	288.095
2674.28	288.838
2677.32	287.345
2680.36	287.955
2683.39	288.94
2686.41	287.719
2689.44	287.172
2692.46	293.273
2695.48	283.706
2698.5	286.83
2701.51	284.59
2704.52	283.126
2707.52	284.366
2710.53	277.129
2713.53	282.718
2716.52	284.631
2719.52	280.233
2722.51	284.928
2725.49	282.064
2728.48	294.401
2731.46	284.82
2734.44	287.483
2737.41	292.439
2740.38	295.252
2743.3	295.119
2746.33	287.115
2749.35	290.967
2752.37	288.32
2755.38	292.706
2758.39	296.128
2761.4	291.117
2764.41	295.742
2767.41	290.49
2770.41	287.274
2773.4	289.613
2776.4	300.14
2779.39	286.912
2782.37	293.528
2785.36	297.241
2788.34	287.074
2791.32	298.945
2794.29	285.443
2797.26	293.573
2800.23	293.001
2803.2	295.023
2806.16	297.579
2809.12	291.906
2812.08	293.12
2815.03	296.173
2817.98	294.57
2820.93	295.273
2823.87	293.672
2826.81	292.977
2829.75	293.679
2832.69	295.071
2835.62	296.959
2838.55	286.053
2841.47	295.779
2844.4	295.328
2847.32	288.406
2850.23	288.284
2853.15	295.831
2856.06	289.951
2858.97	292.101
2861.87	295.582
2864.77	296.272
2867.67	291.314
2870.57	294.77
2873.46	294.821
2876.35	294.351
2879.24	297.6
2882.12	296.196
2885	287.998
2887.88	291.458
2890.75	297.764
2893.63	296.686
2896.5	298.113
2899.36	287.751
2902.22	285.302
2905.08	295.39
2907.94	294.146
2910.79	294.882
2913.64	296.802
2916.49	299.547
2919.34	297.487
2922.19	300.649
2925.09	299.277
2927.98	300.271
2930.88	299.013
2933.76	303.996
2936.65	295.627
2939.53	297.539
2942.41	300.218
2945.29	302.216
2948.16	296.961
2951.03	305.348
2953.9	301.848
2956.76	299.572
2959.62	308.898
2962.48	302.5
2965.33	305.947
2968.19	301.218
2971.04	298.508
2973.88	305.687
2976.73	301.458
2979.57	302.667
2982.41	299.108
2985.24	297.698
2988.07	300.521
2990.9	308.41
2993.73	301.674
2996.55	305.784
2999.37	300.784
3002.19	305.529
3005.01	305.604
3007.82	303.649
3010.63	310.394
3013.43	319.836
3016.23	305.641
3019.03	305.25
3021.83	299.938
3024.63	304.412
3027.42	306.847
3030.2	303.05
3032.99	302.911
3035.77	312.481
3038.55	309.311
3041.33	306.121
3044.1	310.874
3046.87	305.857
3049.64	307.089
3052.41	308.571
3055.17	313.061
3057.93	302.795
3060.69	308.106
3063.44	312.215
3066.19	310.001
3068.94	309.398
3071.68	314.954
3074.42	307.546
3077.16	307.309
3079.9	314.582
3082.63	315.072
3085.36	308.79
3088.09	316.093
3090.82	319.911
3093.54	318.266
3096.13	326.7
3098.9	317.707
3101.67	321.689
3104.44	327.395
3107.2	320.265
3109.97	322.29
3112.72	333.46
3115.48	321.489
3118.23	318.814
3120.98	324.781
3123.73	326.82
3126.48	325.179
3129.22	326.247
3131.96	330.695
3134.69	326.602
3137.43	335.795
3140.16	319.966
3142.88	326.408
3145.61	317.769
3148.33	322.409
3151.05	323.347
3153.77	315.713
3156.48	324.217
3159.19	319.567
3161.9	321.451
3164.6	326.825
3167.31	316.444
3170.01	328.217
3172.7	322.514
3175.4	322.319
3178.09	327.209
3180.78	317.869
3183.46	328.713
3186.15	322.534
3188.83	315.391
3191.5	319.441
3194.18	314.084
3196.85	326.9
3199.52	323.213
3202.19	325.923
3204.85	325.745
3207.51	320.286
3210.17	328.184
3212.82	323.938
3215.47	323.183
3218.12	324.131
3220.77	323.956
3223.41	325.477
3226.05	323.093
3228.69	322.022
3231.33	324.175
3233.96	326.201
3236.59	324.752
3239.22	314.225
3241.84	326.43
3244.46	321.57
3247.08	326.806
3249.7	326.635
3252.31	333.146
3254.92	330.553
3257.53	336.135
3260.13	333.717
3262.73	339.252
3265.39	335.498
3268.04	331.673
3270.69	333.76
3273.34	342.881
3275.98	327.557
3278.62	327.735
3281.26	335.692
3283.9	333.645
3286.53	335.852
3289.16	331.973
3291.79	330.443
3294.42	338.819
3297.04	342.141
3299.66	332.171
3302.28	332.857
3304.89	336.97
3307.5	333.006
3310.11	334.962
3312.72	336.591
3315.32	330.254
3317.92	333.276
3320.52	340.804
3323.12	333.497
3325.71	334.414
3328.3	330.712
3330.89	335.873
3333.47	328.692
3336.06	334.44
3338.64	336.28
3341.21	337.627
3343.79	338.647
3346.36	330.872
3348.93	334.008
3351.49	340.947
3354.06	329.238
3356.62	340.034
3359.18	335.996
3361.73	329.817
3364.28	337.482
3366.83	334.306
3369.38	329.841
3371.92	337.771
3374.47	332.812
3377.01	338.254
3379.54	341.528
3382.08	341.558
3384.61	334.764
3387.14	329.336
3389.66	345.165
3392.19	348.848
3394.71	348.624
3397.22	341.35
3399.74	329.768
3402.25	333.044
3404.76	339.508
3407.27	338.017
3409.77	341.659
3412.27	343.212
3414.77	338.166
3417.27	340.646
3419.68	344.313
3422.23	343.849
3424.77	341.892
3427.31	351.526
3429.85	341.722
3432.39	349.321
3434.92	344.746
3437.45	343.916
3439.98	336.268
3442.51	351.439
3445.03	345.615
3447.55	345.67
3450.07	346.663
3452.58	354.76
3455.09	340.907
3457.6	352.469
3460.11	352.495
3462.62	342.232
3465.12	349.312
3467.62	341.206
3470.12	349.49
3472.61	351.193
3475.1	346.792
3477.59	362.504
3480.08	340.92
3482.56	345.204
3485.04	346.362
3487.52	339.169
3490	344.83
3492.47	340.284
3494.94	359.299
3497.41	337.476
3499.88	349.687
3502.34	339.04
3504.8	342.578
3507.26	345.632
3509.72	336.64
3512.17	350.926
3514.62	336.887
3517.07	348.815
3519.51	332.431
3521.95	345.152
3524.39	338.274
3526.83	342.842
3529.27	341.012
3531.7	347.301
3534.13	335.389
3536.56	341.015
3538.98	340.159
3541.4	340.73
3543.82	338.478
3546.24	343.788
3548.65	336.619
3551.06	348.797
3553.47	341.141
3555.88	341.878
3558.28	341.571
3560.69	339.654
3563.08	338.163
3565.48	344.68
3567.87	345.03
3570.26	349.364
3572.61	347.586
3575.05	347.421
3577.49	344.914
3579.93	350.069
3582.36	350.812
3584.79	344.769
3587.22	348.037
3589.65	351.61
3592.07	348.182
3594.49	349.625
3596.91	358.764
3599.32	348.131
3601.74	344.882
3604.15	332.892
3606.56	351.185
3608.96	341.218
3611.36	345.257
3613.76	349.64
3616.16	347.374
3618.56	355.547
3620.95	355.672
3623.34	348.625
3625.73	349.847
3628.12	340.7
3630.5	345.559
3632.88	348.184
3635.26	341.894
3637.63	355.899
3640.01	348.601
3642.38	339.508
3644.74	339.751
3647.11	344.927
3649.47	342.187
3651.83	338.82
3654.19	341.532
3656.55	346.343
3658.9	345.074
3661.25	343.584
3663.6	342.523
3665.94	342.3
3668.29	344.025
3670.63	343.872
3672.97	344.831
3675.3	348.445
3677.64	341.602
3679.97	343.635
3682.29	341.409
3684.62	343.351
3686.94	338.74
3689.26	343.26
3691.58	330.318
3693.9	342.59
3696.21	338.142
3698.52	342.04
3700.83	353.939
3703.14	341.81
3705.44	346.674
3707.74	345.263
3710.04	343.693
3712.33	343.393
3714.63	336.04
3716.92	341.579
3719.19	335.697
3721.53	341.007
3723.87	341.311
3726.21	344.026
3728.54	346.271
3730.87	335.852
3733.2	341.53
3735.52	333.877
3737.85	346.232
3740.17	349.938
3742.49	343.414
3744.8	341.287
3747.11	340.545
3749.43	341.171
3751.73	364.635
3754.04	339.798
3756.34	344.949
3758.64	342.548
3760.94	331.919
3763.24	343.644
3765.53	331.167
3767.83	333.28
3770.12	330.067
3772.4	329.266
3774.69	339.946
3776.97	327.633
3779.25	334.565
3781.52	328.248
3783.8	331.396
3786.07	333.418
3788.34	331.382
3790.61	329.796
3792.87	338.724
3795.14	333.267
3797.4	336.131
3799.65	331.085
3801.91	329.294
3804.16	328.912
3806.41	327.4
3808.66	329.206
3810.91	327.27
3813.15	340.065
3815.39	326.075
3817.63	329.631
3819.86	334.773
3822.1	321.491
3824.33	332.074
3826.56	324.359
3828.78	324.447
3831.01	331.726
3833.23	327.361
3835.45	336.98
3837.67	332.496
3839.88	320.162
3842.09	327.179
3844.3	334.005
3846.51	328.896
3848.71	332.087
3850.92	326.507
3853.12	331.698
3855.31	328.362
3857.51	335.21
3859.64	329.49
3861.89	322.749
3864.13	318.377
3866.37	324.328
3868.6	322.673
3870.84	326.212
3873.07	325.422
3875.3	324.925
3877.53	317.929
3879.75	326.555
3881.97	334.437
3884.19	325.009
3886.41	329.674
3888.63	321.165
3890.84	323.887
3893.05	326.46
3895.26	327.882
3897.47	325.64
3899.67	330.487
3901.87	318.447
3904.07	318.899
3906.27	330.58
3908.46	323.407
3910.66	326.208
3912.85	321.578
3915.03	326.296
3917.22	317.122
3919.4	324.662
3921.58	313.732
3923.76	325.053
3925.94	315.279
3928.11	322.106
3930.28	320.459
3932.45	314.589
3934.62	315.385
3936.78	323.115
3938.94	308.052
3941.1	320.529
3943.26	315.95
3945.41	317.81
3947.57	314.419
3949.72	314.455
3951.86	307.163
3954.01	313.847
3956.15	315.038
3958.29	308.093
3960.43	322.055
3962.57	308.874
3964.7	299.654
3966.83	319.982
3968.96	309.722
3971.09	314.323
3973.22	305.97
3975.34	308.07
3977.46	303.27
3979.58	307.08
3981.69	308.877
3983.8	307.344
3985.92	308.218
3988.02	311.534
3990.13	313.509
3992.23	308.674
3994.27	310.934
3996.42	301.512
3998.57	316.915
4000.72	310.596
4002.86	313.077
4005.01	319.879
4007.15	309.54
4009.29	306.341
4011.42	313.27
4013.56	311.795
4015.69	307.123
4017.82	318.635
4019.94	306.337
4022.07	307.706
4024.19	313.06
4026.31	317.189
4028.43	299.613
4030.54	310.663
4032.66	307.374
4034.77	310.842
4036.88	309.351
4038.98	307.701
4041.09	308.069
4043.19	312.429
4045.29	303.371
4047.39	307.262
4049.48	310.977
4051.58	309.065
4053.67	306.721
4055.75	312.322
4057.84	310.291
4059.92	309.858
4062.01	304.712
4064.09	302.559
4066.16	303.433
4068.24	306.158
4070.31	309.669
4072.38	307.164
4074.45	293.029
4076.51	303.931
4078.58	298.971
4080.64	301.895
4082.7	306.368
4084.76	300.081
4086.81	294.276
4088.86	300.76
4090.91	301.288
4092.96	294.423
4095.01	304.187
4097.05	293.823
4099.09	295.773
4101.13	298.642
4103.17	300.914
4105.2	296.322
4107.23	298.382
4109.26	299.041
4111.29	291.72
4113.32	296.364
4115.34	296.458
4117.36	296.363
4119.38	299.446
4121.28	289.901
4123.35	304.787
4125.41	299.161
4127.48	292.266
4129.54	293.497
4131.59	289.571
4133.65	295.597
4135.7	302.096
4137.75	297.639
4139.8	286.433
4141.85	295.039
4143.9	290.443
4145.94	295.861
4147.98	293.936
4150.02	293.97
4152.05	291.107
4154.08	301.226
4156.12	295.265
4158.15	292.972
4160.17	287.339
4162.2	291.753
4164.22	286.12
4166.24	296.848
4168.26	292.094
4170.27	295.962
4172.29	291.653
4174.3	282.045
4176.31	289.806
4178.32	296.627
4180.32	298.308
4182.32	293.187
4184.32	289.636
4186.32	288.47
4188.32	288.038
4190.31	285.991
4192.31	296.243
4194.3	281.96
4196.28	282.475
4198.27	294.33
4200.25	290.91
4202.23	283.168
4204.21	288.118
4206.19	288.832
4208.16	291.535
4210.14	298.249
4212.11	286.135
4214.07	273.379
4216.04	293.289
4218	282.417
4219.96	287.483
4221.92	285.484
4223.88	292.351
4225.84	275.355
4227.79	280.2
4229.74	286.329
4231.69	284.045
4233.63	288.603
4235.58	290.553
4237.52	287.602
4239.46	285.761
4241.4	286.118
4243.33	280.583
4245.3	284.044
4247.28	274.788
4249.26	280.64
4251.24	285.932
4253.22	284.14
4255.19	278.42
4257.16	279.348
4259.13	271.238
4261.1	270.572
4263.07	277.736
4265.03	273.741
4266.99	280.076
4268.95	272.683
4270.91	280.503
4272.86	276.912
4274.81	278.524
4276.76	279.625
4278.71	271.919
4280.66	275.582
4282.6	268.115
4284.55	273.692
4286.49	282.382
4288.42	274.462
4290.36	280.967
4292.29	271.276
4294.22	272.807
4296.15	285.7
4298.08	273.465
4300.01	267.918
4301.93	273.863
4303.85	275.563
4305.77	274.817
4307.69	269.496
4309.6	273.964
4311.51	272.527
4313.42	280.513
4315.33	269.752
4317.24	274.496
4319.14	269.85
4321.04	266.677
4322.94	278.748
4324.84	271.569
4326.74	268.358
4328.63	264.277
4330.52	268.797
4332.41	273.418
4334.3	269.987
4336.18	270.92
4338.06	259.748
4339.94	274.321
4341.82	269.542
4343.7	256.491
4345.57	263.998
4347.45	266.158
4349.32	264.298
4351.19	266.882
4353.05	260.68
4354.91	261.058
4356.78	264.021
4358.64	258.241
4360.49	260.811
4362.3	260.727
4364.21	259.796
4366.11	265.532
4368.01	257.884
4369.91	263.452
4371.8	262.611
4373.7	257.964
4375.59	258.275
4377.48	258.271
4379.37	258.385
4381.26	256.643
4383.14	251.675
4385.02	265.881
4386.9	261.069
4388.78	253.768
4390.66	252.539
4392.53	261.523
4394.4	254.917
4396.27	256.751
4398.14	260.628
4400	259.702
4401.87	251.654
4403.73	258.925
4405.59	256.12
4407.44	249.833
4409.3	282.322
4411.15	254.988
4413	255.22
4414.85	261.341
4416.7	251.547
4418.54	257.597
4420.39	256.322
4422.23	255.419
4424.06	251.887
4425.9	246.232
4427.74	254.36
4429.57	251.745
4431.4	249.012
4433.23	252.519
4435.05	254.774
4436.88	259.316
4438.7	252.844
4440.52	249.151
4442.34	253.464
4444.15	253.345
4445.97	252.66
4447.78	245.4
4449.59	245.178
4451.4	252.738
4453.2	247.972
4455.01	245.16
4456.81	246.211
4458.61	246.741
4460.41	242.877
4462.2	240.779
4463.99	241.527
4465.79	252.327
4467.57	242.915
4469.36	243.795
4471.15	241.362
4472.93	240.296
4474.71	245.288
4476.46	244.04
4478.29	254.038
4480.11	239.298
4481.94	246.306
4483.76	246.873
4485.58	246.261
4487.4	243.47
4489.21	243.658
4491.03	238.948
4492.84	239.852
4494.65	245.01
4496.46	234.352
4498.26	251.096
4499.95	239.521